Workbook

Sheet Panel SyS
A1: DESARROLLO PROFESIONAL SyS · AUDIOS DEL EQUIPO
A2: Audios del equipo en el paso 1.2 · tres embudos
A3: ISO + Calidad, Manufactura y Calidad y Core Tools Premium · preguntas del 5 al 15 de octubre de 2026 · corte: 15 oct 2026, 23:59 h (Monterrey)
A4: 615 leads recibieron la pregunta «¿en qué área trabajas?». Lectura del CRM en solo lectura; los casos del 15 de octubre todavía pueden cambiar.
A6: =Resumen!H10 -> 615 | C6: =Resumen!H11 -> 236 | E6: =Resumen!H18 -> 220 | G6: =Resumen!H21 -> 6.4108167 | I6: =Resumen!H31 -> 155 | K6: =Resumen!H34 -> 85
A8: Leads con la pregunta | C8: Informaron su perfil | E8: Recibieron audio | G8: Minutos al audio (mediana) | I8: Respondieron después | K8: Bot a Negativo después
A10: • De 236 que informaron su perfil, 235 recibieron recomendación y 220 con audio (93%). 155 volvieron a responder y el bot pasó a 85 de ellos a Negativo (55%), a las 4.0 h (mediana) de su último mensaje.
A11: • La pregunta es el cuello de botella: solo 38% dice su perfil; 214 de los 342 que no contestaron sí la vieron (palomitas azules). Entre 8:00 y 22:00 contestaron 208 de 500 (42%); fuera, 28 de 115 (24%).
A12: • El audio llega en 6.4 min (mediana), dura 105 s y el 71% lo ve. Con audio en menos de 4 min respondió el 76%; con más espera, el 63% (p = 0.10).
A13: • Después de una nota de voz de una persona, el lead escribe en 24 h el 60% de las veces; después del audio automático del bot, el 11%.
A15: Tiempo a la recomendación
A16: Rango | C16: Leads | D16: Respondieron | E16: Tasa
A17: =Tiempos!B6 -> Menos de 4 min | C17: =Tiempos!C6 -> 54 | D17: =Tiempos!D6 -> 41 | E17: =IFERROR(D17/C17,0) -> 0.75925926
A18: =Tiempos!B7 -> 4 a 6 min | C18: =Tiempos!C7 -> 53 | D18: =Tiempos!D7 -> 32 | E18: =IFERROR(D18/C18,0) -> 0.60377358
A19: =Tiempos!B8 -> 6 a 10 min | C19: =Tiempos!C8 -> 52 | D19: =Tiempos!D8 -> 34 | E19: =IFERROR(D19/C19,0) -> 0.65384615
A20: =Tiempos!B9 -> 10 a 30 min | C20: =Tiempos!C9 -> 56 | D20: =Tiempos!D9 -> 37 | E20: =IFERROR(D20/C20,0) -> 0.66071429
A21: =Tiempos!B10 -> 30 min o más | C21: =Tiempos!C10 -> 20 | D21: =Tiempos!D10 -> 11 | E21: =IFERROR(D21/C21,0) -> 0.55
A31: Por embudo
A32: Embudo | C32: Con la pregunta | D32: Informaron perfil | E32: Con audio | F32: Min. al audio | G32: Respondieron | H32: Bot a Negativo | I32: Ganados (perfil)
A33: ISO + Calidad | C33: =Resumen!B10 -> 398 | D33: =Resumen!B11 -> 158 | E33: =Resumen!B18 -> 147 | F33: =Resumen!B21 -> 6.875 | G33: =Resumen!B31 -> 101 | H33: =Resumen!B34 -> 58 | I33: =Resumen!B37 -> 3
A34: Manufactura y Calidad | C34: =Resumen!D10 -> 110 | D34: =Resumen!D11 -> 41 | E34: =Resumen!D18 -> 39 | F34: =Resumen!D21 -> 5.0288167 | G34: =Resumen!D31 -> 30 | H34: =Resumen!D34 -> 14 | I34: =Resumen!D37 -> 2
A35: Core Tools Premium | C35: =Resumen!F10 -> 107 | D35: =Resumen!F11 -> 37 | E35: =Resumen!F18 -> 34 | F35: =Resumen!F21 -> 6.3731 | G35: =Resumen!F31 -> 24 | H35: =Resumen!F34 -> 13 | I35: =Resumen!F37 -> 3
A36: Tres embudos | C36: =Resumen!H10 -> 615 | D36: =Resumen!H11 -> 236 | E36: =Resumen!H18 -> 220 | F36: =Resumen!H21 -> 6.4108167 | G36: =Resumen!H31 -> 155 | H36: =Resumen!H34 -> 85 | I36: =Resumen!H37 -> 8
A38: Hora de Monterrey (central de México). «Respondieron» = escribieron después de la recomendación, hasta el corte. Detalle en las demás pestañas.

Sheet Resumen
A1: DESARROLLO PROFESIONAL SyS
A2: Paso 1.2: respuesta del lead y recomendación con audio del equipo
A3: ISO + Calidad, Manufactura y Calidad y Core Tools Premium · preguntas del 5 al 15 de octubre de 2026 · corte: 15 oct 2026, 23:59 h (Monterrey) · hora de Monterrey (central de México)
A4: El equipo manda el audio rápido (mediana de 6.4 min) y 66% de los leads vuelve a escribir. Lo que más se pierde: la pregunta que nadie contesta (56%) y los leads que el bot pasa a Negativo cuando ya estaban conversando (55%).
A6: Indicador | B6: ISO + Calidad | D6: Manufactura y Calidad | F6: Core Tools Premium | H6: Tres embudos | J6: Muestra anterior
B7: Valor | C7: % | D7: Valor | E7: % | F7: Valor | G7: % | H7: Valor | I7: % | J7: Valor | K7: %
A9: La pregunta del bot (paso 1.2)
A10: Leads que recibieron la pregunta | B10: =COUNTIFS('Detalle por lead'!$A$2:$A$616,B$6) -> 398 | D10: =COUNTIFS('Detalle por lead'!$A$2:$A$616,D$6) -> 110 | F10: =COUNTIFS('Detalle por lead'!$A$2:$A$616,F$6) -> 107 | H10: =COUNT('Detalle por lead'!$B$2:$B$616) -> 615 | J10: 70
A11: Contestaron la pregunta (dijeron su área o que estudian) | B11: =COUNTIFS('Detalle por lead'!$A$2:$A$616,B$6,'Detalle por lead'!$D$2:$D$616,"Sí") -> 158 | C11: =IFERROR(B11/B10,"—") -> 0.39698492 | D11: =COUNTIFS('Detalle por lead'!$A$2:$A$616,D$6,'Detalle por lead'!$D$2:$D$616,"Sí") -> 41 | E11: =IFERROR(D11/D10,"—") -> 0.37272727 | F11: =COUNTIFS('Detalle por lead'!$A$2:$A$616,F$6,'Detalle por lead'!$D$2:$D$616,"Sí") -> 37 | G11: =IFERROR(F11/F10,"—") -> 0.34579439 | H11: =COUNTIFS('Detalle por lead'!$D$2:$D$616,"Sí") -> 236 | I11: =IFERROR(H11/H10,"—") -> 0.38373984 | J11: 28 | K11: 0.4
A12: Respondieron otra cosa | B12: =COUNTIFS('Detalle por lead'!$A$2:$A$616,B$6,'Detalle por lead'!$D$2:$D$616,"Respondió otra cosa") -> 24 | C12: =IFERROR(B12/B10,"—") -> 0.060301508 | D12: =COUNTIFS('Detalle por lead'!$A$2:$A$616,D$6,'Detalle por lead'!$D$2:$D$616,"Respondió otra cosa") -> 7 | E12: =IFERROR(D12/D10,"—") -> 0.063636364 | F12: =COUNTIFS('Detalle por lead'!$A$2:$A$616,F$6,'Detalle por lead'!$D$2:$D$616,"Respondió otra cosa") -> 6 | G12: =IFERROR(F12/F10,"—") -> 0.056074766 | H12: =COUNTIFS('Detalle por lead'!$D$2:$D$616,"Respondió otra cosa") -> 37 | I12: =IFERROR(H12/H10,"—") -> 0.060162602 | J12: 0 | K12: 0
A13: No contestaron | B13: =COUNTIFS('Detalle por lead'!$A$2:$A$616,B$6,'Detalle por lead'!$D$2:$D$616,"No") -> 216 | C13: =IFERROR(B13/B10,"—") -> 0.54271357 | D13: =COUNTIFS('Detalle por lead'!$A$2:$A$616,D$6,'Detalle por lead'!$D$2:$D$616,"No") -> 62 | E13: =IFERROR(D13/D10,"—") -> 0.56363636 | F13: =COUNTIFS('Detalle por lead'!$A$2:$A$616,F$6,'Detalle por lead'!$D$2:$D$616,"No") -> 64 | G13: =IFERROR(F13/F10,"—") -> 0.59813084 | H13: =COUNTIFS('Detalle por lead'!$D$2:$D$616,"No") -> 342 | I13: =IFERROR(H13/H10,"—") -> 0.55609756 | J13: 42 | K13: 0.6
A14: De ellos, vieron la pregunta (palomitas azules) y no contestaron | B14: =COUNTIFS('Detalle por lead'!$A$2:$A$616,B$6,'Detalle por lead'!$D$2:$D$616,"No",'Detalle por lead'!$H$2:$H$616,"Sí") -> 138 | C14: =IFERROR(B14/B13,"—") -> 0.63888889 | D14: =COUNTIFS('Detalle por lead'!$A$2:$A$616,D$6,'Detalle por lead'!$D$2:$D$616,"No",'Detalle por lead'!$H$2:$H$616,"Sí") -> 40 | E14: =IFERROR(D14/D13,"—") -> 0.64516129 | F14: =COUNTIFS('Detalle por lead'!$A$2:$A$616,F$6,'Detalle por lead'!$D$2:$D$616,"No",'Detalle por lead'!$H$2:$H$616,"Sí") -> 36 | G14: =IFERROR(F14/F13,"—") -> 0.5625 | H14: =COUNTIFS('Detalle por lead'!$D$2:$D$616,"No",'Detalle por lead'!$H$2:$H$616,"Sí") -> 214 | I14: =IFERROR(H14/H13,"—") -> 0.62573099 | J14: 28 | K14: 0.66666667
A16: La respuesta del equipo (leads que contestaron la pregunta)
A17: Recibieron respuesta de una persona | B17: =COUNTIFS('Detalle por lead'!$A$2:$A$616,B$6,'Detalle por lead'!$D$2:$D$616,"Sí",'Detalle por lead'!$K$2:$K$616,"<>") -> 157 | C17: =IFERROR(B17/B11,"—") -> 0.99367089 | D17: =COUNTIFS('Detalle por lead'!$A$2:$A$616,D$6,'Detalle por lead'!$D$2:$D$616,"Sí",'Detalle por lead'!$K$2:$K$616,"<>") -> 41 | E17: =IFERROR(D17/D11,"—") -> 1 | F17: =COUNTIFS('Detalle por lead'!$A$2:$A$616,F$6,'Detalle por lead'!$D$2:$D$616,"Sí",'Detalle por lead'!$K$2:$K$616,"<>") -> 37 | G17: =IFERROR(F17/F11,"—") -> 1 | H17: =COUNTIFS('Detalle por lead'!$D$2:$D$616,"Sí",'Detalle por lead'!$K$2:$K$616,"<>") -> 235 | I17: =IFERROR(H17/H11,"—") -> 0.99576271 | J17: 28 | K17: 1
A18: Recibieron audio | B18: =COUNTIFS('Detalle por lead'!$A$2:$A$616,B$6,'Detalle por lead'!$D$2:$D$616,"Sí",'Detalle por lead'!$Q$2:$Q$616,"Sí") -> 147 | C18: =IFERROR(B18/B11,"—") -> 0.93037975 | D18: =COUNTIFS('Detalle por lead'!$A$2:$A$616,D$6,'Detalle por lead'!$D$2:$D$616,"Sí",'Detalle por lead'!$Q$2:$Q$616,"Sí") -> 39 | E18: =IFERROR(D18/D11,"—") -> 0.95121951 | F18: =COUNTIFS('Detalle por lead'!$A$2:$A$616,F$6,'Detalle por lead'!$D$2:$D$616,"Sí",'Detalle por lead'!$Q$2:$Q$616,"Sí") -> 34 | G18: =IFERROR(F18/F11,"—") -> 0.91891892 | H18: =COUNTIFS('Detalle por lead'!$D$2:$D$616,"Sí",'Detalle por lead'!$Q$2:$Q$616,"Sí") -> 220 | I18: =IFERROR(H18/H11,"—") -> 0.93220339 | J18: 27 | K18: 0.96428571
A19: Recibieron el paquete completo: aviso + audio + cursos | B19: =COUNTIFS('Detalle por lead'!$A$2:$A$616,B$6,'Detalle por lead'!$D$2:$D$616,"Sí",'Detalle por lead'!$P$2:$P$616,"Texto (aviso del audio) + Audio + Cursos*") -> 132 | C19: =IFERROR(B19/B11,"—") -> 0.83544304 | D19: =COUNTIFS('Detalle por lead'!$A$2:$A$616,D$6,'Detalle por lead'!$D$2:$D$616,"Sí",'Detalle por lead'!$P$2:$P$616,"Texto (aviso del audio) + Audio + Cursos*") -> 38 | E19: =IFERROR(D19/D11,"—") -> 0.92682927 | F19: =COUNTIFS('Detalle por lead'!$A$2:$A$616,F$6,'Detalle por lead'!$D$2:$D$616,"Sí",'Detalle por lead'!$P$2:$P$616,"Texto (aviso del audio) + Audio + Cursos*") -> 29 | G19: =IFERROR(F19/F11,"—") -> 0.78378378 | H19: =COUNTIFS('Detalle por lead'!$D$2:$D$616,"Sí",'Detalle por lead'!$P$2:$P$616,"Texto (aviso del audio) + Audio + Cursos*") -> 199 | I19: =IFERROR(H19/H11,"—") -> 0.84322034 | J19: —
A20: Mediana de minutos al primer mensaje del equipo | B20: {=IFERROR(MEDIAN(IF(('Detalle por lead'!$A$2:$A$616=B$6)*('Detalle por lead'!$D$2:$D$616="Sí")*ISNUMBER('Detalle por lead'!$L$2:$L$616),'Detalle por lead'!$L$2:$L$616)),"—")} -> 2.5625667 | D20: {=IFERROR(MEDIAN(IF(('Detalle por lead'!$A$2:$A$616=D$6)*('Detalle por lead'!$D$2:$D$616="Sí")*ISNUMBER('Detalle por lead'!$L$2:$L$616),'Detalle por lead'!$L$2:$L$616)),"—")} -> 1.3429666 | F20: {=IFERROR(MEDIAN(IF(('Detalle por lead'!$A$2:$A$616=F$6)*('Detalle por lead'!$D$2:$D$616="Sí")*ISNUMBER('Detalle por lead'!$L$2:$L$616),'Detalle por lead'!$L$2:$L$616)),"—")} -> 2.4578833 | H20: {=IFERROR(MEDIAN(IF(('Detalle por lead'!$D$2:$D$616="Sí")*ISNUMBER('Detalle por lead'!$L$2:$L$616),'Detalle por lead'!$L$2:$L$616)),"—")} -> 2.16335 | J20: 1.318
A21: Mediana de minutos a la recomendación (audio) | B21: {=IFERROR(MEDIAN(IF(('Detalle por lead'!$A$2:$A$616=B$6)*('Detalle por lead'!$D$2:$D$616="Sí")*ISNUMBER('Detalle por lead'!$N$2:$N$616),'Detalle por lead'!$N$2:$N$616)),"—")} -> 6.875 | D21: {=IFERROR(MEDIAN(IF(('Detalle por lead'!$A$2:$A$616=D$6)*('Detalle por lead'!$D$2:$D$616="Sí")*ISNUMBER('Detalle por lead'!$N$2:$N$616),'Detalle por lead'!$N$2:$N$616)),"—")} -> 5.0288167 | F21: {=IFERROR(MEDIAN(IF(('Detalle por lead'!$A$2:$A$616=F$6)*('Detalle por lead'!$D$2:$D$616="Sí")*ISNUMBER('Detalle por lead'!$N$2:$N$616),'Detalle por lead'!$N$2:$N$616)),"—")} -> 6.3731 | H21: {=IFERROR(MEDIAN(IF(('Detalle por lead'!$D$2:$D$616="Sí")*ISNUMBER('Detalle por lead'!$N$2:$N$616),'Detalle por lead'!$N$2:$N$616)),"—")} -> 6.4108167 | J21: 5.257
A22: Percentil 90 de minutos a la recomendación | B22: {=IFERROR(PERCENTILE(IF(('Detalle por lead'!$A$2:$A$616=B$6)*('Detalle por lead'!$D$2:$D$616="Sí")*ISNUMBER('Detalle por lead'!$N$2:$N$616),'Detalle por lead'!$N$2:$N$616),0.9),"—")} -> 22.076337 | D22: {=IFERROR(PERCENTILE(IF(('Detalle por lead'!$A$2:$A$616=D$6)*('Detalle por lead'!$D$2:$D$616="Sí")*ISNUMBER('Detalle por lead'!$N$2:$N$616),'Detalle por lead'!$N$2:$N$616),0.9),"—")} -> 12.55505 | F22: {=IFERROR(PERCENTILE(IF(('Detalle por lead'!$A$2:$A$616=F$6)*('Detalle por lead'!$D$2:$D$616="Sí")*ISNUMBER('Detalle por lead'!$N$2:$N$616),'Detalle por lead'!$N$2:$N$616),0.9),"—")} -> 37.677177 | H22: {=IFERROR(PERCENTILE(IF(('Detalle por lead'!$D$2:$D$616="Sí")*ISNUMBER('Detalle por lead'!$N$2:$N$616),'Detalle por lead'!$N$2:$N$616),0.9),"—")} -> 22.062023 | J22: 12.174
A23: Máximo de minutos a la recomendación | B23: {=IFERROR(MAX(IF(('Detalle por lead'!$A$2:$A$616=B$6)*('Detalle por lead'!$D$2:$D$616="Sí")*ISNUMBER('Detalle por lead'!$N$2:$N$616),'Detalle por lead'!$N$2:$N$616)),"—")} -> 1204.0598 | D23: {=IFERROR(MAX(IF(('Detalle por lead'!$A$2:$A$616=D$6)*('Detalle por lead'!$D$2:$D$616="Sí")*ISNUMBER('Detalle por lead'!$N$2:$N$616),'Detalle por lead'!$N$2:$N$616)),"—")} -> 843.73367 | F23: {=IFERROR(MAX(IF(('Detalle por lead'!$A$2:$A$616=F$6)*('Detalle por lead'!$D$2:$D$616="Sí")*ISNUMBER('Detalle por lead'!$N$2:$N$616),'Detalle por lead'!$N$2:$N$616)),"—")} -> 537.84313 | H23: {=IFERROR(MAX(IF(('Detalle por lead'!$D$2:$D$616="Sí")*ISNUMBER('Detalle por lead'!$N$2:$N$616),'Detalle por lead'!$N$2:$N$616)),"—")} -> 1204.0598 | J23: 23.946
A24: Recomendaciones en menos de 10 min | B24: =COUNTIFS('Detalle por lead'!$A$2:$A$616,B$6,'Detalle por lead'!$D$2:$D$616,"Sí",'Detalle por lead'!$N$2:$N$616,"<10") -> 104 | C24: =IFERROR(B24/B17,"—") -> 0.66242038 | D24: =COUNTIFS('Detalle por lead'!$A$2:$A$616,D$6,'Detalle por lead'!$D$2:$D$616,"Sí",'Detalle por lead'!$N$2:$N$616,"<10") -> 30 | E24: =IFERROR(D24/D17,"—") -> 0.73170732 | F24: =COUNTIFS('Detalle por lead'!$A$2:$A$616,F$6,'Detalle por lead'!$D$2:$D$616,"Sí",'Detalle por lead'!$N$2:$N$616,"<10") -> 25 | G24: =IFERROR(F24/F17,"—") -> 0.67567568 | H24: =COUNTIFS('Detalle por lead'!$D$2:$D$616,"Sí",'Detalle por lead'!$N$2:$N$616,"<10") -> 159 | I24: =IFERROR(H24/H17,"—") -> 0.67659574 | J24: 20 | K24: 0.71428571
A25: Mediana de minutos del aviso al audio (grabarlo y mandarlo) | B25: {=IFERROR(MEDIAN(IF(('Detalle por lead'!$A$2:$A$616=B$6)*('Detalle por lead'!$D$2:$D$616="Sí")*ISNUMBER('Detalle por lead'!$V$2:$V$616),'Detalle por lead'!$V$2:$V$616)),"—")} -> 3.84 | D25: {=IFERROR(MEDIAN(IF(('Detalle por lead'!$A$2:$A$616=D$6)*('Detalle por lead'!$D$2:$D$616="Sí")*ISNUMBER('Detalle por lead'!$V$2:$V$616),'Detalle por lead'!$V$2:$V$616)),"—")} -> 3.63 | F25: {=IFERROR(MEDIAN(IF(('Detalle por lead'!$A$2:$A$616=F$6)*('Detalle por lead'!$D$2:$D$616="Sí")*ISNUMBER('Detalle por lead'!$V$2:$V$616),'Detalle por lead'!$V$2:$V$616)),"—")} -> 3.32 | H25: {=IFERROR(MEDIAN(IF(('Detalle por lead'!$D$2:$D$616="Sí")*ISNUMBER('Detalle por lead'!$V$2:$V$616),'Detalle por lead'!$V$2:$V$616)),"—")} -> 3.78 | J25: —
A26: Duración mediana del audio (s) | B26: {=IFERROR(MEDIAN(IF(('Detalle por lead'!$A$2:$A$616=B$6)*('Detalle por lead'!$D$2:$D$616="Sí")*ISNUMBER('Detalle por lead'!$T$2:$T$616),'Detalle por lead'!$T$2:$T$616)),"—")} -> 104.7 | D26: {=IFERROR(MEDIAN(IF(('Detalle por lead'!$A$2:$A$616=D$6)*('Detalle por lead'!$D$2:$D$616="Sí")*ISNUMBER('Detalle por lead'!$T$2:$T$616),'Detalle por lead'!$T$2:$T$616)),"—")} -> 105.1 | F26: {=IFERROR(MEDIAN(IF(('Detalle por lead'!$A$2:$A$616=F$6)*('Detalle por lead'!$D$2:$D$616="Sí")*ISNUMBER('Detalle por lead'!$T$2:$T$616),'Detalle por lead'!$T$2:$T$616)),"—")} -> 103.95 | H26: {=IFERROR(MEDIAN(IF(('Detalle por lead'!$D$2:$D$616="Sí")*ISNUMBER('Detalle por lead'!$T$2:$T$616),'Detalle por lead'!$T$2:$T$616)),"—")} -> 104.8 | J26: 106.4
A27: Vieron el audio (palomitas azules) | B27: =COUNTIFS('Detalle por lead'!$A$2:$A$616,B$6,'Detalle por lead'!$D$2:$D$616,"Sí",'Detalle por lead'!$U$2:$U$616,"Sí") -> 111 | C27: =IFERROR(B27/B18,"—") -> 0.75510204 | D27: =COUNTIFS('Detalle por lead'!$A$2:$A$616,D$6,'Detalle por lead'!$D$2:$D$616,"Sí",'Detalle por lead'!$U$2:$U$616,"Sí") -> 21 | E27: =IFERROR(D27/D18,"—") -> 0.53846154 | F27: =COUNTIFS('Detalle por lead'!$A$2:$A$616,F$6,'Detalle por lead'!$D$2:$D$616,"Sí",'Detalle por lead'!$U$2:$U$616,"Sí") -> 24 | G27: =IFERROR(F27/F18,"—") -> 0.70588235 | H27: =COUNTIFS('Detalle por lead'!$D$2:$D$616,"Sí",'Detalle por lead'!$U$2:$U$616,"Sí") -> 156 | I27: =IFERROR(H27/H18,"—") -> 0.70909091 | J27: —
A28: Cursos recomendados por lead (promedio) | B28: {=IFERROR(AVERAGE(IF(('Detalle por lead'!$A$2:$A$616=B$6)*('Detalle por lead'!$D$2:$D$616="Sí")*ISNUMBER('Detalle por lead'!$X$2:$X$616),'Detalle por lead'!$X$2:$X$616)),"—")} -> 2.3566879 | D28: {=IFERROR(AVERAGE(IF(('Detalle por lead'!$A$2:$A$616=D$6)*('Detalle por lead'!$D$2:$D$616="Sí")*ISNUMBER('Detalle por lead'!$X$2:$X$616),'Detalle por lead'!$X$2:$X$616)),"—")} -> 2.4390244 | F28: {=IFERROR(AVERAGE(IF(('Detalle por lead'!$A$2:$A$616=F$6)*('Detalle por lead'!$D$2:$D$616="Sí")*ISNUMBER('Detalle por lead'!$X$2:$X$616),'Detalle por lead'!$X$2:$X$616)),"—")} -> 2.4054054 | H28: {=IFERROR(AVERAGE(IF(('Detalle por lead'!$D$2:$D$616="Sí")*ISNUMBER('Detalle por lead'!$X$2:$X$616),'Detalle por lead'!$X$2:$X$616)),"—")} -> 2.3787234 | J28: —
A30: Lo que pasó después
A31: Respondieron después de la recomendación | B31: =COUNTIFS('Detalle por lead'!$A$2:$A$616,B$6,'Detalle por lead'!$D$2:$D$616,"Sí",'Detalle por lead'!$Y$2:$Y$616,"Sí") -> 101 | C31: =IFERROR(B31/B17,"—") -> 0.6433121 | D31: =COUNTIFS('Detalle por lead'!$A$2:$A$616,D$6,'Detalle por lead'!$D$2:$D$616,"Sí",'Detalle por lead'!$Y$2:$Y$616,"Sí") -> 30 | E31: =IFERROR(D31/D17,"—") -> 0.73170732 | F31: =COUNTIFS('Detalle por lead'!$A$2:$A$616,F$6,'Detalle por lead'!$D$2:$D$616,"Sí",'Detalle por lead'!$Y$2:$Y$616,"Sí") -> 24 | G31: =IFERROR(F31/F17,"—") -> 0.64864865 | H31: =COUNTIFS('Detalle por lead'!$D$2:$D$616,"Sí",'Detalle por lead'!$Y$2:$Y$616,"Sí") -> 155 | I31: =IFERROR(H31/H17,"—") -> 0.65957447 | J31: 20 | K31: 0.71428571
A32: Mediana de minutos del lead en responder | B32: {=IFERROR(MEDIAN(IF(('Detalle por lead'!$A$2:$A$616=B$6)*('Detalle por lead'!$D$2:$D$616="Sí")*ISNUMBER('Detalle por lead'!$AA$2:$AA$616),'Detalle por lead'!$AA$2:$AA$616)),"—")} -> 10.67245 | D32: {=IFERROR(MEDIAN(IF(('Detalle por lead'!$A$2:$A$616=D$6)*('Detalle por lead'!$D$2:$D$616="Sí")*ISNUMBER('Detalle por lead'!$AA$2:$AA$616),'Detalle por lead'!$AA$2:$AA$616)),"—")} -> 8.0662667 | F32: {=IFERROR(MEDIAN(IF(('Detalle por lead'!$A$2:$A$616=F$6)*('Detalle por lead'!$D$2:$D$616="Sí")*ISNUMBER('Detalle por lead'!$AA$2:$AA$616),'Detalle por lead'!$AA$2:$AA$616)),"—")} -> 23.277525 | H32: {=IFERROR(MEDIAN(IF(('Detalle por lead'!$D$2:$D$616="Sí")*ISNUMBER('Detalle por lead'!$AA$2:$AA$616),'Detalle por lead'!$AA$2:$AA$616)),"—")} -> 10.985267 | J32: —
A33: Mediana de minutos del equipo en volver a contestarles | B33: {=IFERROR(MEDIAN(IF(('Detalle por lead'!$A$2:$A$616=B$6)*('Detalle por lead'!$D$2:$D$616="Sí")*ISNUMBER('Detalle por lead'!$AD$2:$AD$616),'Detalle por lead'!$AD$2:$AD$616)),"—")} -> 1.6471333 | D33: {=IFERROR(MEDIAN(IF(('Detalle por lead'!$A$2:$A$616=D$6)*('Detalle por lead'!$D$2:$D$616="Sí")*ISNUMBER('Detalle por lead'!$AD$2:$AD$616),'Detalle por lead'!$AD$2:$AD$616)),"—")} -> 1.9589 | F33: {=IFERROR(MEDIAN(IF(('Detalle por lead'!$A$2:$A$616=F$6)*('Detalle por lead'!$D$2:$D$616="Sí")*ISNUMBER('Detalle por lead'!$AD$2:$AD$616),'Detalle por lead'!$AD$2:$AD$616)),"—")} -> 2.3794833 | H33: {=IFERROR(MEDIAN(IF(('Detalle por lead'!$D$2:$D$616="Sí")*ISNUMBER('Detalle por lead'!$AD$2:$AD$616),'Detalle por lead'!$AD$2:$AD$616)),"—")} -> 1.87285 | J33: 1.784
A34: Respondieron y luego el bot los pasó a Negativo | B34: =COUNTIFS('Detalle por lead'!$A$2:$A$616,B$6,'Detalle por lead'!$D$2:$D$616,"Sí",'Detalle por lead'!$AG$2:$AG$616,"Sí") -> 58 | C34: =IFERROR(B34/B31,"—") -> 0.57425743 | D34: =COUNTIFS('Detalle por lead'!$A$2:$A$616,D$6,'Detalle por lead'!$D$2:$D$616,"Sí",'Detalle por lead'!$AG$2:$AG$616,"Sí") -> 14 | E34: =IFERROR(D34/D31,"—") -> 0.46666667 | F34: =COUNTIFS('Detalle por lead'!$A$2:$A$616,F$6,'Detalle por lead'!$D$2:$D$616,"Sí",'Detalle por lead'!$AG$2:$AG$616,"Sí") -> 13 | G34: =IFERROR(F34/F31,"—") -> 0.54166667 | H34: =COUNTIFS('Detalle por lead'!$D$2:$D$616,"Sí",'Detalle por lead'!$AG$2:$AG$616,"Sí") -> 85 | I34: =IFERROR(H34/H31,"—") -> 0.5483871 | J34: 10 | K34: 0.5
A35: Horas desde su último mensaje hasta que el bot los pasó a Negativo (mediana) | B35: {=IFERROR(MEDIAN(IF(('Detalle por lead'!$A$2:$A$616=B$6)*('Detalle por lead'!$D$2:$D$616="Sí")*ISNUMBER('Detalle por lead'!$AH$2:$AH$616),'Detalle por lead'!$AH$2:$AH$616)),"—")} -> 4 | D35: {=IFERROR(MEDIAN(IF(('Detalle por lead'!$A$2:$A$616=D$6)*('Detalle por lead'!$D$2:$D$616="Sí")*ISNUMBER('Detalle por lead'!$AH$2:$AH$616),'Detalle por lead'!$AH$2:$AH$616)),"—")} -> 4.05 | F35: {=IFERROR(MEDIAN(IF(('Detalle por lead'!$A$2:$A$616=F$6)*('Detalle por lead'!$D$2:$D$616="Sí")*ISNUMBER('Detalle por lead'!$AH$2:$AH$616),'Detalle por lead'!$AH$2:$AH$616)),"—")} -> 3.9 | H35: {=IFERROR(MEDIAN(IF(('Detalle por lead'!$D$2:$D$616="Sí")*ISNUMBER('Detalle por lead'!$AH$2:$AH$616),'Detalle por lead'!$AH$2:$AH$616)),"—")} -> 4 | J35: —
A36: Recibieron la recomendación y el bot los pasó a Negativo | B36: =COUNTIFS('Detalle por lead'!$A$2:$A$616,B$6,'Detalle por lead'!$D$2:$D$616,"Sí",'Detalle por lead'!$AF$2:$AF$616,"Sí") -> 124 | C36: =IFERROR(B36/B17,"—") -> 0.78980892 | D36: =COUNTIFS('Detalle por lead'!$A$2:$A$616,D$6,'Detalle por lead'!$D$2:$D$616,"Sí",'Detalle por lead'!$AF$2:$AF$616,"Sí") -> 28 | E36: =IFERROR(D36/D17,"—") -> 0.68292683 | F36: =COUNTIFS('Detalle por lead'!$A$2:$A$616,F$6,'Detalle por lead'!$D$2:$D$616,"Sí",'Detalle por lead'!$AF$2:$AF$616,"Sí") -> 33 | G36: =IFERROR(F36/F17,"—") -> 0.89189189 | H36: =COUNTIFS('Detalle por lead'!$D$2:$D$616,"Sí",'Detalle por lead'!$AF$2:$AF$616,"Sí") -> 185 | I36: =IFERROR(H36/H17,"—") -> 0.78723404 | J36: —
A37: Ganados (de los que contestaron la pregunta) | B37: =COUNTIFS('Detalle por lead'!$A$2:$A$616,B$6,'Detalle por lead'!$D$2:$D$616,"Sí",'Detalle por lead'!$AK$2:$AK$616,"Sí") -> 3 | C37: =IFERROR(B37/B11,"—") -> 0.018987342 | D37: =COUNTIFS('Detalle por lead'!$A$2:$A$616,D$6,'Detalle por lead'!$D$2:$D$616,"Sí",'Detalle por lead'!$AK$2:$AK$616,"Sí") -> 2 | E37: =IFERROR(D37/D11,"—") -> 0.048780488 | F37: =COUNTIFS('Detalle por lead'!$A$2:$A$616,F$6,'Detalle por lead'!$D$2:$D$616,"Sí",'Detalle por lead'!$AK$2:$AK$616,"Sí") -> 3 | G37: =IFERROR(F37/F11,"—") -> 0.081081081 | H37: =COUNTIFS('Detalle por lead'!$D$2:$D$616,"Sí",'Detalle por lead'!$AK$2:$AK$616,"Sí") -> 8 | I37: =IFERROR(H37/H11,"—") -> 0.033898305 | J37: 1 | K37: 0.035714286
A38: Ganados (todos los leads) | B38: =COUNTIFS('Detalle por lead'!$A$2:$A$616,B$6,'Detalle por lead'!$AK$2:$AK$616,"Sí") -> 6 | C38: =IFERROR(B38/B10,"—") -> 0.015075377 | D38: =COUNTIFS('Detalle por lead'!$A$2:$A$616,D$6,'Detalle por lead'!$AK$2:$AK$616,"Sí") -> 5 | E38: =IFERROR(D38/D10,"—") -> 0.045454545 | F38: =COUNTIFS('Detalle por lead'!$A$2:$A$616,F$6,'Detalle por lead'!$AK$2:$AK$616,"Sí") -> 4 | G38: =IFERROR(F38/F10,"—") -> 0.037383178 | H38: =COUNTIFS('Detalle por lead'!$AK$2:$AK$616,"Sí") -> 15 | I38: =IFERROR(H38/H10,"—") -> 0.024390244 | J38: 2 | K38: 0.028571429
A40: Con audio contra sin audio (de los que contestaron la pregunta)
A41: Con audio: leads | B41: =COUNTIFS('Detalle por lead'!$A$2:$A$616,B$6,'Detalle por lead'!$D$2:$D$616,"Sí",'Detalle por lead'!$Q$2:$Q$616,"Sí") -> 147 | D41: =COUNTIFS('Detalle por lead'!$A$2:$A$616,D$6,'Detalle por lead'!$D$2:$D$616,"Sí",'Detalle por lead'!$Q$2:$Q$616,"Sí") -> 39 | F41: =COUNTIFS('Detalle por lead'!$A$2:$A$616,F$6,'Detalle por lead'!$D$2:$D$616,"Sí",'Detalle por lead'!$Q$2:$Q$616,"Sí") -> 34 | H41: =COUNTIFS('Detalle por lead'!$D$2:$D$616,"Sí",'Detalle por lead'!$Q$2:$Q$616,"Sí") -> 220 | J41: —
A42: Con audio: respondieron después | B42: =COUNTIFS('Detalle por lead'!$A$2:$A$616,B$6,'Detalle por lead'!$D$2:$D$616,"Sí",'Detalle por lead'!$Q$2:$Q$616,"Sí",'Detalle por lead'!$Y$2:$Y$616,"Sí") -> 94 | C42: =IFERROR(B42/B41,"—") -> 0.63945578 | D42: =COUNTIFS('Detalle por lead'!$A$2:$A$616,D$6,'Detalle por lead'!$D$2:$D$616,"Sí",'Detalle por lead'!$Q$2:$Q$616,"Sí",'Detalle por lead'!$Y$2:$Y$616,"Sí") -> 28 | E42: =IFERROR(D42/D41,"—") -> 0.71794872 | F42: =COUNTIFS('Detalle por lead'!$A$2:$A$616,F$6,'Detalle por lead'!$D$2:$D$616,"Sí",'Detalle por lead'!$Q$2:$Q$616,"Sí",'Detalle por lead'!$Y$2:$Y$616,"Sí") -> 22 | G42: =IFERROR(F42/F41,"—") -> 0.64705882 | H42: =COUNTIFS('Detalle por lead'!$D$2:$D$616,"Sí",'Detalle por lead'!$Q$2:$Q$616,"Sí",'Detalle por lead'!$Y$2:$Y$616,"Sí") -> 144 | I42: =IFERROR(H42/H41,"—") -> 0.65454545 | J42: —
A43: Solo texto: leads | B43: =COUNTIFS('Detalle por lead'!$A$2:$A$616,B$6,'Detalle por lead'!$D$2:$D$616,"Sí",'Detalle por lead'!$Q$2:$Q$616,"No") -> 10 | D43: =COUNTIFS('Detalle por lead'!$A$2:$A$616,D$6,'Detalle por lead'!$D$2:$D$616,"Sí",'Detalle por lead'!$Q$2:$Q$616,"No") -> 2 | F43: =COUNTIFS('Detalle por lead'!$A$2:$A$616,F$6,'Detalle por lead'!$D$2:$D$616,"Sí",'Detalle por lead'!$Q$2:$Q$616,"No") -> 3 | H43: =COUNTIFS('Detalle por lead'!$D$2:$D$616,"Sí",'Detalle por lead'!$Q$2:$Q$616,"No") -> 15 | J43: —
A44: Solo texto: respondieron después | B44: =COUNTIFS('Detalle por lead'!$A$2:$A$616,B$6,'Detalle por lead'!$D$2:$D$616,"Sí",'Detalle por lead'!$Q$2:$Q$616,"No",'Detalle por lead'!$Y$2:$Y$616,"Sí") -> 7 | C44: =IFERROR(B44/B43,"—") -> 0.7 | D44: =COUNTIFS('Detalle por lead'!$A$2:$A$616,D$6,'Detalle por lead'!$D$2:$D$616,"Sí",'Detalle por lead'!$Q$2:$Q$616,"No",'Detalle por lead'!$Y$2:$Y$616,"Sí") -> 2 | E44: =IFERROR(D44/D43,"—") -> 1 | F44: =COUNTIFS('Detalle por lead'!$A$2:$A$616,F$6,'Detalle por lead'!$D$2:$D$616,"Sí",'Detalle por lead'!$Q$2:$Q$616,"No",'Detalle por lead'!$Y$2:$Y$616,"Sí") -> 2 | G44: =IFERROR(F44/F43,"—") -> 0.66666667 | H44: =COUNTIFS('Detalle por lead'!$D$2:$D$616,"Sí",'Detalle por lead'!$Q$2:$Q$616,"No",'Detalle por lead'!$Y$2:$Y$616,"Sí") -> 11 | I44: =IFERROR(H44/H43,"—") -> 0.73333333 | J44: —
A45: Vieron el audio: respondieron después | B45: =COUNTIFS('Detalle por lead'!$A$2:$A$616,B$6,'Detalle por lead'!$D$2:$D$616,"Sí",'Detalle por lead'!$U$2:$U$616,"Sí",'Detalle por lead'!$Y$2:$Y$616,"Sí") -> 74 | C45: =IFERROR(B45/B27,"—") -> 0.66666667 | D45: =COUNTIFS('Detalle por lead'!$A$2:$A$616,D$6,'Detalle por lead'!$D$2:$D$616,"Sí",'Detalle por lead'!$U$2:$U$616,"Sí",'Detalle por lead'!$Y$2:$Y$616,"Sí") -> 16 | E45: =IFERROR(D45/D27,"—") -> 0.76190476 | F45: =COUNTIFS('Detalle por lead'!$A$2:$A$616,F$6,'Detalle por lead'!$D$2:$D$616,"Sí",'Detalle por lead'!$U$2:$U$616,"Sí",'Detalle por lead'!$Y$2:$Y$616,"Sí") -> 17 | G45: =IFERROR(F45/F27,"—") -> 0.70833333 | H45: =COUNTIFS('Detalle por lead'!$D$2:$D$616,"Sí",'Detalle por lead'!$U$2:$U$616,"Sí",'Detalle por lead'!$Y$2:$Y$616,"Sí") -> 107 | I45: =IFERROR(H45/H27,"—") -> 0.68589744 | J45: —
...

Sheet Tiempos
A1: DESARROLLO PROFESIONAL SyS
A2: Minutos a la recomendación y si después el lead volvió a escribir
A3: Solo los 236 leads que contestaron la pregunta · corte: 15 oct 2026, 23:59 h (Monterrey)
A4: Rangos (desde, en minutos). Puedes cambiar los límites de la columna A y todo se recalcula.
A5: Desde (min) | B5: Rango | C5: Leads | D5: Respondieron después | E5: % que respondió | F5: Ganados | G5: ISO: leads | H5: ISO: % respondió | I5: Manufactura: leads | J5: Manufactura: % respondió | K5: Core Tools: leads | L5: Core Tools: % respondió
A6: 0 | B6: Menos de 4 min | C6: =COUNTIFS('Detalle por lead'!$D$2:$D$616,"Sí",'Detalle por lead'!$O$2:$O$616,B6) -> 54 | D6: =COUNTIFS('Detalle por lead'!$D$2:$D$616,"Sí",'Detalle por lead'!$O$2:$O$616,B6,'Detalle por lead'!$Y$2:$Y$616,"Sí") -> 41 | E6: =IFERROR(D6/C6,"—") -> 0.75925926 | F6: =COUNTIFS('Detalle por lead'!$D$2:$D$616,"Sí",'Detalle por lead'!$O$2:$O$616,B6,'Detalle por lead'!$AK$2:$AK$616,"Sí") -> 1 | G6: =COUNTIFS('Detalle por lead'!$D$2:$D$616,"Sí",'Detalle por lead'!$A$2:$A$616,"ISO + Calidad",'Detalle por lead'!$O$2:$O$616,B6) -> 32 | H6: =IFERROR(COUNTIFS('Detalle por lead'!$D$2:$D$616,"Sí",'Detalle por lead'!$A$2:$A$616,"ISO + Calidad",'Detalle por lead'!$O$2:$O$616,B6,'Detalle por lead'!$Y$2:$Y$616,"Sí")/G6,"—") -> 0.65625 | I6: =COUNTIFS('Detalle por lead'!$D$2:$D$616,"Sí",'Detalle por lead'!$A$2:$A$616,"Manufactura y Calidad",'Detalle por lead'!$O$2:$O$616,B6) -> 15 | J6: =IFERROR(COUNTIFS('Detalle por lead'!$D$2:$D$616,"Sí",'Detalle por lead'!$A$2:$A$616,"Manufactura y Calidad",'Detalle por lead'!$O$2:$O$616,B6,'Detalle por lead'!$Y$2:$Y$616,"Sí")/I6,"—") -> 0.86666667 | K6: =COUNTIFS('Detalle por lead'!$D$2:$D$616,"Sí",'Detalle por lead'!$A$2:$A$616,"Core Tools Premium",'Detalle por lead'!$O$2:$O$616,B6) -> 7 | L6: =IFERROR(COUNTIFS('Detalle por lead'!$D$2:$D$616,"Sí",'Detalle por lead'!$A$2:$A$616,"Core Tools Premium",'Detalle por lead'!$O$2:$O$616,B6,'Detalle por lead'!$Y$2:$Y$616,"Sí")/K6,"—") -> 1
A7: 4 | B7: 4 a 6 min | C7: =COUNTIFS('Detalle por lead'!$D$2:$D$616,"Sí",'Detalle por lead'!$O$2:$O$616,B7) -> 53 | D7: =COUNTIFS('Detalle por lead'!$D$2:$D$616,"Sí",'Detalle por lead'!$O$2:$O$616,B7,'Detalle por lead'!$Y$2:$Y$616,"Sí") -> 32 | E7: =IFERROR(D7/C7,"—") -> 0.60377358 | F7: =COUNTIFS('Detalle por lead'!$D$2:$D$616,"Sí",'Detalle por lead'!$O$2:$O$616,B7,'Detalle por lead'!$AK$2:$AK$616,"Sí") -> 2 | G7: =COUNTIFS('Detalle por lead'!$D$2:$D$616,"Sí",'Detalle por lead'!$A$2:$A$616,"ISO + Calidad",'Detalle por lead'!$O$2:$O$616,B7) -> 33 | H7: =IFERROR(COUNTIFS('Detalle por lead'!$D$2:$D$616,"Sí",'Detalle por lead'!$A$2:$A$616,"ISO + Calidad",'Detalle por lead'!$O$2:$O$616,B7,'Detalle por lead'!$Y$2:$Y$616,"Sí")/G7,"—") -> 0.66666667 | I7: =COUNTIFS('Detalle por lead'!$D$2:$D$616,"Sí",'Detalle por lead'!$A$2:$A$616,"Manufactura y Calidad",'Detalle por lead'!$O$2:$O$616,B7) -> 10 | J7: =IFERROR(COUNTIFS('Detalle por lead'!$D$2:$D$616,"Sí",'Detalle por lead'!$A$2:$A$616,"Manufactura y Calidad",'Detalle por lead'!$O$2:$O$616,B7,'Detalle por lead'!$Y$2:$Y$616,"Sí")/I7,"—") -> 0.6 | K7: =COUNTIFS('Detalle por lead'!$D$2:$D$616,"Sí",'Detalle por lead'!$A$2:$A$616,"Core Tools Premium",'Detalle por lead'!$O$2:$O$616,B7) -> 10 | L7: =IFERROR(COUNTIFS('Detalle por lead'!$D$2:$D$616,"Sí",'Detalle por lead'!$A$2:$A$616,"Core Tools Premium",'Detalle por lead'!$O$2:$O$616,B7,'Detalle por lead'!$Y$2:$Y$616,"Sí")/K7,"—") -> 0.4
A8: 6 | B8: 6 a 10 min | C8: =COUNTIFS('Detalle por lead'!$D$2:$D$616,"Sí",'Detalle por lead'!$O$2:$O$616,B8) -> 52 | D8: =COUNTIFS('Detalle por lead'!$D$2:$D$616,"Sí",'Detalle por lead'!$O$2:$O$616,B8,'Detalle por lead'!$Y$2:$Y$616,"Sí") -> 34 | E8: =IFERROR(D8/C8,"—") -> 0.65384615 | F8: =COUNTIFS('Detalle por lead'!$D$2:$D$616,"Sí",'Detalle por lead'!$O$2:$O$616,B8,'Detalle por lead'!$AK$2:$AK$616,"Sí") -> 0 | G8: =COUNTIFS('Detalle por lead'!$D$2:$D$616,"Sí",'Detalle por lead'!$A$2:$A$616,"ISO + Calidad",'Detalle por lead'!$O$2:$O$616,B8) -> 39 | H8: =IFERROR(COUNTIFS('Detalle por lead'!$D$2:$D$616,"Sí",'Detalle por lead'!$A$2:$A$616,"ISO + Calidad",'Detalle por lead'!$O$2:$O$616,B8,'Detalle por lead'!$Y$2:$Y$616,"Sí")/G8,"—") -> 0.64102564 | I8: =COUNTIFS('Detalle por lead'!$D$2:$D$616,"Sí",'Detalle por lead'!$A$2:$A$616,"Manufactura y Calidad",'Detalle por lead'!$O$2:$O$616,B8) -> 5 | J8: =IFERROR(COUNTIFS('Detalle por lead'!$D$2:$D$616,"Sí",'Detalle por lead'!$A$2:$A$616,"Manufactura y Calidad",'Detalle por lead'!$O$2:$O$616,B8,'Detalle por lead'!$Y$2:$Y$616,"Sí")/I8,"—") -> 0.6 | K8: =COUNTIFS('Detalle por lead'!$D$2:$D$616,"Sí",'Detalle por lead'!$A$2:$A$616,"Core Tools Premium",'Detalle por lead'!$O$2:$O$616,B8) -> 8 | L8: =IFERROR(COUNTIFS('Detalle por lead'!$D$2:$D$616,"Sí",'Detalle por lead'!$A$2:$A$616,"Core Tools Premium",'Detalle por lead'!$O$2:$O$616,B8,'Detalle por lead'!$Y$2:$Y$616,"Sí")/K8,"—") -> 0.75
A9: 10 | B9: 10 a 30 min | C9: =COUNTIFS('Detalle por lead'!$D$2:$D$616,"Sí",'Detalle por lead'!$O$2:$O$616,B9) -> 56 | D9: =COUNTIFS('Detalle por lead'!$D$2:$D$616,"Sí",'Detalle por lead'!$O$2:$O$616,B9,'Detalle por lead'!$Y$2:$Y$616,"Sí") -> 37 | E9: =IFERROR(D9/C9,"—") -> 0.66071429 | F9: =COUNTIFS('Detalle por lead'!$D$2:$D$616,"Sí",'Detalle por lead'!$O$2:$O$616,B9,'Detalle por lead'!$AK$2:$AK$616,"Sí") -> 5 | G9: =COUNTIFS('Detalle por lead'!$D$2:$D$616,"Sí",'Detalle por lead'!$A$2:$A$616,"ISO + Calidad",'Detalle por lead'!$O$2:$O$616,B9) -> 40 | H9: =IFERROR(COUNTIFS('Detalle por lead'!$D$2:$D$616,"Sí",'Detalle por lead'!$A$2:$A$616,"ISO + Calidad",'Detalle por lead'!$O$2:$O$616,B9,'Detalle por lead'!$Y$2:$Y$616,"Sí")/G9,"—") -> 0.65 | I9: =COUNTIFS('Detalle por lead'!$D$2:$D$616,"Sí",'Detalle por lead'!$A$2:$A$616,"Manufactura y Calidad",'Detalle por lead'!$O$2:$O$616,B9) -> 9 | J9: =IFERROR(COUNTIFS('Detalle por lead'!$D$2:$D$616,"Sí",'Detalle por lead'!$A$2:$A$616,"Manufactura y Calidad",'Detalle por lead'!$O$2:$O$616,B9,'Detalle por lead'!$Y$2:$Y$616,"Sí")/I9,"—") -> 0.66666667 | K9: =COUNTIFS('Detalle por lead'!$D$2:$D$616,"Sí",'Detalle por lead'!$A$2:$A$616,"Core Tools Premium",'Detalle por lead'!$O$2:$O$616,B9) -> 7 | L9: =IFERROR(COUNTIFS('Detalle por lead'!$D$2:$D$616,"Sí",'Detalle por lead'!$A$2:$A$616,"Core Tools Premium",'Detalle por lead'!$O$2:$O$616,B9,'Detalle por lead'!$Y$2:$Y$616,"Sí")/K9,"—") -> 0.71428571
A10: 30 | B10: 30 min o más | C10: =COUNTIFS('Detalle por lead'!$D$2:$D$616,"Sí",'Detalle por lead'!$O$2:$O$616,B10) -> 20 | D10: =COUNTIFS('Detalle por lead'!$D$2:$D$616,"Sí",'Detalle por lead'!$O$2:$O$616,B10,'Detalle por lead'!$Y$2:$Y$616,"Sí") -> 11 | E10: =IFERROR(D10/C10,"—") -> 0.55 | F10: =COUNTIFS('Detalle por lead'!$D$2:$D$616,"Sí",'Detalle por lead'!$O$2:$O$616,B10,'Detalle por lead'!$AK$2:$AK$616,"Sí") -> 0 | G10: =COUNTIFS('Detalle por lead'!$D$2:$D$616,"Sí",'Detalle por lead'!$A$2:$A$616,"ISO + Calidad",'Detalle por lead'!$O$2:$O$616,B10) -> 13 | H10: =IFERROR(COUNTIFS('Detalle por lead'!$D$2:$D$616,"Sí",'Detalle por lead'!$A$2:$A$616,"ISO + Calidad",'Detalle por lead'!$O$2:$O$616,B10,'Detalle por lead'!$Y$2:$Y$616,"Sí")/G10,"—") -> 0.53846154 | I10: =COUNTIFS('Detalle por lead'!$D$2:$D$616,"Sí",'Detalle por lead'!$A$2:$A$616,"Manufactura y Calidad",'Detalle por lead'!$O$2:$O$616,B10) -> 2 | J10: =IFERROR(COUNTIFS('Detalle por lead'!$D$2:$D$616,"Sí",'Detalle por lead'!$A$2:$A$616,"Manufactura y Calidad",'Detalle por lead'!$O$2:$O$616,B10,'Detalle por lead'!$Y$2:$Y$616,"Sí")/I10,"—") -> 1 | K10: =COUNTIFS('Detalle por lead'!$D$2:$D$616,"Sí",'Detalle por lead'!$A$2:$A$616,"Core Tools Premium",'Detalle por lead'!$O$2:$O$616,B10) -> 5 | L10: =IFERROR(COUNTIFS('Detalle por lead'!$D$2:$D$616,"Sí",'Detalle por lead'!$A$2:$A$616,"Core Tools Premium",'Detalle por lead'!$O$2:$O$616,B10,'Detalle por lead'!$Y$2:$Y$616,"Sí")/K10,"—") -> 0.4
B11: Total | C11: =SUM(C6:C10) -> 235 | D11: =SUM(D6:D10) -> 155 | E11: =IFERROR(D11/C11,"—") -> 0.65957447 | F11: =SUM(F6:F10) -> 8 | G11: =SUM(G6:G10) -> 157 | I11: =SUM(I6:I10) -> 41 | K11: =SUM(K6:K10) -> 37
A12: Con recomendación en menos de 4 min respondió el 75.9% (41 de 54); con más espera, el 63.0% (114 de 181). Prueba exacta de Fisher: p = 0.10. La diferencia se repite en los tres embudos, pero todavía no es concluyente.
A14: Medida | B14: Primer mensaje del equipo | C14: Recomendación (audio) | D14: Del aviso al audio | E14: Lead en responder la recomendación | F14: Equipo en volver a contestar
A15: Mediana | B15: {=IFERROR(MEDIAN(IF(('Detalle por lead'!$D$2:$D$616="Sí")*ISNUMBER('Detalle por lead'!$L$2:$L$616),'Detalle por lead'!$L$2:$L$616)),"—")} -> 2.16335 | C15: {=IFERROR(MEDIAN(IF(('Detalle por lead'!$D$2:$D$616="Sí")*ISNUMBER('Detalle por lead'!$N$2:$N$616),'Detalle por lead'!$N$2:$N$616)),"—")} -> 6.4108167 | D15: {=IFERROR(MEDIAN(IF(('Detalle por lead'!$D$2:$D$616="Sí")*ISNUMBER('Detalle por lead'!$V$2:$V$616),'Detalle por lead'!$V$2:$V$616)),"—")} -> 3.78 | E15: {=IFERROR(MEDIAN(IF(('Detalle por lead'!$D$2:$D$616="Sí")*ISNUMBER('Detalle por lead'!$AA$2:$AA$616),'Detalle por lead'!$AA$2:$AA$616)),"—")} -> 10.985267 | F15: {=IFERROR(MEDIAN(IF(('Detalle por lead'!$D$2:$D$616="Sí")*ISNUMBER('Detalle por lead'!$AD$2:$AD$616),'Detalle por lead'!$AD$2:$AD$616)),"—")} -> 1.87285
A16: Promedio | B16: {=IFERROR(AVERAGE(IF(('Detalle por lead'!$D$2:$D$616="Sí")*ISNUMBER('Detalle por lead'!$L$2:$L$616),'Detalle por lead'!$L$2:$L$616)),"—")} -> 17.984247 | C16: {=IFERROR(AVERAGE(IF(('Detalle por lead'!$D$2:$D$616="Sí")*ISNUMBER('Detalle por lead'!$N$2:$N$616),'Detalle por lead'!$N$2:$N$616)),"—")} -> 35.994497 | D16: {=IFERROR(AVERAGE(IF(('Detalle por lead'!$D$2:$D$616="Sí")*ISNUMBER('Detalle por lead'!$V$2:$V$616),'Detalle por lead'!$V$2:$V$616)),"—")} -> 8.011194 | E16: {=IFERROR(AVERAGE(IF(('Detalle por lead'!$D$2:$D$616="Sí")*ISNUMBER('Detalle por lead'!$AA$2:$AA$616),'Detalle por lead'!$AA$2:$AA$616)),"—")} -> 392.09678 | F16: {=IFERROR(AVERAGE(IF(('Detalle por lead'!$D$2:$D$616="Sí")*ISNUMBER('Detalle por lead'!$AD$2:$AD$616),'Detalle por lead'!$AD$2:$AD$616)),"—")} -> 172.93293
A17: Percentil 75 | B17: {=IFERROR(PERCENTILE(IF(('Detalle por lead'!$D$2:$D$616="Sí")*ISNUMBER('Detalle por lead'!$L$2:$L$616),'Detalle por lead'!$L$2:$L$616),0.75),"—")} -> 6.1430417 | C17: {=IFERROR(PERCENTILE(IF(('Detalle por lead'!$D$2:$D$616="Sí")*ISNUMBER('Detalle por lead'!$N$2:$N$616),'Detalle por lead'!$N$2:$N$616),0.75),"—")} -> 11.922458 | D17: {=IFERROR(PERCENTILE(IF(('Detalle por lead'!$D$2:$D$616="Sí")*ISNUMBER('Detalle por lead'!$V$2:$V$616),'Detalle por lead'!$V$2:$V$616),0.75),"—")} -> 5.22 | E17: {=IFERROR(PERCENTILE(IF(('Detalle por lead'!$D$2:$D$616="Sí")*ISNUMBER('Detalle por lead'!$AA$2:$AA$616),'Detalle por lead'!$AA$2:$AA$616),0.75),"—")} -> 43.540733 | F17: {=IFERROR(PERCENTILE(IF(('Detalle por lead'!$D$2:$D$616="Sí")*ISNUMBER('Detalle por lead'!$AD$2:$AD$616),'Detalle por lead'!$AD$2:$AD$616),0.75),"—")} -> 4.5486167
A18: Percentil 90 | B18: {=IFERROR(PERCENTILE(IF(('Detalle por lead'!$D$2:$D$616="Sí")*ISNUMBER('Detalle por lead'!$L$2:$L$616),'Detalle por lead'!$L$2:$L$616),0.9),"—")} -> 17.21212 | C18: {=IFERROR(PERCENTILE(IF(('Detalle por lead'!$D$2:$D$616="Sí")*ISNUMBER('Detalle por lead'!$N$2:$N$616),'Detalle por lead'!$N$2:$N$616),0.9),"—")} -> 22.062023 | D18: {=IFERROR(PERCENTILE(IF(('Detalle por lead'!$D$2:$D$616="Sí")*ISNUMBER('Detalle por lead'!$V$2:$V$616),'Detalle por lead'!$V$2:$V$616),0.9),"—")} -> 7.04 | E18: {=IFERROR(PERCENTILE(IF(('Detalle por lead'!$D$2:$D$616="Sí")*ISNUMBER('Detalle por lead'!$AA$2:$AA$616),'Detalle por lead'!$AA$2:$AA$616),0.9),"—")} -> 1040.8782 | F18: {=IFERROR(PERCENTILE(IF(('Detalle por lead'!$D$2:$D$616="Sí")*ISNUMBER('Detalle por lead'!$AD$2:$AD$616),'Detalle por lead'!$AD$2:$AD$616),0.9),"—")} -> 11.53254
A19: Mínimo | B19: {=IFERROR(MIN(IF(('Detalle por lead'!$D$2:$D$616="Sí")*ISNUMBER('Detalle por lead'!$L$2:$L$616),'Detalle por lead'!$L$2:$L$616)),"—")} -> 0.038133332 | C19: {=IFERROR(MIN(IF(('Detalle por lead'!$D$2:$D$616="Sí")*ISNUMBER('Detalle por lead'!$N$2:$N$616),'Detalle por lead'!$N$2:$N$616)),"—")} -> 0.16340002 | D19: {=IFERROR(MIN(IF(('Detalle por lead'!$D$2:$D$616="Sí")*ISNUMBER('Detalle por lead'!$V$2:$V$616),'Detalle por lead'!$V$2:$V$616)),"—")} -> 0.21 | E19: {=IFERROR(MIN(IF(('Detalle por lead'!$D$2:$D$616="Sí")*ISNUMBER('Detalle por lead'!$AA$2:$AA$616),'Detalle por lead'!$AA$2:$AA$616)),"—")} -> 0.20384999 | F19: {=IFERROR(MIN(IF(('Detalle por lead'!$D$2:$D$616="Sí")*ISNUMBER('Detalle por lead'!$AD$2:$AD$616),'Detalle por lead'!$AD$2:$AD$616)),"—")} -> 0.16093333
A20: Máximo | B20: {=IFERROR(MAX(IF(('Detalle por lead'!$D$2:$D$616="Sí")*ISNUMBER('Detalle por lead'!$L$2:$L$616),'Detalle por lead'!$L$2:$L$616)),"—")} -> 573.03305 | C20: {=IFERROR(MAX(IF(('Detalle por lead'!$D$2:$D$616="Sí")*ISNUMBER('Detalle por lead'!$N$2:$N$616),'Detalle por lead'!$N$2:$N$616)),"—")} -> 1204.0598 | D20: {=IFERROR(MAX(IF(('Detalle por lead'!$D$2:$D$616="Sí")*ISNUMBER('Detalle por lead'!$V$2:$V$616),'Detalle por lead'!$V$2:$V$616)),"—")} -> 652.87 | E20: {=IFERROR(MAX(IF(('Detalle por lead'!$D$2:$D$616="Sí")*ISNUMBER('Detalle por lead'!$AA$2:$AA$616),'Detalle por lead'!$AA$2:$AA$616)),"—")} -> 7156.4426 | F20: {=IFERROR(MAX(IF(('Detalle por lead'!$D$2:$D$616="Sí")*ISNUMBER('Detalle por lead'!$AD$2:$AD$616),'Detalle por lead'!$AD$2:$AD$616)),"—")} -> 6977.7025
A21: Leads medidos | B21: =SUMPRODUCT(('Detalle por lead'!$D$2:$D$616="Sí")*ISNUMBER('Detalle por lead'!$L$2:$L$616)) -> 235 | C21: =SUMPRODUCT(('Detalle por lead'!$D$2:$D$616="Sí")*ISNUMBER('Detalle por lead'!$N$2:$N$616)) -> 235 | D21: =SUMPRODUCT(('Detalle por lead'!$D$2:$D$616="Sí")*ISNUMBER('Detalle por lead'!$V$2:$V$616)) -> 201 | E21: =SUMPRODUCT(('Detalle por lead'!$D$2:$D$616="Sí")*ISNUMBER('Detalle por lead'!$AA$2:$AA$616)) -> 155 | F21: =SUMPRODUCT(('Detalle por lead'!$D$2:$D$616="Sí")*ISNUMBER('Detalle por lead'!$AD$2:$AD$616)) -> 153
A22: Minutos de reloj desde la respuesta del lead. «Del aviso al audio» = del «te mando un audio» al audio (grabarlo y subirlo).

Sheet Por persona
A1: DESARROLLO PROFESIONAL SyS
A2: Quién dio la recomendación
A3: Solo leads que contestaron la pregunta. Minutos desde la respuesta del lead hasta la recomendación · corte: 15 oct 2026, 23:59 h (Monterrey)
A5: Persona | B5: Recomendaciones | C5: Mediana de minutos | D5: Promedio de minutos | E5: Máximo de minutos | F5: Respondieron después | G5: % que respondió | H5: Duración media del audio (s) | I5: % que vio el audio | J5: Cursos por recomendación | K5: El bot los pasó a Negativo después de que respondieron | L5: Ganados
A6: Salma | B6: =COUNTIFS('Detalle por lead'!$D$2:$D$616,"Sí",'Detalle por lead'!$R$2:$R$616,$A6) -> 84 | C6: {=IFERROR(MEDIAN(IF(('Detalle por lead'!$D$2:$D$616="Sí")*('Detalle por lead'!$R$2:$R$616=$A6)*ISNUMBER('Detalle por lead'!$N$2:$N$616),'Detalle por lead'!$N$2:$N$616)),"—")} -> 6.0998417 | D6: {=IFERROR(AVERAGE(IF(('Detalle por lead'!$D$2:$D$616="Sí")*('Detalle por lead'!$R$2:$R$616=$A6)*ISNUMBER('Detalle por lead'!$N$2:$N$616),'Detalle por lead'!$N$2:$N$616)),"—")} -> 54.598876 | E6: {=IFERROR(MAX(IF(('Detalle por lead'!$D$2:$D$616="Sí")*('Detalle por lead'!$R$2:$R$616=$A6)*ISNUMBER('Detalle por lead'!$N$2:$N$616),'Detalle por lead'!$N$2:$N$616)),"—")} -> 843.73367 | F6: =COUNTIFS('Detalle por lead'!$D$2:$D$616,"Sí",'Detalle por lead'!$R$2:$R$616,$A6,'Detalle por lead'!$Y$2:$Y$616,"Sí") -> 56 | G6: =IFERROR(F6/B6,"—") -> 0.66666667 | H6: {=IFERROR(AVERAGE(IF(('Detalle por lead'!$D$2:$D$616="Sí")*('Detalle por lead'!$R$2:$R$616=$A6)*ISNUMBER('Detalle por lead'!$T$2:$T$616),'Detalle por lead'!$T$2:$T$616)),"—")} -> 111.51084 | I6: =IFERROR(COUNTIFS('Detalle por lead'!$D$2:$D$616,"Sí",'Detalle por lead'!$R$2:$R$616,$A6,'Detalle por lead'!$U$2:$U$616,"Sí")/COUNTIFS('Detalle por lead'!$D$2:$D$616,"Sí",'Detalle por lead'!$R$2:$R$616,$A6,'Detalle por lead'!$Q$2:$Q$616,"Sí"),"—") -> 0.78313253 | J6: {=IFERROR(AVERAGE(IF(('Detalle por lead'!$D$2:$D$616="Sí")*('Detalle por lead'!$R$2:$R$616=$A6)*ISNUMBER('Detalle por lead'!$X$2:$X$616),'Detalle por lead'!$X$2:$X$616)),"—")} -> 1.9404762 | K6: =COUNTIFS('Detalle por lead'!$D$2:$D$616,"Sí",'Detalle por lead'!$R$2:$R$616,$A6,'Detalle por lead'!$AG$2:$AG$616,"Sí") -> 31 | L6: =COUNTIFS('Detalle por lead'!$D$2:$D$616,"Sí",'Detalle por lead'!$R$2:$R$616,$A6,'Detalle por lead'!$AK$2:$AK$616,"Sí") -> 1
A7: Alexander | B7: =COUNTIFS('Detalle por lead'!$D$2:$D$616,"Sí",'Detalle por lead'!$R$2:$R$616,$A7) -> 64 | C7: {=IFERROR(MEDIAN(IF(('Detalle por lead'!$D$2:$D$616="Sí")*('Detalle por lead'!$R$2:$R$616=$A7)*ISNUMBER('Detalle por lead'!$N$2:$N$616),'Detalle por lead'!$N$2:$N$616)),"—")} -> 7.2016583 | D7: {=IFERROR(AVERAGE(IF(('Detalle por lead'!$D$2:$D$616="Sí")*('Detalle por lead'!$R$2:$R$616=$A7)*ISNUMBER('Detalle por lead'!$N$2:$N$616),'Detalle por lead'!$N$2:$N$616)),"—")} -> 37.581215 | E7: {=IFERROR(MAX(IF(('Detalle por lead'!$D$2:$D$616="Sí")*('Detalle por lead'!$R$2:$R$616=$A7)*ISNUMBER('Detalle por lead'!$N$2:$N$616),'Detalle por lead'!$N$2:$N$616)),"—")} -> 1204.0598 | F7: =COUNTIFS('Detalle por lead'!$D$2:$D$616,"Sí",'Detalle por lead'!$R$2:$R$616,$A7,'Detalle por lead'!$Y$2:$Y$616,"Sí") -> 40 | G7: =IFERROR(F7/B7,"—") -> 0.625 | H7: {=IFERROR(AVERAGE(IF(('Detalle por lead'!$D$2:$D$616="Sí")*('Detalle por lead'!$R$2:$R$616=$A7)*ISNUMBER('Detalle por lead'!$T$2:$T$616),'Detalle por lead'!$T$2:$T$616)),"—")} -> 84.55082 | I7: =IFERROR(COUNTIFS('Detalle por lead'!$D$2:$D$616,"Sí",'Detalle por lead'!$R$2:$R$616,$A7,'Detalle por lead'!$U$2:$U$616,"Sí")/COUNTIFS('Detalle por lead'!$D$2:$D$616,"Sí",'Detalle por lead'!$R$2:$R$616,$A7,'Detalle por lead'!$Q$2:$Q$616,"Sí"),"—") -> 0.67213115 | J7: {=IFERROR(AVERAGE(IF(('Detalle por lead'!$D$2:$D$616="Sí")*('Detalle por lead'!$R$2:$R$616=$A7)*ISNUMBER('Detalle por lead'!$X$2:$X$616),'Detalle por lead'!$X$2:$X$616)),"—")} -> 2.75 | K7: =COUNTIFS('Detalle por lead'!$D$2:$D$616,"Sí",'Detalle por lead'!$R$2:$R$616,$A7,'Detalle por lead'!$AG$2:$AG$616,"Sí") -> 20 | L7: =COUNTIFS('Detalle por lead'!$D$2:$D$616,"Sí",'Detalle por lead'!$R$2:$R$616,$A7,'Detalle por lead'!$AK$2:$AK$616,"Sí") -> 3
A8: Victoria | B8: =COUNTIFS('Detalle por lead'!$D$2:$D$616,"Sí",'Detalle por lead'!$R$2:$R$616,$A8) -> 48 | C8: {=IFERROR(MEDIAN(IF(('Detalle por lead'!$D$2:$D$616="Sí")*('Detalle por lead'!$R$2:$R$616=$A8)*ISNUMBER('Detalle por lead'!$N$2:$N$616),'Detalle por lead'!$N$2:$N$616)),"—")} -> 4.8918833 | D8: {=IFERROR(AVERAGE(IF(('Detalle por lead'!$D$2:$D$616="Sí")*('Detalle por lead'!$R$2:$R$616=$A8)*ISNUMBER('Detalle por lead'!$N$2:$N$616),'Detalle por lead'!$N$2:$N$616)),"—")} -> 7.3510229 | E8: {=IFERROR(MAX(IF(('Detalle por lead'!$D$2:$D$616="Sí")*('Detalle por lead'!$R$2:$R$616=$A8)*ISNUMBER('Detalle por lead'!$N$2:$N$616),'Detalle por lead'!$N$2:$N$616)),"—")} -> 42.176817 | F8: =COUNTIFS('Detalle por lead'!$D$2:$D$616,"Sí",'Detalle por lead'!$R$2:$R$616,$A8,'Detalle por lead'!$Y$2:$Y$616,"Sí") -> 34 | G8: =IFERROR(F8/B8,"—") -> 0.70833333 | H8: {=IFERROR(AVERAGE(IF(('Detalle por lead'!$D$2:$D$616="Sí")*('Detalle por lead'!$R$2:$R$616=$A8)*ISNUMBER('Detalle por lead'!$T$2:$T$616),'Detalle por lead'!$T$2:$T$616)),"—")} -> 100.555 | I8: =IFERROR(COUNTIFS('Detalle por lead'!$D$2:$D$616,"Sí",'Detalle por lead'!$R$2:$R$616,$A8,'Detalle por lead'!$U$2:$U$616,"Sí")/COUNTIFS('Detalle por lead'!$D$2:$D$616,"Sí",'Detalle por lead'!$R$2:$R$616,$A8,'Detalle por lead'!$Q$2:$Q$616,"Sí"),"—") -> 0.725 | J8: {=IFERROR(AVERAGE(IF(('Detalle por lead'!$D$2:$D$616="Sí")*('Detalle por lead'!$R$2:$R$616=$A8)*ISNUMBER('Detalle por lead'!$X$2:$X$616),'Detalle por lead'!$X$2:$X$616)),"—")} -> 3.0833333 | K8: =COUNTIFS('Detalle por lead'!$D$2:$D$616,"Sí",'Detalle por lead'!$R$2:$R$616,$A8,'Detalle por lead'!$AG$2:$AG$616,"Sí") -> 23 | L8: =COUNTIFS('Detalle por lead'!$D$2:$D$616,"Sí",'Detalle por lead'!$R$2:$R$616,$A8,'Detalle por lead'!$AK$2:$AK$616,"Sí") -> 2
A9: Joceline | B9: =COUNTIFS('Detalle por lead'!$D$2:$D$616,"Sí",'Detalle por lead'!$R$2:$R$616,$A9) -> 39 | C9: {=IFERROR(MEDIAN(IF(('Detalle por lead'!$D$2:$D$616="Sí")*('Detalle por lead'!$R$2:$R$616=$A9)*ISNUMBER('Detalle por lead'!$N$2:$N$616),'Detalle por lead'!$N$2:$N$616)),"—")} -> 8.4338833 | D9: {=IFERROR(AVERAGE(IF(('Detalle por lead'!$D$2:$D$616="Sí")*('Detalle por lead'!$R$2:$R$616=$A9)*ISNUMBER('Detalle por lead'!$N$2:$N$616),'Detalle por lead'!$N$2:$N$616)),"—")} -> 28.573189 | E9: {=IFERROR(MAX(IF(('Detalle por lead'!$D$2:$D$616="Sí")*('Detalle por lead'!$R$2:$R$616=$A9)*ISNUMBER('Detalle por lead'!$N$2:$N$616),'Detalle por lead'!$N$2:$N$616)),"—")} -> 573.03305 | F9: =COUNTIFS('Detalle por lead'!$D$2:$D$616,"Sí",'Detalle por lead'!$R$2:$R$616,$A9,'Detalle por lead'!$Y$2:$Y$616,"Sí") -> 25 | G9: =IFERROR(F9/B9,"—") -> 0.64102564 | H9: {=IFERROR(AVERAGE(IF(('Detalle por lead'!$D$2:$D$616="Sí")*('Detalle por lead'!$R$2:$R$616=$A9)*ISNUMBER('Detalle por lead'!$T$2:$T$616),'Detalle por lead'!$T$2:$T$616)),"—")} -> 113.63056 | I9: =IFERROR(COUNTIFS('Detalle por lead'!$D$2:$D$616,"Sí",'Detalle por lead'!$R$2:$R$616,$A9,'Detalle por lead'!$U$2:$U$616,"Sí")/COUNTIFS('Detalle por lead'!$D$2:$D$616,"Sí",'Detalle por lead'!$R$2:$R$616,$A9,'Detalle por lead'!$Q$2:$Q$616,"Sí"),"—") -> 0.58333333 | J9: {=IFERROR(AVERAGE(IF(('Detalle por lead'!$D$2:$D$616="Sí")*('Detalle por lead'!$R$2:$R$616=$A9)*ISNUMBER('Detalle por lead'!$X$2:$X$616),'Detalle por lead'!$X$2:$X$616)),"—")} -> 1.8461538 | K9: =COUNTIFS('Detalle por lead'!$D$2:$D$616,"Sí",'Detalle por lead'!$R$2:$R$616,$A9,'Detalle por lead'!$AG$2:$AG$616,"Sí") -> 11 | L9: =COUNTIFS('Detalle por lead'!$D$2:$D$616,"Sí",'Detalle por lead'!$R$2:$R$616,$A9,'Detalle por lead'!$AK$2:$AK$616,"Sí") -> 2
A10: Total | B10: =SUM(B6:B9) -> 235 | F10: =SUM(F6:F9) -> 155 | G10: =IFERROR(F10/B10,"—") -> 0.65957447 | K10: =SUM(K6:K9) -> 85 | L10: =SUM(L6:L9) -> 8
A11: Joceline es auxiliar (apoya el chat); los demás son asesores. Con pocos casos por persona, un solo lead mueve mucho los porcentajes.
A13: Recomendaciones por persona y embudo
A14: Persona | B14: ISO + Calidad: recomendaciones | C14: Manufactura y Calidad: recomendaciones | D14: Core Tools Premium: recomendaciones | E14: ISO + Calidad: mediana de min | F14: Manufactura y Calidad: mediana de min | G14: Core Tools Premium: mediana de min
A15: Salma | B15: =COUNTIFS('Detalle por lead'!$D$2:$D$616,"Sí",'Detalle por lead'!$R$2:$R$616,"Salma",'Detalle por lead'!$A$2:$A$616,"ISO + Calidad") -> 56 | C15: =COUNTIFS('Detalle por lead'!$D$2:$D$616,"Sí",'Detalle por lead'!$R$2:$R$616,"Salma",'Detalle por lead'!$A$2:$A$616,"Manufactura y Calidad") -> 16 | D15: =COUNTIFS('Detalle por lead'!$D$2:$D$616,"Sí",'Detalle por lead'!$R$2:$R$616,"Salma",'Detalle por lead'!$A$2:$A$616,"Core Tools Premium") -> 12 | E15: {=IFERROR(MEDIAN(IF(('Detalle por lead'!$D$2:$D$616="Sí")*('Detalle por lead'!$R$2:$R$616="Salma")*('Detalle por lead'!$A$2:$A$616="ISO + Calidad")*ISNUMBER('Detalle por lead'!$N$2:$N$616),'Detalle por lead'!$N$2:$N$616)),"—")} -> 6.0998417 | F15: {=IFERROR(MEDIAN(IF(('Detalle por lead'!$D$2:$D$616="Sí")*('Detalle por lead'!$R$2:$R$616="Salma")*('Detalle por lead'!$A$2:$A$616="Manufactura y Calidad")*ISNUMBER('Detalle por lead'!$N$2:$N$616),'Detalle por lead'!$N$2:$N$616)),"—")} -> 4.6318833 | G15: {=IFERROR(MEDIAN(IF(('Detalle por lead'!$D$2:$D$616="Sí")*('Detalle por lead'!$R$2:$R$616="Salma")*('Detalle por lead'!$A$2:$A$616="Core Tools Premium")*ISNUMBER('Detalle por lead'!$N$2:$N$616),'Detalle por lead'!$N$2:$N$616)),"—")} -> 6.5289167
A16: Alexander | B16: =COUNTIFS('Detalle por lead'!$D$2:$D$616,"Sí",'Detalle por lead'!$R$2:$R$616,"Alexander",'Detalle por lead'!$A$2:$A$616,"ISO + Calidad") -> 42 | C16: =COUNTIFS('Detalle por lead'!$D$2:$D$616,"Sí",'Detalle por lead'!$R$2:$R$616,"Alexander",'Detalle por lead'!$A$2:$A$616,"Manufactura y Calidad") -> 11 | D16: =COUNTIFS('Detalle por lead'!$D$2:$D$616,"Sí",'Detalle por lead'!$R$2:$R$616,"Alexander",'Detalle por lead'!$A$2:$A$616,"Core Tools Premium") -> 11 | E16: {=IFERROR(MEDIAN(IF(('Detalle por lead'!$D$2:$D$616="Sí")*('Detalle por lead'!$R$2:$R$616="Alexander")*('Detalle por lead'!$A$2:$A$616="ISO + Calidad")*ISNUMBER('Detalle por lead'!$N$2:$N$616),'Detalle por lead'!$N$2:$N$616)),"—")} -> 7.2510917 | F16: {=IFERROR(MEDIAN(IF(('Detalle por lead'!$D$2:$D$616="Sí")*('Detalle por lead'!$R$2:$R$616="Alexander")*('Detalle por lead'!$A$2:$A$616="Manufactura y Calidad")*ISNUMBER('Detalle por lead'!$N$2:$N$616),'Detalle por lead'!$N$2:$N$616)),"—")} -> 5.0288167 | G16: {=IFERROR(MEDIAN(IF(('Detalle por lead'!$D$2:$D$616="Sí")*('Detalle por lead'!$R$2:$R$616="Alexander")*('Detalle por lead'!$A$2:$A$616="Core Tools Premium")*ISNUMBER('Detalle por lead'!$N$2:$N$616),'Detalle por lead'!$N$2:$N$616)),"—")} -> 8.6577834
A17: Victoria | B17: =COUNTIFS('Detalle por lead'!$D$2:$D$616,"Sí",'Detalle por lead'!$R$2:$R$616,"Victoria",'Detalle por lead'!$A$2:$A$616,"ISO + Calidad") -> 30 | C17: =COUNTIFS('Detalle por lead'!$D$2:$D$616,"Sí",'Detalle por lead'!$R$2:$R$616,"Victoria",'Detalle por lead'!$A$2:$A$616,"Manufactura y Calidad") -> 9 | D17: =COUNTIFS('Detalle por lead'!$D$2:$D$616,"Sí",'Detalle por lead'!$R$2:$R$616,"Victoria",'Detalle por lead'!$A$2:$A$616,"Core Tools Premium") -> 9 | E17: {=IFERROR(MEDIAN(IF(('Detalle por lead'!$D$2:$D$616="Sí")*('Detalle por lead'!$R$2:$R$616="Victoria")*('Detalle por lead'!$A$2:$A$616="ISO + Calidad")*ISNUMBER('Detalle por lead'!$N$2:$N$616),'Detalle por lead'!$N$2:$N$616)),"—")} -> 5.036525 | F17: {=IFERROR(MEDIAN(IF(('Detalle por lead'!$D$2:$D$616="Sí")*('Detalle por lead'!$R$2:$R$616="Victoria")*('Detalle por lead'!$A$2:$A$616="Manufactura y Calidad")*ISNUMBER('Detalle por lead'!$N$2:$N$616),'Detalle por lead'!$N$2:$N$616)),"—")} -> 3.24605 | G17: {=IFERROR(MEDIAN(IF(('Detalle por lead'!$D$2:$D$616="Sí")*('Detalle por lead'!$R$2:$R$616="Victoria")*('Detalle por lead'!$A$2:$A$616="Core Tools Premium")*ISNUMBER('Detalle por lead'!$N$2:$N$616),'Detalle por lead'!$N$2:$N$616)),"—")} -> 5.0849833
A18: Joceline | B18: =COUNTIFS('Detalle por lead'!$D$2:$D$616,"Sí",'Detalle por lead'!$R$2:$R$616,"Joceline",'Detalle por lead'!$A$2:$A$616,"ISO + Calidad") -> 29 | C18: =COUNTIFS('Detalle por lead'!$D$2:$D$616,"Sí",'Detalle por lead'!$R$2:$R$616,"Joceline",'Detalle por lead'!$A$2:$A$616,"Manufactura y Calidad") -> 5 | D18: =COUNTIFS('Detalle por lead'!$D$2:$D$616,"Sí",'Detalle por lead'!$R$2:$R$616,"Joceline",'Detalle por lead'!$A$2:$A$616,"Core Tools Premium") -> 5 | E18: {=IFERROR(MEDIAN(IF(('Detalle por lead'!$D$2:$D$616="Sí")*('Detalle por lead'!$R$2:$R$616="Joceline")*('Detalle por lead'!$A$2:$A$616="ISO + Calidad")*ISNUMBER('Detalle por lead'!$N$2:$N$616),'Detalle por lead'!$N$2:$N$616)),"—")} -> 11.05665 | F18: {=IFERROR(MEDIAN(IF(('Detalle por lead'!$D$2:$D$616="Sí")*('Detalle por lead'!$R$2:$R$616="Joceline")*('Detalle por lead'!$A$2:$A$616="Manufactura y Calidad")*ISNUMBER('Detalle por lead'!$N$2:$N$616),'Detalle por lead'!$N$2:$N$616)),"—")} -> 6.9695833 | G18: {=IFERROR(MEDIAN(IF(('Detalle por lead'!$D$2:$D$616="Sí")*('Detalle por lead'!$R$2:$R$616="Joceline")*('Detalle por lead'!$A$2:$A$616="Core Tools Premium")*ISNUMBER('Detalle por lead'!$N$2:$N$616),'Detalle por lead'!$N$2:$N$616)),"—")} -> 5.8677667

Sheet Audios del equipo
A1: DESARROLLO PROFESIONAL SyS
A2: Todos los audios que mandó el equipo
A3: Notas de voz de las personas y audio automático del bot, del 5 al 15 de octubre · tres embudos · corte: 15 oct 2026, 23:59 h (Monterrey)
A5: Audio de una persona contra audio automático del bot
A6: Quién lo mandó | B6: Audios | C6: % de los audios | D6: Duración mediana (s) | E6: % que el lead vio | F6: Min. hasta que lo vio (mediana) | G6: % en que el lead escribió en 24 h | H6: Min. hasta que escribió (mediana)
A7: Persona (nota de voz) | B7: =COUNTIFS('Detalle de audios'!$G$2:$G$810,"Persona") -> 257 | C7: =IFERROR(B7/COUNT('Detalle de audios'!$B$2:$B$810),"—") -> 0.31767614 | D7: {=IFERROR(MEDIAN(IF(('Detalle de audios'!$G$2:$G$810="Persona")*ISNUMBER('Detalle de audios'!$K$2:$K$810),'Detalle de audios'!$K$2:$K$810)),"—")} -> 103.7 | E7: =IFERROR(COUNTIFS('Detalle de audios'!$G$2:$G$810,"Persona",'Detalle de audios'!$N$2:$N$810,"Sí")/B7,"—") -> 0.71595331 | F7: {=IFERROR(MEDIAN(IF(('Detalle de audios'!$G$2:$G$810="Persona")*ISNUMBER('Detalle de audios'!$O$2:$O$810),'Detalle de audios'!$O$2:$O$810)),"—")} -> 5.05 | G7: =IFERROR(COUNTIFS('Detalle de audios'!$G$2:$G$810,"Persona",'Detalle de audios'!$P$2:$P$810,"Sí")/B7,"—") -> 0.59533074 | H7: {=IFERROR(MEDIAN(IF(('Detalle de audios'!$G$2:$G$810="Persona")*ISNUMBER('Detalle de audios'!$Q$2:$Q$810),'Detalle de audios'!$Q$2:$Q$810)),"—")} -> 8.8
A8: Bot (audio automático en Negativo) | B8: =COUNTIFS('Detalle de audios'!$G$2:$G$810,"Bot (automático)") -> 552 | C8: =IFERROR(B8/COUNT('Detalle de audios'!$B$2:$B$810),"—") -> 0.68232386 | D8: {=IFERROR(MEDIAN(IF(('Detalle de audios'!$G$2:$G$810="Bot (automático)")*ISNUMBER('Detalle de audios'!$K$2:$K$810),'Detalle de audios'!$K$2:$K$810)),"—")} -> 72 | E8: =IFERROR(COUNTIFS('Detalle de audios'!$G$2:$G$810,"Bot (automático)",'Detalle de audios'!$N$2:$N$810,"Sí")/B8,"—") -> 0.64311594 | F8: {=IFERROR(MEDIAN(IF(('Detalle de audios'!$G$2:$G$810="Bot (automático)")*ISNUMBER('Detalle de audios'!$O$2:$O$810),'Detalle de audios'!$O$2:$O$810)),"—")} -> 92.3 | G8: =IFERROR(COUNTIFS('Detalle de audios'!$G$2:$G$810,"Bot (automático)",'Detalle de audios'!$P$2:$P$810,"Sí")/B8,"—") -> 0.11231884 | H8: {=IFERROR(MEDIAN(IF(('Detalle de audios'!$G$2:$G$810="Bot (automático)")*ISNUMBER('Detalle de audios'!$Q$2:$Q$810),'Detalle de audios'!$Q$2:$Q$810)),"—")} -> 137.35
A10: Por persona
A11: Persona | B11: Audios | C11: % de los audios | D11: Duración mediana (s) | E11: % que el lead vio | F11: Min. hasta que lo vio (mediana) | G11: % en que el lead escribió en 24 h | H11: Min. hasta que escribió (mediana)
A12: Salma | B12: =COUNTIFS('Detalle de audios'!$G$2:$G$810,"Persona",'Detalle de audios'!$F$2:$F$810,"Salma") -> 105 | C12: =IFERROR(B12/COUNTIFS('Detalle de audios'!$G$2:$G$810,"Persona"),"—") -> 0.40856031 | D12: {=IFERROR(MEDIAN(IF(('Detalle de audios'!$G$2:$G$810="Persona")*('Detalle de audios'!$F$2:$F$810="Salma")*ISNUMBER('Detalle de audios'!$K$2:$K$810),'Detalle de audios'!$K$2:$K$810)),"—")} -> 108.8 | E12: =IFERROR(COUNTIFS('Detalle de audios'!$G$2:$G$810,"Persona",'Detalle de audios'!$F$2:$F$810,"Salma",'Detalle de audios'!$N$2:$N$810,"Sí")/B12,"—") -> 0.8 | F12: {=IFERROR(MEDIAN(IF(('Detalle de audios'!$G$2:$G$810="Persona")*('Detalle de audios'!$F$2:$F$810="Salma")*ISNUMBER('Detalle de audios'!$O$2:$O$810),'Detalle de audios'!$O$2:$O$810)),"—")} -> 7.4 | G12: =IFERROR(COUNTIFS('Detalle de audios'!$G$2:$G$810,"Persona",'Detalle de audios'!$F$2:$F$810,"Salma",'Detalle de audios'!$P$2:$P$810,"Sí")/B12,"—") -> 0.61904762 | H12: {=IFERROR(MEDIAN(IF(('Detalle de audios'!$G$2:$G$810="Persona")*('Detalle de audios'!$F$2:$F$810="Salma")*ISNUMBER('Detalle de audios'!$Q$2:$Q$810),'Detalle de audios'!$Q$2:$Q$810)),"—")} -> 13.4
A13: Alexander | B13: =COUNTIFS('Detalle de audios'!$G$2:$G$810,"Persona",'Detalle de audios'!$F$2:$F$810,"Alexander") -> 62 | C13: =IFERROR(B13/COUNTIFS('Detalle de audios'!$G$2:$G$810,"Persona"),"—") -> 0.24124514 | D13: {=IFERROR(MEDIAN(IF(('Detalle de audios'!$G$2:$G$810="Persona")*('Detalle de audios'!$F$2:$F$810="Alexander")*ISNUMBER('Detalle de audios'!$K$2:$K$810),'Detalle de audios'!$K$2:$K$810)),"—")} -> 83.7 | E13: =IFERROR(COUNTIFS('Detalle de audios'!$G$2:$G$810,"Persona",'Detalle de audios'!$F$2:$F$810,"Alexander",'Detalle de audios'!$N$2:$N$810,"Sí")/B13,"—") -> 0.66129032 | F13: {=IFERROR(MEDIAN(IF(('Detalle de audios'!$G$2:$G$810="Persona")*('Detalle de audios'!$F$2:$F$810="Alexander")*ISNUMBER('Detalle de audios'!$O$2:$O$810),'Detalle de audios'!$O$2:$O$810)),"—")} -> 4.4 | G13: =IFERROR(COUNTIFS('Detalle de audios'!$G$2:$G$810,"Persona",'Detalle de audios'!$F$2:$F$810,"Alexander",'Detalle de audios'!$P$2:$P$810,"Sí")/B13,"—") -> 0.58064516 | H13: {=IFERROR(MEDIAN(IF(('Detalle de audios'!$G$2:$G$810="Persona")*('Detalle de audios'!$F$2:$F$810="Alexander")*ISNUMBER('Detalle de audios'!$Q$2:$Q$810),'Detalle de audios'!$Q$2:$Q$810)),"—")} -> 9.75
A14: Victoria | B14: =COUNTIFS('Detalle de audios'!$G$2:$G$810,"Persona",'Detalle de audios'!$F$2:$F$810,"Victoria") -> 50 | C14: =IFERROR(B14/COUNTIFS('Detalle de audios'!$G$2:$G$810,"Persona"),"—") -> 0.19455253 | D14: {=IFERROR(MEDIAN(IF(('Detalle de audios'!$G$2:$G$810="Persona")*('Detalle de audios'!$F$2:$F$810="Victoria")*ISNUMBER('Detalle de audios'!$K$2:$K$810),'Detalle de audios'!$K$2:$K$810)),"—")} -> 97.45 | E14: =IFERROR(COUNTIFS('Detalle de audios'!$G$2:$G$810,"Persona",'Detalle de audios'!$F$2:$F$810,"Victoria",'Detalle de audios'!$N$2:$N$810,"Sí")/B14,"—") -> 0.72 | F14: {=IFERROR(MEDIAN(IF(('Detalle de audios'!$G$2:$G$810="Persona")*('Detalle de audios'!$F$2:$F$810="Victoria")*ISNUMBER('Detalle de audios'!$O$2:$O$810),'Detalle de audios'!$O$2:$O$810)),"—")} -> 3.45 | G14: =IFERROR(COUNTIFS('Detalle de audios'!$G$2:$G$810,"Persona",'Detalle de audios'!$F$2:$F$810,"Victoria",'Detalle de audios'!$P$2:$P$810,"Sí")/B14,"—") -> 0.64 | H14: {=IFERROR(MEDIAN(IF(('Detalle de audios'!$G$2:$G$810="Persona")*('Detalle de audios'!$F$2:$F$810="Victoria")*ISNUMBER('Detalle de audios'!$Q$2:$Q$810),'Detalle de audios'!$Q$2:$Q$810)),"—")} -> 10.35
