Workbook

Sheet Resumen
B1: DESARROLLO PROFESIONAL SyS
B2: Línea base (As Is) · Embudo ISO + Calidad
B3: CRM · 407 leads del 5 al 15 de octubre de 2026 · corte: 15 oct 2026, 23:59 h (Monterrey) · medido en solo lectura, sin mover ni enviar nada
B5: Los números
B6: Qué medimos | C6: Valor | D6: Cómo leerlo
B7: Leads que entraron | C7: =COUNT(Datos!$B$2:$B$408) -> 407 | D7: Del 5 al 15 de octubre de 2026. Semana completa del 5 al 11 y 4 días de la siguiente.
B8: Contestaron el saludo | C8: =IFERROR(COUNTIFS(Datos!$G$2:$G$408,"Sí")/COUNT(Datos!$B$2:$B$408),"—") -> 0.62899263 | D8: Escribieron después de que el bot pidió el nombre.
B9: Dejaron de escribir en el saludo o antes | C9: =IFERROR((COUNTIFS(Datos!$AJ$2:$AJ$408,"Solo su primer mensaje")+COUNTIFS(Datos!$AJ$2:$AJ$408,"Saludo: contestó y no volvió"))/COUNT(Datos!$B$2:$B$408),"—") -> 0.5012285 | D9: La caída más grande del embudo.
B10: Llegaron a facilidades de pago | C10: =IFERROR(COUNTIFS(Datos!$P$2:$P$408,"Sí")/COUNT(Datos!$B$2:$B$408),"—") -> 0.34152334 | D10: Etapa 1.3 o más lejos.
B11: Recibieron al menos una oferta | C11: =IFERROR(COUNTIFS(Datos!$Z$2:$Z$408,"Sí")/COUNT(Datos!$B$2:$B$408),"—") -> 0.86486486 | D11: $3,799, $3,400, $2,799 o $1,950.
B12: Primeras ofertas que manda el bot | C12: =IFERROR(COUNTIFS(Datos!$AB$2:$AB$408,"Bot")/COUNTIFS(Datos!$Z$2:$Z$408,"Sí"),"—") -> 0.79261364 | D12: Por tiempo, no por lo que dice el lead.
B13: Entraron fuera de horario (antes de 9 h o desde 21 h) | C13: =IFERROR(COUNTIFS(Datos!$F$2:$F$408,"No")/COUNT(Datos!$B$2:$B$408),"—") -> 0.25061425 | D13: El equipo en la práctica atiende de 7 a 22 h.
B14: Horas hasta el 1er mensaje de una persona (mediana) | C14: =IFERROR(MEDIAN(Datos!$T$2:$T$408)/60,"—") -> 7.4916667 | D14: Mover de etapa llega en minutos; el primer mensaje escrito, no.
B15: Nunca recibieron un mensaje de una persona | C15: =IFERROR(COUNTBLANK(Datos!$T$2:$T$408)/COUNT(Datos!$B$2:$B$408),"—") -> 0.12530713 | D15: Hasta el corte, solo les escribió el bot.
B16: Leads donde intervino auxiliar | C16: =IFERROR(COUNTIFS(Datos!$S$2:$S$408,"Sí")/COUNT(Datos!$B$2:$B$408),"—") -> 0.51351351 | D16: Escribió o movió de etapa al lead.
B17: Ventas | C17: =COUNTIFS(Datos!$AQ$2:$AQ$408,"Sí") -> 10 | D17: Leads en la etapa Ganado al corte.
B18: Conversión (ventas ÷ leads) | C18: =IFERROR(COUNTIFS(Datos!$AQ$2:$AQ$408,"Sí")/COUNT(Datos!$B$2:$B$408),"—") -> 0.024570025
B19: Ventas a precio de lista ($3,999 o más) | C19: =COUNTIFS(Datos!$AQ$2:$AQ$408,"Sí",Datos!$AR$2:$AR$408,">=3999") -> 2 | D19: El resto fueron con descuento.
B20: Precio promedio de venta | C20: =IFERROR(AVERAGEIFS(Datos!$AR$2:$AR$408,Datos!$AQ$2:$AQ$408,"Sí"),"—") -> 3239 | D20: Precio de lista: $3,999.
B21: Leads abiertos al corte | C21: =COUNTIFS(Datos!$AK$2:$AK$408,"Abierto") -> 123 | D21: Todavía pueden avanzar; sobre todo los de la última semana.
B23: Lo más importante
B24: • La mitad de los leads (50%) deja de escribir en el saludo o antes.
B25: • Si el lead contesta el saludo (63%), el bot se detiene y espera a que una persona lo mueva; 29 leads esperaron más de 1 hora.
B26: • El primer mensaje de una persona tarda 7.5 h (mediana); 13% de los leads nunca recibe uno.
B27: • El bot manda las ofertas por tiempo: la primera llega a las 31.6 h (mediana) y el 86% recibe al menos una.
B28: • 10 ventas (2.5%); 8 con descuento y 2 a precio de lista. Precio promedio $3,239.
B29: • Quien abre un link compra 6.7% contra 1.0% de quien no lo abre, y esa señal no detona ninguna acción.
B31: Puntos a mejorar
B32: Punto | C32: Dato | D32: Qué muestra el dato
B33: 1 · La mitad deja de escribir en el saludo o antes | C33: =IFERROR((COUNTIFS(Datos!$AJ$2:$AJ$408,"Solo su primer mensaje")+COUNTIFS(Datos!$AJ$2:$AJ$408,"Saludo: contestó y no volvió"))/COUNT(Datos!$B$2:$B$408),"—") -> 0.5012285 | D33: 27% solo mandó su primer mensaje y 24% contestó el saludo (casi siempre su nombre) y ya no volvió a escribir. Es la caída más grande del embudo.
B34: 2 · Si el lead contesta el saludo, el bot se detiene y espera a una persona | C34: =COUNTIFS(Datos!$J$2:$J$408,">60") -> 29 | D34: Leads que esperaron más de 1 hora para pasar a 1.1. Contesta el 63% y casi siempre lo mueve una persona: en horario tarda 0.5 min (mediana); fuera de horario, 18.4 min, y quien escribe de noche espera hasta la mañana.
B35: 3 · El primer mensaje de una persona llega tarde | C35: =IFERROR(MEDIAN(Datos!$T$2:$T$408)/60,"—") -> 7.4916667 | D35: Horas (mediana). Una persona mueve al lead en 5.3 min, pero su primer mensaje escrito tarda 7.5 h; 36% lo recibe después de 1 día y 13% nunca. Con mensaje en la 1.ª hora compra el 4.8%; después de 1 día, el 0.7% (relación, no causa).
B36: 4 · Las ofertas salen por tiempo y casi todo se vende con descuento | C36: =IFERROR(COUNTIFS(Datos!$AQ$2:$AQ$408,"Sí",Datos!$AR$2:$AR$408,"<3999")/COUNTIFS(Datos!$AQ$2:$AQ$408,"Sí"),"—") -> 0.8 | D36: Ventas con descuento. El 86% recibe al menos una oferta y el bot manda el 79% de las primeras, a las 31.6 h (mediana) de entrar, conteste o no. De 10 ventas, 8 fueron con descuento; precio promedio $3,239 contra $3,999 de lista.
B37: 5 · Los leads que piden cómo pagar se enfrían | C37: =IFERROR(COUNTIFS(Datos!$P$2:$P$408,"Sí",Datos!$AQ$2:$AQ$408,"Sí")/COUNTIFS(Datos!$P$2:$P$408,"Sí"),"—") -> 0.071942446 | D37: Compran de los que llegan a facilidades de pago. 139 leads (34%) llegaron a 1.3 o más lejos y 10 compraron; 56 dejaron de escribir ya en facilidades o en forma de pago.
B38: 6 · La pregunta de ocupación casi no se contesta y no cambia el flujo | C38: =IFERROR(COUNTIFS(Datos!$L$2:$L$408,"Sí",Datos!$M$2:$M$408,"Sí")/COUNTIFS(Datos!$L$2:$L$408,"Sí"),"—") -> 0.39012346 | D38: Contestan su área en 24 h. El bot sigue igual para todos: 2 h después de preguntar pasa al lead a Negativo, haya contestado o no.
B39: 7 · Las señales de interés no detonan una acción | C39: =IFERROR(COUNTIFS(Datos!$AG$2:$AG$408,"Sí",Datos!$AQ$2:$AQ$408,"Sí")/COUNTIFS(Datos!$AG$2:$AG$408,"Sí"),"—") -> 0.066666667 | D39: Compran de los que abren un link. El 26% abrió su ruta, la clase demo o el mapa; de ellos compra el 6.7%, contra 1.0% de los que no. El CRM solo lo deja como nota interna.
B40: 8 · Los Perdidos se cierran a mano y sin diagnóstico | C40: =IFERROR(COUNTIFS(Datos!$AM$2:$AM$408,"No contestaron")/COUNTIFS(Datos!$AK$2:$AK$408,"Perdido"),"—") -> 0.93430657 | D40: De los Perdidos con razón «No contestaron». Una persona marca el 97% de los 274 Perdidos, a las 88.2 h (mediana) de entrar, y la razón no dice en qué etapa ni por qué se fue. 13 leads volvieron a escribir ya en Perdido y 1 de las 10 ventas salió de ahí.
B41: 9 · El reparto de leads está cargado a una sola asesora | C41: =IFERROR(COUNTIFS(Datos!$R$2:$R$408,"Salma")/COUNT(Datos!$B$2:$B$408),"—") -> 0.68304668 | D41: Leads a nombre de Salma. También quedan a su nombre el 84% de los que entran fuera de horario. En horario, su primera acción tarda 7.7 min (mediana) contra 1.7 min del resto del equipo; con los de fuera de horario, 45.4 min.
B42: 10 · Fuera de horario la atención baja | C42: =IFERROR(COUNTIFS(Respuestas!$E$2:$E$1034,"No",Respuestas!$H$2:$H$1034,"<=15")/COUNTIFS(Respuestas!$E$2:$E$1034,"No"),"—") -> 0.6076555 | D42: De los mensajes del lead fuera de horario que una persona contesta en 15 min, contra 81% en horario. El 25% de los leads entra fuera de 9 a 21 h y espera 30.7 h (mediana) su primer mensaje de una persona, contra 2.3 h en horario.
B44: Valor y Dato se calculan con fórmulas sobre las hojas Datos y Respuestas. Los textos se escribieron con los datos al corte del 15 de octubre de 2026.
...

Sheet Métricas semanales
A1: DESARROLLO PROFESIONAL SyS
A2: Métricas por semana
A3: ISO + Calidad · semana según la fecha en que entró el lead · corte: 15 oct 2026, 23:59 h (Monterrey)
A5: Métrica | B5: 2026-S41 | C5: 2026-S42 | D5: Total | E5: Cómo se calcula
B6: 5 al 11 oct (completa) | C6: 12 al 15 oct (4 días)
A8: Volumen
A9: Leads | B9: =COUNTIFS(Datos!$D$2:$D$408,B$5) -> 253 | C9: =COUNTIFS(Datos!$D$2:$D$408,C$5) -> 154 | D9: =COUNT(Datos!$B$2:$B$408) -> 407 | E9: Leads que entraron.
A10: % que entra fuera de horario | B10: =IFERROR(COUNTIFS(Datos!$D$2:$D$408,B$5,Datos!$F$2:$F$408,"No")/COUNTIFS(Datos!$D$2:$D$408,B$5),"—") -> 0.24901186 | C10: =IFERROR(COUNTIFS(Datos!$D$2:$D$408,C$5,Datos!$F$2:$F$408,"No")/COUNTIFS(Datos!$D$2:$D$408,C$5),"—") -> 0.25324675 | D10: =IFERROR(COUNTIFS(Datos!$F$2:$F$408,"No")/COUNT(Datos!$B$2:$B$408),"—") -> 0.25061425 | E10: Antes de 9 h o desde 21 h (horario de los bots en el CRM).
A12: Saludo
A13: % que contesta el saludo | B13: =IFERROR(COUNTIFS(Datos!$D$2:$D$408,B$5,Datos!$G$2:$G$408,"Sí")/COUNTIFS(Datos!$D$2:$D$408,B$5),"—") -> 0.62055336 | C13: =IFERROR(COUNTIFS(Datos!$D$2:$D$408,C$5,Datos!$G$2:$G$408,"Sí")/COUNTIFS(Datos!$D$2:$D$408,C$5),"—") -> 0.64285714 | D13: =IFERROR(COUNTIFS(Datos!$G$2:$G$408,"Sí")/COUNT(Datos!$B$2:$B$408),"—") -> 0.62899263 | E13: Escribió después de que el bot pidió el nombre y antes de salir de 1 Saludo.
A14: % que da su nombre | B14: =IFERROR(COUNTIFS(Datos!$D$2:$D$408,B$5,Datos!$H$2:$H$408,"Sí")/COUNTIFS(Datos!$D$2:$D$408,B$5),"—") -> 0.60474308 | C14: =IFERROR(COUNTIFS(Datos!$D$2:$D$408,C$5,Datos!$H$2:$H$408,"Sí")/COUNTIFS(Datos!$D$2:$D$408,C$5),"—") -> 0.62337662 | D14: =IFERROR(COUNTIFS(Datos!$H$2:$H$408,"Sí")/COUNT(Datos!$B$2:$B$408),"—") -> 0.61179361 | E14: Su nombre aparece en lo que contestó al saludo.
A15: Minutos de su respuesta al paso a 1.1 · mediana, de 9 a 21 h | B15: {=IFERROR(MEDIAN(IF((Datos!$D$2:$D$408=B$5)*(Datos!$F$2:$F$408="Sí")*(Datos!$J$2:$J$408<>""),Datos!$J$2:$J$408)),"—")} -> 0.5 | C15: {=IFERROR(MEDIAN(IF((Datos!$D$2:$D$408=C$5)*(Datos!$F$2:$F$408="Sí")*(Datos!$J$2:$J$408<>""),Datos!$J$2:$J$408)),"—")} -> 0.4 | D15: {=IFERROR(MEDIAN(IF((Datos!$F$2:$F$408="Sí")*(Datos!$J$2:$J$408<>""),Datos!$J$2:$J$408)),"—")} -> 0.5 | E15: Solo quienes contestaron. La mediana es el caso de en medio: no la mueven los extremos.
A16: Minutos de su respuesta al paso a 1.1 · mediana, fuera de horario | B16: {=IFERROR(MEDIAN(IF((Datos!$D$2:$D$408=B$5)*(Datos!$F$2:$F$408="No")*(Datos!$J$2:$J$408<>""),Datos!$J$2:$J$408)),"—")} -> 25.5 | C16: {=IFERROR(MEDIAN(IF((Datos!$D$2:$D$408=C$5)*(Datos!$F$2:$F$408="No")*(Datos!$J$2:$J$408<>""),Datos!$J$2:$J$408)),"—")} -> 12.9 | D16: {=IFERROR(MEDIAN(IF((Datos!$F$2:$F$408="No")*(Datos!$J$2:$J$408<>""),Datos!$J$2:$J$408)),"—")} -> 18.4
A17: Minutos de su respuesta al paso a 1.1 · promedio, de 9 a 21 h | B17: =IFERROR(AVERAGEIFS(Datos!$J$2:$J$408,Datos!$D$2:$D$408,B$5,Datos!$F$2:$F$408,"Sí"),"—") -> 1.6681034 | C17: =IFERROR(AVERAGEIFS(Datos!$J$2:$J$408,Datos!$D$2:$D$408,C$5,Datos!$F$2:$F$408,"Sí"),"—") -> 1.2619718 | D17: =IFERROR(AVERAGEIFS(Datos!$J$2:$J$408,Datos!$F$2:$F$408,"Sí"),"—") -> 1.5139037
A18: Minutos de su respuesta al paso a 1.1 · promedio, fuera de horario | B18: =IFERROR(AVERAGEIFS(Datos!$J$2:$J$408,Datos!$D$2:$D$408,B$5,Datos!$F$2:$F$408,"No"),"—") -> 170.71707 | C18: =IFERROR(AVERAGEIFS(Datos!$J$2:$J$408,Datos!$D$2:$D$408,C$5,Datos!$F$2:$F$408,"No"),"—") -> 144.7963 | D18: =IFERROR(AVERAGEIFS(Datos!$J$2:$J$408,Datos!$F$2:$F$408,"No"),"—") -> 160.425 | E18: Lo sube quien escribe de noche y espera hasta la mañana.
A19: Esperaron más de 1 hora para pasar a 1.1 | B19: =COUNTIFS(Datos!$D$2:$D$408,B$5,Datos!$J$2:$J$408,">60") -> 19 | C19: =COUNTIFS(Datos!$D$2:$D$408,C$5,Datos!$J$2:$J$408,">60") -> 10 | D19: =COUNTIFS(Datos!$J$2:$J$408,">60") -> 29 | E19: Contestaron y nadie los movió en la primera hora.
A21: Avance
A22: % que pasa de 1.1 a 1.2 | B22: =IFERROR(COUNTIFS(Datos!$D$2:$D$408,B$5,Datos!$I$2:$I$408,"Sí",Datos!$L$2:$L$408,"Sí")/COUNTIFS(Datos!$D$2:$D$408,B$5,Datos!$I$2:$I$408,"Sí"),"—") -> 1 | C22: =IFERROR(COUNTIFS(Datos!$D$2:$D$408,C$5,Datos!$I$2:$I$408,"Sí",Datos!$L$2:$L$408,"Sí")/COUNTIFS(Datos!$D$2:$D$408,C$5,Datos!$I$2:$I$408,"Sí"),"—") -> 1 | D22: =IFERROR(COUNTIFS(Datos!$I$2:$I$408,"Sí",Datos!$L$2:$L$408,"Sí")/COUNTIFS(Datos!$I$2:$I$408,"Sí"),"—") -> 1 | E22: Es automático, a los 8 segundos.
A23: % que contesta la ocupación (de los que llegan a 1.2) | B23: =IFERROR(COUNTIFS(Datos!$D$2:$D$408,B$5,Datos!$L$2:$L$408,"Sí",Datos!$M$2:$M$408,"Sí")/COUNTIFS(Datos!$D$2:$D$408,B$5,Datos!$L$2:$L$408,"Sí"),"—") -> 0.40079365 | C23: =IFERROR(COUNTIFS(Datos!$D$2:$D$408,C$5,Datos!$L$2:$L$408,"Sí",Datos!$M$2:$M$408,"Sí")/COUNTIFS(Datos!$D$2:$D$408,C$5,Datos!$L$2:$L$408,"Sí"),"—") -> 0.37254902 | D23: =IFERROR(COUNTIFS(Datos!$L$2:$L$408,"Sí",Datos!$M$2:$M$408,"Sí")/COUNTIFS(Datos!$L$2:$L$408,"Sí"),"—") -> 0.39012346 | E23: Contestó en 24 h con su área o si estudia.
A24: % que entra a Negativo | B24: =IFERROR(COUNTIFS(Datos!$D$2:$D$408,B$5,Datos!$O$2:$O$408,"Sí")/COUNTIFS(Datos!$D$2:$D$408,B$5),"—") -> 0.91699605 | C24: =IFERROR(COUNTIFS(Datos!$D$2:$D$408,C$5,Datos!$O$2:$O$408,"Sí")/COUNTIFS(Datos!$D$2:$D$408,C$5),"—") -> 0.88961039 | D24: =IFERROR(COUNTIFS(Datos!$O$2:$O$408,"Sí")/COUNT(Datos!$B$2:$B$408),"—") -> 0.90663391 | E24: El bot lo pasa solo si nadie lo mueve en 2 h.
A25: % que llega a facilidades de pago | B25: =IFERROR(COUNTIFS(Datos!$D$2:$D$408,B$5,Datos!$P$2:$P$408,"Sí")/COUNTIFS(Datos!$D$2:$D$408,B$5),"—") -> 0.33992095 | C25: =IFERROR(COUNTIFS(Datos!$D$2:$D$408,C$5,Datos!$P$2:$P$408,"Sí")/COUNTIFS(Datos!$D$2:$D$408,C$5),"—") -> 0.34415584 | D25: =IFERROR(COUNTIFS(Datos!$P$2:$P$408,"Sí")/COUNT(Datos!$B$2:$B$408),"—") -> 0.34152334 | E25: Etapa 1.3 o 1.4, o más lejos.
A26: % que llega a forma de pago | B26: =IFERROR(COUNTIFS(Datos!$D$2:$D$408,B$5,Datos!$Q$2:$Q$408,"Sí")/COUNTIFS(Datos!$D$2:$D$408,B$5),"—") -> 0.071146245 | C26: =IFERROR(COUNTIFS(Datos!$D$2:$D$408,C$5,Datos!$Q$2:$Q$408,"Sí")/COUNTIFS(Datos!$D$2:$D$408,C$5),"—") -> 0.077922078 | D26: =IFERROR(COUNTIFS(Datos!$Q$2:$Q$408,"Sí")/COUNT(Datos!$B$2:$B$408),"—") -> 0.073710074 | E26: Etapas 2.x, MSI y 3.x, o Ganado.
A28: Atención de personas
A29: Minutos hasta la 1a acción de una persona · mediana | B29: {=IFERROR(MEDIAN(IF((Datos!$D$2:$D$408=B$5)*(Datos!$V$2:$V$408<>""),Datos!$V$2:$V$408)),"—")} -> 6.9 | C29: {=IFERROR(MEDIAN(IF((Datos!$D$2:$D$408=C$5)*(Datos!$V$2:$V$408<>""),Datos!$V$2:$V$408)),"—")} -> 3.5 | D29: =IFERROR(MEDIAN(Datos!$V$2:$V$408),"—") -> 5.3 | E29: Un mensaje o un cambio de etapa hecho por una persona.
A30: Horas hasta el 1er mensaje de una persona · mediana | B30: {=IFERROR(MEDIAN(IF((Datos!$D$2:$D$408=B$5)*(Datos!$T$2:$T$408<>""),Datos!$T$2:$T$408))/60,"—")} -> 12.766667 | C30: {=IFERROR(MEDIAN(IF((Datos!$D$2:$D$408=C$5)*(Datos!$T$2:$T$408<>""),Datos!$T$2:$T$408))/60,"—")} -> 1.0583333 | D30: =IFERROR(MEDIAN(Datos!$T$2:$T$408)/60,"—") -> 7.4916667 | E30: Desde que entra el lead. Mover de etapa no cuenta.
A31: % que nunca recibió un mensaje de una persona | B31: =IFERROR(COUNTIFS(Datos!$D$2:$D$408,B$5,Datos!$T$2:$T$408,"")/COUNTIFS(Datos!$D$2:$D$408,B$5),"—") -> 0.015810277 | C31: =IFERROR(COUNTIFS(Datos!$D$2:$D$408,C$5,Datos!$T$2:$T$408,"")/COUNTIFS(Datos!$D$2:$D$408,C$5),"—") -> 0.30519481 | D31: =IFERROR(COUNTBLANK(Datos!$T$2:$T$408)/COUNT(Datos!$B$2:$B$408),"—") -> 0.12530713 | E31: Hasta el corte, solo le escribió el bot.
A32: Minutos que tarda una persona en contestarle al lead · mediana | B32: {=IFERROR(MEDIAN(IF((Datos!$D$2:$D$408=B$5)*(Datos!$W$2:$W$408<>""),Datos!$W$2:$W$408)),"—")} -> 5.9 | C32: {=IFERROR(MEDIAN(IF((Datos!$D$2:$D$408=C$5)*(Datos!$W$2:$W$408<>""),Datos!$W$2:$W$408)),"—")} -> 3.95 | D32: =IFERROR(MEDIAN(Datos!$W$2:$W$408),"—") -> 5.2 | E32: Mediana por lead y luego la de todos. Detalle en la hoja Respuestas.
A33: % con audio del equipo | B33: =IFERROR(COUNTIFS(Datos!$D$2:$D$408,B$5,Datos!$Y$2:$Y$408,"Sí")/COUNTIFS(Datos!$D$2:$D$408,B$5),"—") -> 0.38735178 | C33: =IFERROR(COUNTIFS(Datos!$D$2:$D$408,C$5,Datos!$Y$2:$Y$408,"Sí")/COUNTIFS(Datos!$D$2:$D$408,C$5),"—") -> 0.37662338 | D33: =IFERROR(COUNTIFS(Datos!$Y$2:$Y$408,"Sí")/COUNT(Datos!$B$2:$B$408),"—") -> 0.38329238 | E33: Nota de voz de una persona, no del bot.
A34: % donde intervino auxiliar | B34: =IFERROR(COUNTIFS(Datos!$D$2:$D$408,B$5,Datos!$S$2:$S$408,"Sí")/COUNTIFS(Datos!$D$2:$D$408,B$5),"—") -> 0.54940711 | C34: =IFERROR(COUNTIFS(Datos!$D$2:$D$408,C$5,Datos!$S$2:$S$408,"Sí")/COUNTIFS(Datos!$D$2:$D$408,C$5),"—") -> 0.45454545 | D34: =IFERROR(COUNTIFS(Datos!$S$2:$S$408,"Sí")/COUNT(Datos!$B$2:$B$408),"—") -> 0.51351351 | E34: La auxiliar escribió o movió al lead de etapa.
A36: Ofertas
A37: % que recibe alguna oferta | B37: =IFERROR(COUNTIFS(Datos!$D$2:$D$408,B$5,Datos!$Z$2:$Z$408,"Sí")/COUNTIFS(Datos!$D$2:$D$408,B$5),"—") -> 0.97233202 | C37: =IFERROR(COUNTIFS(Datos!$D$2:$D$408,C$5,Datos!$Z$2:$Z$408,"Sí")/COUNTIFS(Datos!$D$2:$D$408,C$5),"—") -> 0.68831169 | D37: =IFERROR(COUNTIFS(Datos!$Z$2:$Z$408,"Sí")/COUNT(Datos!$B$2:$B$408),"—") -> 0.86486486 | E37: $3,799, $3,400, $2,799 o $1,950 escrito en un mensaje.
A38: % que recibe $3,799 | B38: =IFERROR(COUNTIFS(Datos!$D$2:$D$408,B$5,Datos!$AA$2:$AA$408,"*3,799*")/COUNTIFS(Datos!$D$2:$D$408,B$5),"—") -> 0.95256917 | C38: =IFERROR(COUNTIFS(Datos!$D$2:$D$408,C$5,Datos!$AA$2:$AA$408,"*3,799*")/COUNTIFS(Datos!$D$2:$D$408,C$5),"—") -> 0.68181818 | D38: =IFERROR(COUNTIFS(Datos!$AA$2:$AA$408,"*3,799*")/COUNT(Datos!$B$2:$B$408),"—") -> 0.85012285
A39: % que recibe $2,799 | B39: =IFERROR(COUNTIFS(Datos!$D$2:$D$408,B$5,Datos!$AA$2:$AA$408,"*2,799*")/COUNTIFS(Datos!$D$2:$D$408,B$5),"—") -> 0.96837945 | C39: =IFERROR(COUNTIFS(Datos!$D$2:$D$408,C$5,Datos!$AA$2:$AA$408,"*2,799*")/COUNTIFS(Datos!$D$2:$D$408,C$5),"—") -> 0.3961039 | D39: =IFERROR(COUNTIFS(Datos!$AA$2:$AA$408,"*2,799*")/COUNT(Datos!$B$2:$B$408),"—") -> 0.75184275
A40: % que recibe $1,950 | B40: =IFERROR(COUNTIFS(Datos!$D$2:$D$408,B$5,Datos!$AA$2:$AA$408,"*1,950*")/COUNTIFS(Datos!$D$2:$D$408,B$5),"—") -> 0 | C40: =IFERROR(COUNTIFS(Datos!$D$2:$D$408,C$5,Datos!$AA$2:$AA$408,"*1,950*")/COUNTIFS(Datos!$D$2:$D$408,C$5),"—") -> 0 | D40: =IFERROR(COUNTIFS(Datos!$AA$2:$AA$408,"*1,950*")/COUNT(Datos!$B$2:$B$408),"—") -> 0
A41: % de primeras ofertas que manda el bot | B41: =IFERROR(COUNTIFS(Datos!$D$2:$D$408,B$5,Datos!$Z$2:$Z$408,"Sí",Datos!$AB$2:$AB$408,"Bot")/COUNTIFS(Datos!$D$2:$D$408,B$5,Datos!$Z$2:$Z$408,"Sí"),"—") -> 0.82926829 | C41: =IFERROR(COUNTIFS(Datos!$D$2:$D$408,C$5,Datos!$Z$2:$Z$408,"Sí",Datos!$AB$2:$AB$408,"Bot")/COUNTIFS(Datos!$D$2:$D$408,C$5,Datos!$Z$2:$Z$408,"Sí"),"—") -> 0.70754717 | D41: =IFERROR(COUNTIFS(Datos!$Z$2:$Z$408,"Sí",Datos!$AB$2:$AB$408,"Bot")/COUNTIFS(Datos!$Z$2:$Z$408,"Sí"),"—") -> 0.79261364 | E41: El resto lo manda una persona, casi siempre con plantilla.
A42: Horas hasta la 1a oferta · mediana | B42: {=IFERROR(MEDIAN(IF((Datos!$D$2:$D$408=B$5)*(Datos!$AC$2:$AC$408<>""),Datos!$AC$2:$AC$408)),"—")} -> 37.2 | C42: {=IFERROR(MEDIAN(IF((Datos!$D$2:$D$408=C$5)*(Datos!$AC$2:$AC$408<>""),Datos!$AC$2:$AC$408)),"—")} -> 28.55 | D42: =IFERROR(MEDIAN(Datos!$AC$2:$AC$408),"—") -> 31.6 | E42: Desde que entra el lead.
A44: Interés y volumen de mensajes
A45: % que abrió algún link | B45: =IFERROR(COUNTIFS(Datos!$D$2:$D$408,B$5,Datos!$AG$2:$AG$408,"Sí")/COUNTIFS(Datos!$D$2:$D$408,B$5),"—") -> 0.27272727 | C45: =IFERROR(COUNTIFS(Datos!$D$2:$D$408,C$5,Datos!$AG$2:$AG$408,"Sí")/COUNTIFS(Datos!$D$2:$D$408,C$5),"—") -> 0.23376623 | D45: =IFERROR(COUNTIFS(Datos!$AG$2:$AG$408,"Sí")/COUNT(Datos!$B$2:$B$408),"—") -> 0.25798526 | E45: Ruta, clase demo, mapa o perfil de ejemplo (aviso del CRM).
A46: Mensajes del lead por lead · promedio | B46: =IFERROR(AVERAGEIFS(Datos!$AD$2:$AD$408,Datos!$D$2:$D$408,B$5),"—") -> 4.4782609 | C46: =IFERROR(AVERAGEIFS(Datos!$AD$2:$AD$408,Datos!$D$2:$D$408,C$5),"—") -> 3.8181818 | D46: =IFERROR(AVERAGE(Datos!$AD$2:$AD$408),"—") -> 4.2285012
A47: Mensajes del bot por lead · promedio | B47: =IFERROR(AVERAGEIFS(Datos!$AE$2:$AE$408,Datos!$D$2:$D$408,B$5),"—") -> 19.126482 | C47: =IFERROR(AVERAGEIFS(Datos!$AE$2:$AE$408,Datos!$D$2:$D$408,C$5),"—") -> 16.12987 | D47: =IFERROR(AVERAGE(Datos!$AE$2:$AE$408),"—") -> 17.992629
...

Sheet Embudo
A1: DESARROLLO PROFESIONAL SyS
A2: Embudo
A3: ISO + Calidad · 407 leads del 5 al 15 de octubre de 2026 · conteos con fórmulas sobre la hoja Datos
A5: Leads que llegaron a cada etapa
A6: Etapa | B6: Leads | C6: % de la etapa anterior | D6: % de los que entraron | E6: Nota
A7: Entraron a 1 Saludo | B7: =COUNT(Datos!$B$2:$B$408) -> 407 | C7: — | D7: =IFERROR(B7/B$7,"—") -> 1 | E7: Todos reciben el saludo y la petición de nombre.
A8: 1.1 Informes | B8: =COUNTIFS(Datos!$I$2:$I$408,"Sí") -> 405 | C8: =IFERROR(B8/B7,"—") -> 0.995086 | D8: =IFERROR(B8/B$7,"—") -> 0.995086 | E8: Lo mueve una persona si contestó; el bot, si no contestó.
A9: 1.2 Lista de cursos | B9: =COUNTIFS(Datos!$L$2:$L$408,"Sí") -> 405 | C9: =IFERROR(B9/B8,"—") -> 1 | D9: =IFERROR(B9/B$7,"—") -> 0.995086 | E9: Automático.
A10: Facilidades de pago, 1.3 y 1.4 | B10: =COUNTIFS(Datos!$P$2:$P$408,"Sí") -> 139 | C10: =IFERROR(B10/B9,"—") -> 0.34320988 | D10: =IFERROR(B10/B$7,"—") -> 0.34152334 | E10: Lo mueve una persona o el lead contesta la oferta del bot.
A11: Forma o medio de pago, 2.x y 3.x | B11: =COUNTIFS(Datos!$Q$2:$Q$408,"Sí") -> 30 | C11: =IFERROR(B11/B10,"—") -> 0.21582734 | D11: =IFERROR(B11/B$7,"—") -> 0.073710074 | E11: Eligió cómo pagar o recibió los datos.
A12: Compraron | B12: =COUNTIFS(Datos!$AQ$2:$AQ$408,"Sí") -> 10 | C12: =IFERROR(B12/B11,"—") -> 0.33333333 | D12: =IFERROR(B12/B$7,"—") -> 0.024570025 | E12: Etapa Ganado.
A13: Además: entraron a Negativo | B13: =COUNTIFS(Datos!$O$2:$O$408,"Sí") -> 369 | D13: =IFERROR(B13/B$7,"—") -> 0.90663391 | E13: Seguimiento automático del bot si nadie mueve al lead en 2 h.
A16: Dónde dejó de escribir el lead
A17: Etapa de su último mensaje | B17: Leads | C17: % de los leads | D17: Nota
A18: Solo su primer mensaje | B18: =COUNTIFS(Datos!$AJ$2:$AJ$408,A18) -> 108 | C18: =IFERROR(B18/COUNT(Datos!$B$2:$B$408),"—") -> 0.26535627 | D18: No volvió a escribir después de su primer mensaje.
A19: Saludo: contestó y no volvió | B19: =COUNTIFS(Datos!$AJ$2:$AJ$408,A19) -> 96 | C19: =IFERROR(B19/COUNT(Datos!$B$2:$B$408),"—") -> 0.23587224 | D19: Contestó el saludo (casi siempre su nombre) y ya no escribió.
A20: 1.2 Lista de cursos | B20: =COUNTIFS(Datos!$AJ$2:$AJ$408,A20) -> 74 | C20: =IFERROR(B20/COUNT(Datos!$B$2:$B$408),"—") -> 0.18181818 | D20: Incluye 1.1 Informes (dura 8 segundos).
A21: Negativo | B21: =COUNTIFS(Datos!$AJ$2:$AJ$408,A21) -> 51 | C21: =IFERROR(B21/COUNT(Datos!$B$2:$B$408),"—") -> 0.12530713 | D21: Seguimiento automático del bot.
A22: Facilidades de pago | B22: =COUNTIFS(Datos!$AJ$2:$AJ$408,A22) -> 48 | C22: =IFERROR(B22/COUNT(Datos!$B$2:$B$408),"—") -> 0.11793612 | D22: 1.3 y 1.4: ya pidió o recibió cómo pagar.
A23: Forma o medio de pago | B23: =COUNTIFS(Datos!$AJ$2:$AJ$408,A23) -> 8 | C23: =IFERROR(B23/COUNT(Datos!$B$2:$B$408),"—") -> 0.01965602 | D23: 2.x, MSI y 3.x: eligió cómo pagar o recibió los datos.
A24: Ya marcado como Perdido | B24: =COUNTIFS(Datos!$AJ$2:$AJ$408,A24) -> 12 | C24: =IFERROR(B24/COUNT(Datos!$B$2:$B$408),"—") -> 0.029484029 | D24: Escribió cuando ya estaba en Perdido.
A25: Compró | B25: =COUNTIFS(Datos!$AJ$2:$AJ$408,A25) -> 10 | C25: =IFERROR(B25/COUNT(Datos!$B$2:$B$408),"—") -> 0.024570025 | D25: Etapa Ganado.
A26: Total | B26: =SUM(B18:B25) -> 407 | C26: =IFERROR(B26/COUNT(Datos!$B$2:$B$408),"—") -> 1
A28: «Llegó a una etapa» = llegó a esa etapa o a una más lejana. Una venta cuenta como que pasó por todas.

Sheet Tiempos
A1: DESARROLLO PROFESIONAL SyS
A2: Tiempos de atención
A3: ISO + Calidad · desde que entra el lead y cuando el lead escribe · corte: 15 oct 2026, 23:59 h (Monterrey)
A5: ¿Cuánto tarda el primer mensaje de una persona?
A6: Tiempo desde que entró | B6: Leads | C6: % de los leads | D6: % que contestó el saludo | E6: % que llegó a facilidades | F6: Ventas | G6: Conversión
A7: 5 min o menos | B7: =COUNTIFS(Datos!$T$2:$T$408,"<=5") -> 30 | C7: =IFERROR(B7/COUNT(Datos!$B$2:$B$408),"—") -> 0.073710074 | D7: =IFERROR(COUNTIFS(Datos!$T$2:$T$408,"<=5",Datos!$G$2:$G$408,"Sí")/B7,"—") -> 0.76666667 | E7: =IFERROR(COUNTIFS(Datos!$T$2:$T$408,"<=5",Datos!$P$2:$P$408,"Sí")/B7,"—") -> 0.7 | F7: =COUNTIFS(Datos!$T$2:$T$408,"<=5",Datos!$AQ$2:$AQ$408,"Sí") -> 3 | G7: =IFERROR(F7/B7,"—") -> 0.1
A8: 5 a 15 min | B8: =COUNTIFS(Datos!$T$2:$T$408,">5",Datos!$T$2:$T$408,"<=15") -> 66 | C8: =IFERROR(B8/COUNT(Datos!$B$2:$B$408),"—") -> 0.16216216 | D8: =IFERROR(COUNTIFS(Datos!$T$2:$T$408,">5",Datos!$T$2:$T$408,"<=15",Datos!$G$2:$G$408,"Sí")/B8,"—") -> 1 | E8: =IFERROR(COUNTIFS(Datos!$T$2:$T$408,">5",Datos!$T$2:$T$408,"<=15",Datos!$P$2:$P$408,"Sí")/B8,"—") -> 0.74242424 | F8: =COUNTIFS(Datos!$T$2:$T$408,">5",Datos!$T$2:$T$408,"<=15",Datos!$AQ$2:$AQ$408,"Sí") -> 2 | G8: =IFERROR(F8/B8,"—") -> 0.03030303
A9: 15 a 60 min | B9: =COUNTIFS(Datos!$T$2:$T$408,">15",Datos!$T$2:$T$408,"<=60") -> 49 | C9: =IFERROR(B9/COUNT(Datos!$B$2:$B$408),"—") -> 0.12039312 | D9: =IFERROR(COUNTIFS(Datos!$T$2:$T$408,">15",Datos!$T$2:$T$408,"<=60",Datos!$G$2:$G$408,"Sí")/B9,"—") -> 0.7755102 | E9: =IFERROR(COUNTIFS(Datos!$T$2:$T$408,">15",Datos!$T$2:$T$408,"<=60",Datos!$P$2:$P$408,"Sí")/B9,"—") -> 0.7755102 | F9: =COUNTIFS(Datos!$T$2:$T$408,">15",Datos!$T$2:$T$408,"<=60",Datos!$AQ$2:$AQ$408,"Sí") -> 2 | G9: =IFERROR(F9/B9,"—") -> 0.040816327
A10: 1 a 4 h | B10: =COUNTIFS(Datos!$T$2:$T$408,">60",Datos!$T$2:$T$408,"<=240") -> 29 | C10: =IFERROR(B10/COUNT(Datos!$B$2:$B$408),"—") -> 0.071253071 | D10: =IFERROR(COUNTIFS(Datos!$T$2:$T$408,">60",Datos!$T$2:$T$408,"<=240",Datos!$G$2:$G$408,"Sí")/B10,"—") -> 0.51724138 | E10: =IFERROR(COUNTIFS(Datos!$T$2:$T$408,">60",Datos!$T$2:$T$408,"<=240",Datos!$P$2:$P$408,"Sí")/B10,"—") -> 0.5862069 | F10: =COUNTIFS(Datos!$T$2:$T$408,">60",Datos!$T$2:$T$408,"<=240",Datos!$AQ$2:$AQ$408,"Sí") -> 0 | G10: =IFERROR(F10/B10,"—") -> 0
A11: 4 a 24 h | B11: =COUNTIFS(Datos!$T$2:$T$408,">240",Datos!$T$2:$T$408,"<=1440") -> 35 | C11: =IFERROR(B11/COUNT(Datos!$B$2:$B$408),"—") -> 0.085995086 | D11: =IFERROR(COUNTIFS(Datos!$T$2:$T$408,">240",Datos!$T$2:$T$408,"<=1440",Datos!$G$2:$G$408,"Sí")/B11,"—") -> 0.62857143 | E11: =IFERROR(COUNTIFS(Datos!$T$2:$T$408,">240",Datos!$T$2:$T$408,"<=1440",Datos!$P$2:$P$408,"Sí")/B11,"—") -> 0.28571429 | F11: =COUNTIFS(Datos!$T$2:$T$408,">240",Datos!$T$2:$T$408,"<=1440",Datos!$AQ$2:$AQ$408,"Sí") -> 2 | G11: =IFERROR(F11/B11,"—") -> 0.057142857
A12: Más de 1 día | B12: =COUNTIFS(Datos!$T$2:$T$408,">1440") -> 147 | C12: =IFERROR(B12/COUNT(Datos!$B$2:$B$408),"—") -> 0.36117936 | D12: =IFERROR(COUNTIFS(Datos!$T$2:$T$408,">1440",Datos!$G$2:$G$408,"Sí")/B12,"—") -> 0.44897959 | E12: =IFERROR(COUNTIFS(Datos!$T$2:$T$408,">1440",Datos!$P$2:$P$408,"Sí")/B12,"—") -> 0.020408163 | F12: =COUNTIFS(Datos!$T$2:$T$408,">1440",Datos!$AQ$2:$AQ$408,"Sí") -> 1 | G12: =IFERROR(F12/B12,"—") -> 0.0068027211
A13: Nunca (solo el bot) | B13: =COUNTIFS(Datos!$T$2:$T$408,"") -> 51 | C13: =IFERROR(B13/COUNT(Datos!$B$2:$B$408),"—") -> 0.12530713 | D13: =IFERROR(COUNTIFS(Datos!$T$2:$T$408,"",Datos!$G$2:$G$408,"Sí")/B13,"—") -> 0.47058824 | E13: =IFERROR(COUNTIFS(Datos!$T$2:$T$408,"",Datos!$P$2:$P$408,"Sí")/B13,"—") -> 0.019607843 | F13: =COUNTIFS(Datos!$T$2:$T$408,"",Datos!$AQ$2:$AQ$408,"Sí") -> 0 | G13: =IFERROR(F13/B13,"—") -> 0
A14: Total | B14: =SUM(B7:B13) -> 407 | F14: =SUM(F7:F13) -> 10 | G14: =IFERROR(F14/B14,"—") -> 0.024570025
A15: Relación, no causa: quien contesta más rápido también recibe antes el mensaje de una persona.
A17: Cuando el lead escribe, ¿cuánto tarda una persona en contestar?
A18: Tiempo de respuesta | B18: De 9 a 21 h | C18: % de 9 a 21 h | D18: Fuera de horario | E18: % fuera | F18: Total | G18: % total
A19: 5 min o menos | B19: =COUNTIFS(Respuestas!$H$2:$H$1034,"<=5",Respuestas!$E$2:$E$1034,"Sí") -> 527 | C19: =IFERROR(B19/COUNTIFS(Respuestas!$E$2:$E$1034,"Sí"),"—") -> 0.63956311 | D19: =COUNTIFS(Respuestas!$H$2:$H$1034,"<=5",Respuestas!$E$2:$E$1034,"No") -> 111 | E19: =IFERROR(D19/COUNTIFS(Respuestas!$E$2:$E$1034,"No"),"—") -> 0.53110048 | F19: =COUNTIFS(Respuestas!$H$2:$H$1034,"<=5") -> 638 | G19: =IFERROR(F19/COUNT(Respuestas!$B$2:$B$1034),"—") -> 0.61761859
A20: 5 a 15 min | B20: =COUNTIFS(Respuestas!$H$2:$H$1034,">5",Respuestas!$H$2:$H$1034,"<=15",Respuestas!$E$2:$E$1034,"Sí") -> 144 | C20: =IFERROR(B20/COUNTIFS(Respuestas!$E$2:$E$1034,"Sí"),"—") -> 0.17475728 | D20: =COUNTIFS(Respuestas!$H$2:$H$1034,">5",Respuestas!$H$2:$H$1034,"<=15",Respuestas!$E$2:$E$1034,"No") -> 16 | E20: =IFERROR(D20/COUNTIFS(Respuestas!$E$2:$E$1034,"No"),"—") -> 0.076555024 | F20: =COUNTIFS(Respuestas!$H$2:$H$1034,">5",Respuestas!$H$2:$H$1034,"<=15") -> 160 | G20: =IFERROR(F20/COUNT(Respuestas!$B$2:$B$1034),"—") -> 0.15488867
A21: 15 a 60 min | B21: =COUNTIFS(Respuestas!$H$2:$H$1034,">15",Respuestas!$H$2:$H$1034,"<=60",Respuestas!$E$2:$E$1034,"Sí") -> 43 | C21: =IFERROR(B21/COUNTIFS(Respuestas!$E$2:$E$1034,"Sí"),"—") -> 0.052184466 | D21: =COUNTIFS(Respuestas!$H$2:$H$1034,">15",Respuestas!$H$2:$H$1034,"<=60",Respuestas!$E$2:$E$1034,"No") -> 16 | E21: =IFERROR(D21/COUNTIFS(Respuestas!$E$2:$E$1034,"No"),"—") -> 0.076555024 | F21: =COUNTIFS(Respuestas!$H$2:$H$1034,">15",Respuestas!$H$2:$H$1034,"<=60") -> 59 | G21: =IFERROR(F21/COUNT(Respuestas!$B$2:$B$1034),"—") -> 0.057115198
A22: 1 a 4 h | B22: =COUNTIFS(Respuestas!$H$2:$H$1034,">60",Respuestas!$H$2:$H$1034,"<=240",Respuestas!$E$2:$E$1034,"Sí") -> 14 | C22: =IFERROR(B22/COUNTIFS(Respuestas!$E$2:$E$1034,"Sí"),"—") -> 0.016990291 | D22: =COUNTIFS(Respuestas!$H$2:$H$1034,">60",Respuestas!$H$2:$H$1034,"<=240",Respuestas!$E$2:$E$1034,"No") -> 13 | E22: =IFERROR(D22/COUNTIFS(Respuestas!$E$2:$E$1034,"No"),"—") -> 0.062200957 | F22: =COUNTIFS(Respuestas!$H$2:$H$1034,">60",Respuestas!$H$2:$H$1034,"<=240") -> 27 | G22: =IFERROR(F22/COUNT(Respuestas!$B$2:$B$1034),"—") -> 0.026137464
A23: Más de 4 h | B23: =COUNTIFS(Respuestas!$H$2:$H$1034,">240",Respuestas!$E$2:$E$1034,"Sí") -> 71 | C23: =IFERROR(B23/COUNTIFS(Respuestas!$E$2:$E$1034,"Sí"),"—") -> 0.086165049 | D23: =COUNTIFS(Respuestas!$H$2:$H$1034,">240",Respuestas!$E$2:$E$1034,"No") -> 42 | E23: =IFERROR(D23/COUNTIFS(Respuestas!$E$2:$E$1034,"No"),"—") -> 0.20095694 | F23: =COUNTIFS(Respuestas!$H$2:$H$1034,">240") -> 113 | G23: =IFERROR(F23/COUNT(Respuestas!$B$2:$B$1034),"—") -> 0.10939013
A24: Sin respuesta de una persona | B24: =COUNTIFS(Respuestas!$H$2:$H$1034,"",Respuestas!$E$2:$E$1034,"Sí") -> 24 | C24: =IFERROR(B24/COUNTIFS(Respuestas!$E$2:$E$1034,"Sí"),"—") -> 0.029126214 | D24: =COUNTIFS(Respuestas!$H$2:$H$1034,"",Respuestas!$E$2:$E$1034,"No") -> 9 | E24: =IFERROR(D24/COUNTIFS(Respuestas!$E$2:$E$1034,"No"),"—") -> 0.043062201 | F24: =COUNTIFS(Respuestas!$H$2:$H$1034,"") -> 36 | G24: =IFERROR(F24/COUNT(Respuestas!$B$2:$B$1034),"—") -> 0.034849952
A25: Mensajes del lead (rachas) | B25: =COUNTIFS(Respuestas!$E$2:$E$1034,"Sí") -> 824 | D25: =COUNTIFS(Respuestas!$E$2:$E$1034,"No") -> 209 | F25: =COUNT(Respuestas!$B$2:$B$1034) -> 1033
A26: Minutos de respuesta · mediana | B26: {=IFERROR(MEDIAN(IF((Respuestas!$E$2:$E$1034="Sí")*(Respuestas!$H$2:$H$1034<>""),Respuestas!$H$2:$H$1034)),"—")} -> 2.9 | D26: {=IFERROR(MEDIAN(IF((Respuestas!$E$2:$E$1034="No")*(Respuestas!$H$2:$H$1034<>""),Respuestas!$H$2:$H$1034)),"—")} -> 4.1 | F26: =IFERROR(MEDIAN(Respuestas!$H$2:$H$1034),"—") -> 3.1
A27: % en que el bot contestó primero | C27: =IFERROR(COUNTIFS(Respuestas!$E$2:$E$1034,"Sí",Respuestas!$I$2:$I$1034,"Bot")/B25,"—") -> 0.30582524 | E27: =IFERROR(COUNTIFS(Respuestas!$E$2:$E$1034,"No",Respuestas!$I$2:$I$1034,"Bot")/D25,"—") -> 0.37799043 | G27: =IFERROR(COUNTIFS(Respuestas!$I$2:$I$1034,"Bot")/F25,"—") -> 0.32042594
A28: Racha = uno o varios mensajes seguidos del lead, después de que el bot pidió el nombre. Se mide hasta el siguiente mensaje de una persona.
A30: Según la hora en que entró el lead
A31: Hora de entrada | B31: Leads | C31: % de los leads | D31: % que contestó el saludo | E31: Min. a 1.1 (mediana) | F31: Ventas | G31: Conversión
A32: 00:00 a 00:59 (fuera de horario) | B32: =COUNTIFS(Datos!$E$2:$E$408,0) -> 5 | C32: =IFERROR(B32/COUNT(Datos!$B$2:$B$408),"—") -> 0.012285012 | D32: =IFERROR(COUNTIFS(Datos!$E$2:$E$408,0,Datos!$G$2:$G$408,"Sí")/B32,"—") -> 0.4 | E32: {=IFERROR(MEDIAN(IF((Datos!$E$2:$E$408=0)*(Datos!$J$2:$J$408<>""),Datos!$J$2:$J$408)),"—")} -> 423.6 | F32: =COUNTIFS(Datos!$E$2:$E$408,0,Datos!$AQ$2:$AQ$408,"Sí") -> 0 | G32: =IFERROR(F32/B32,"—") -> 0
A33: 01:00 a 01:59 (fuera de horario) | B33: =COUNTIFS(Datos!$E$2:$E$408,1) -> 5 | C33: =IFERROR(B33/COUNT(Datos!$B$2:$B$408),"—") -> 0.012285012 | D33: =IFERROR(COUNTIFS(Datos!$E$2:$E$408,1,Datos!$G$2:$G$408,"Sí")/B33,"—") -> 0.4 | E33: {=IFERROR(MEDIAN(IF((Datos!$E$2:$E$408=1)*(Datos!$J$2:$J$408<>""),Datos!$J$2:$J$408)),"—")} -> 320.2 | F33: =COUNTIFS(Datos!$E$2:$E$408,1,Datos!$AQ$2:$AQ$408,"Sí") -> 0 | G33: =IFERROR(F33/B33,"—") -> 0
A34: 02:00 a 02:59 (fuera de horario) | B34: =COUNTIFS(Datos!$E$2:$E$408,2) -> 3 | C34: =IFERROR(B34/COUNT(Datos!$B$2:$B$408),"—") -> 0.0073710074 | D34: =IFERROR(COUNTIFS(Datos!$E$2:$E$408,2,Datos!$G$2:$G$408,"Sí")/B34,"—") -> 0.33333333 | E34: {=IFERROR(MEDIAN(IF((Datos!$E$2:$E$408=2)*(Datos!$J$2:$J$408<>""),Datos!$J$2:$J$408)),"—")} -> 269.5 | F34: =COUNTIFS(Datos!$E$2:$E$408,2,Datos!$AQ$2:$AQ$408,"Sí") -> 0 | G34: =IFERROR(F34/B34,"—") -> 0
A35: 03:00 a 03:59 (fuera de horario) | B35: =COUNTIFS(Datos!$E$2:$E$408,3) -> 0 | C35: =IFERROR(B35/COUNT(Datos!$B$2:$B$408),"—") -> 0 | D35: =IFERROR(COUNTIFS(Datos!$E$2:$E$408,3,Datos!$G$2:$G$408,"Sí")/B35,"—") -> — | E35: {=IFERROR(MEDIAN(IF((Datos!$E$2:$E$408=3)*(Datos!$J$2:$J$408<>""),Datos!$J$2:$J$408)),"—")} -> — | F35: =COUNTIFS(Datos!$E$2:$E$408,3,Datos!$AQ$2:$AQ$408,"Sí") -> 0 | G35: =IFERROR(F35/B35,"—") -> —
A36: 04:00 a 04:59 (fuera de horario) | B36: =COUNTIFS(Datos!$E$2:$E$408,4) -> 3 | C36: =IFERROR(B36/COUNT(Datos!$B$2:$B$408),"—") -> 0.0073710074 | D36: =IFERROR(COUNTIFS(Datos!$E$2:$E$408,4,Datos!$G$2:$G$408,"Sí")/B36,"—") -> 0.33333333 | E36: {=IFERROR(MEDIAN(IF((Datos!$E$2:$E$408=4)*(Datos!$J$2:$J$408<>""),Datos!$J$2:$J$408)),"—")} -> 191.4 | F36: =COUNTIFS(Datos!$E$2:$E$408,4,Datos!$AQ$2:$AQ$408,"Sí") -> 0 | G36: =IFERROR(F36/B36,"—") -> 0
A37: 05:00 a 05:59 (fuera de horario) | B37: =COUNTIFS(Datos!$E$2:$E$408,5) -> 3 | C37: =IFERROR(B37/COUNT(Datos!$B$2:$B$408),"—") -> 0.0073710074 | D37: =IFERROR(COUNTIFS(Datos!$E$2:$E$408,5,Datos!$G$2:$G$408,"Sí")/B37,"—") -> 1 | E37: {=IFERROR(MEDIAN(IF((Datos!$E$2:$E$408=5)*(Datos!$J$2:$J$408<>""),Datos!$J$2:$J$408)),"—")} -> 117.6 | F37: =COUNTIFS(Datos!$E$2:$E$408,5,Datos!$AQ$2:$AQ$408,"Sí") -> 0 | G37: =IFERROR(F37/B37,"—") -> 0
A38: 06:00 a 06:59 (fuera de horario) | B38: =COUNTIFS(Datos!$E$2:$E$408,6) -> 9 | C38: =IFERROR(B38/COUNT(Datos!$B$2:$B$408),"—") -> 0.022113022 | D38: =IFERROR(COUNTIFS(Datos!$E$2:$E$408,6,Datos!$G$2:$G$408,"Sí")/B38,"—") -> 0.55555556 | E38: {=IFERROR(MEDIAN(IF((Datos!$E$2:$E$408=6)*(Datos!$J$2:$J$408<>""),Datos!$J$2:$J$408)),"—")} -> 75.4 | F38: =COUNTIFS(Datos!$E$2:$E$408,6,Datos!$AQ$2:$AQ$408,"Sí") -> 0 | G38: =IFERROR(F38/B38,"—") -> 0
A39: 07:00 a 07:59 (fuera de horario) | B39: =COUNTIFS(Datos!$E$2:$E$408,7) -> 14 | C39: =IFERROR(B39/COUNT(Datos!$B$2:$B$408),"—") -> 0.034398034 | D39: =IFERROR(COUNTIFS(Datos!$E$2:$E$408,7,Datos!$G$2:$G$408,"Sí")/B39,"—") -> 0.92857143 | E39: {=IFERROR(MEDIAN(IF((Datos!$E$2:$E$408=7)*(Datos!$J$2:$J$408<>""),Datos!$J$2:$J$408)),"—")} -> 2.9 | F39: =COUNTIFS(Datos!$E$2:$E$408,7,Datos!$AQ$2:$AQ$408,"Sí") -> 0 | G39: =IFERROR(F39/B39,"—") -> 0
A40: 08:00 a 08:59 (fuera de horario) | B40: =COUNTIFS(Datos!$E$2:$E$408,8) -> 11 | C40: =IFERROR(B40/COUNT(Datos!$B$2:$B$408),"—") -> 0.027027027 | D40: =IFERROR(COUNTIFS(Datos!$E$2:$E$408,8,Datos!$G$2:$G$408,"Sí")/B40,"—") -> 0.72727273 | E40: {=IFERROR(MEDIAN(IF((Datos!$E$2:$E$408=8)*(Datos!$J$2:$J$408<>""),Datos!$J$2:$J$408)),"—")} -> 1.3 | F40: =COUNTIFS(Datos!$E$2:$E$408,8,Datos!$AQ$2:$AQ$408,"Sí") -> 0 | G40: =IFERROR(F40/B40,"—") -> 0
A41: 09:00 a 09:59 | B41: =COUNTIFS(Datos!$E$2:$E$408,9) -> 15 | C41: =IFERROR(B41/COUNT(Datos!$B$2:$B$408),"—") -> 0.036855037 | D41: =IFERROR(COUNTIFS(Datos!$E$2:$E$408,9,Datos!$G$2:$G$408,"Sí")/B41,"—") -> 0.26666667 | E41: {=IFERROR(MEDIAN(IF((Datos!$E$2:$E$408=9)*(Datos!$J$2:$J$408<>""),Datos!$J$2:$J$408)),"—")} -> 0.45 | F41: =COUNTIFS(Datos!$E$2:$E$408,9,Datos!$AQ$2:$AQ$408,"Sí") -> 1 | G41: =IFERROR(F41/B41,"—") -> 0.066666667
A42: 10:00 a 10:59 | B42: =COUNTIFS(Datos!$E$2:$E$408,10) -> 27 | C42: =IFERROR(B42/COUNT(Datos!$B$2:$B$408),"—") -> 0.066339066 | D42: =IFERROR(COUNTIFS(Datos!$E$2:$E$408,10,Datos!$G$2:$G$408,"Sí")/B42,"—") -> 0.7037037 | E42: {=IFERROR(MEDIAN(IF((Datos!$E$2:$E$408=10)*(Datos!$J$2:$J$408<>""),Datos!$J$2:$J$408)),"—")} -> 0.55 | F42: =COUNTIFS(Datos!$E$2:$E$408,10,Datos!$AQ$2:$AQ$408,"Sí") -> 0 | G42: =IFERROR(F42/B42,"—") -> 0
A43: 11:00 a 11:59 | B43: =COUNTIFS(Datos!$E$2:$E$408,11) -> 34 | C43: =IFERROR(B43/COUNT(Datos!$B$2:$B$408),"—") -> 0.083538084 | D43: =IFERROR(COUNTIFS(Datos!$E$2:$E$408,11,Datos!$G$2:$G$408,"Sí")/B43,"—") -> 0.61764706 | E43: {=IFERROR(MEDIAN(IF((Datos!$E$2:$E$408=11)*(Datos!$J$2:$J$408<>""),Datos!$J$2:$J$408)),"—")} -> 0.4 | F43: =COUNTIFS(Datos!$E$2:$E$408,11,Datos!$AQ$2:$AQ$408,"Sí") -> 2 | G43: =IFERROR(F43/B43,"—") -> 0.058823529
...

Sheet Ofertas y ventas
A1: DESARROLLO PROFESIONAL SyS
A2: Ofertas y ventas
A3: ISO + Calidad · ofertas escritas en mensajes y ventas registradas en el CRM · corte: 15 oct 2026, 23:59 h (Monterrey)
A5: Ofertas que recibió el lead
A6: Oferta | B6: Leads | C6: % de los leads | D6: Compraron | E6: Conversión
A7: Alguna oferta | B7: =COUNTIFS(Datos!$Z$2:$Z$408,"Sí") -> 352 | C7: =IFERROR(B7/COUNT(Datos!$B$2:$B$408),"—") -> 0.86486486 | D7: =COUNTIFS(Datos!$Z$2:$Z$408,"Sí",Datos!$AQ$2:$AQ$408,"Sí") -> 8 | E7: =IFERROR(D7/B7,"—") -> 0.022727273
A8: $3,799 | B8: =COUNTIFS(Datos!$AA$2:$AA$408,"*3,799*") -> 346 | C8: =IFERROR(B8/COUNT(Datos!$B$2:$B$408),"—") -> 0.85012285 | D8: =COUNTIFS(Datos!$AA$2:$AA$408,"*3,799*",Datos!$AQ$2:$AQ$408,"Sí") -> 5 | E8: =IFERROR(D8/B8,"—") -> 0.014450867
A9: $3,400 | B9: =COUNTIFS(Datos!$AA$2:$AA$408,"*3,400*") -> 1 | C9: =IFERROR(B9/COUNT(Datos!$B$2:$B$408),"—") -> 0.0024570025 | D9: =COUNTIFS(Datos!$AA$2:$AA$408,"*3,400*",Datos!$AQ$2:$AQ$408,"Sí") -> 0 | E9: =IFERROR(D9/B9,"—") -> 0
A10: $2,799 | B10: =COUNTIFS(Datos!$AA$2:$AA$408,"*2,799*") -> 306 | C10: =IFERROR(B10/COUNT(Datos!$B$2:$B$408),"—") -> 0.75184275 | D10: =COUNTIFS(Datos!$AA$2:$AA$408,"*2,799*",Datos!$AQ$2:$AQ$408,"Sí") -> 6 | E10: =IFERROR(D10/B10,"—") -> 0.019607843
A11: $1,950 | B11: =COUNTIFS(Datos!$AA$2:$AA$408,"*1,950*") -> 0 | C11: =IFERROR(B11/COUNT(Datos!$B$2:$B$408),"—") -> 0 | D11: =COUNTIFS(Datos!$AA$2:$AA$408,"*1,950*",Datos!$AQ$2:$AQ$408,"Sí") -> 0 | E11: =IFERROR(D11/B11,"—") -> —
A12: Ninguna oferta | B12: =COUNTIFS(Datos!$Z$2:$Z$408,"No") -> 55 | C12: =IFERROR(B12/COUNT(Datos!$B$2:$B$408),"—") -> 0.13513514 | D12: =COUNTIFS(Datos!$Z$2:$Z$408,"No",Datos!$AQ$2:$AQ$408,"Sí") -> 2 | E12: =IFERROR(D12/B12,"—") -> 0.036363636
A13: Un lead puede recibir varias ofertas. «Compraron» incluye a quien compró a otro precio.
A15: ¿Quién mandó la primera oferta?
A16: Primera oferta enviada por | B16: Leads | C16: % de las primeras ofertas | D16: Horas a la 1a oferta (mediana)
A17: Bot | B17: =COUNTIFS(Datos!$AB$2:$AB$408,"Bot") -> 279 | C17: =IFERROR(B17/COUNTIFS(Datos!$Z$2:$Z$408,"Sí"),"—") -> 0.79261364 | D17: {=IFERROR(MEDIAN(IF((Datos!$AB$2:$AB$408="Bot")*(Datos!$AC$2:$AC$408<>""),Datos!$AC$2:$AC$408)),"—")} -> 30.2
A18: Joceline | B18: =COUNTIFS(Datos!$AB$2:$AB$408,"Joceline") -> 43 | C18: =IFERROR(B18/COUNTIFS(Datos!$Z$2:$Z$408,"Sí"),"—") -> 0.12215909 | D18: {=IFERROR(MEDIAN(IF((Datos!$AB$2:$AB$408="Joceline")*(Datos!$AC$2:$AC$408<>""),Datos!$AC$2:$AC$408)),"—")} -> 31.6
A19: Salma | B19: =COUNTIFS(Datos!$AB$2:$AB$408,"Salma") -> 14 | C19: =IFERROR(B19/COUNTIFS(Datos!$Z$2:$Z$408,"Sí"),"—") -> 0.039772727 | D19: {=IFERROR(MEDIAN(IF((Datos!$AB$2:$AB$408="Salma")*(Datos!$AC$2:$AC$408<>""),Datos!$AC$2:$AC$408)),"—")} -> 40.65
A20: Alexander | B20: =COUNTIFS(Datos!$AB$2:$AB$408,"Alexander") -> 13 | C20: =IFERROR(B20/COUNTIFS(Datos!$Z$2:$Z$408,"Sí"),"—") -> 0.036931818 | D20: {=IFERROR(MEDIAN(IF((Datos!$AB$2:$AB$408="Alexander")*(Datos!$AC$2:$AC$408<>""),Datos!$AC$2:$AC$408)),"—")} -> 48.5
A21: Victoria | B21: =COUNTIFS(Datos!$AB$2:$AB$408,"Victoria") -> 3 | C21: =IFERROR(B21/COUNTIFS(Datos!$Z$2:$Z$408,"Sí"),"—") -> 0.0085227273 | D21: {=IFERROR(MEDIAN(IF((Datos!$AB$2:$AB$408="Victoria")*(Datos!$AC$2:$AC$408<>""),Datos!$AC$2:$AC$408)),"—")} -> 24.1
A22: Cuando una persona manda la oferta casi siempre es con una plantilla de Meta (imagen con el precio y botones).
A24: Precio al que se vendió
A25: Precio de venta | B25: Ventas | C25: % de las ventas | D25: Ingreso
A26: $3,999 o más (lista) | B26: =COUNTIFS(Datos!$AQ$2:$AQ$408,"Sí",Datos!$AR$2:$AR$408,">=3999") -> 2 | C26: =IFERROR(B26/COUNTIFS(Datos!$AQ$2:$AQ$408,"Sí"),"—") -> 0.2 | D26: =SUMIFS(Datos!$AR$2:$AR$408,Datos!$AQ$2:$AQ$408,"Sí",Datos!$AR$2:$AR$408,">=3999") -> 7998
A27: $3,799 | B27: =COUNTIFS(Datos!$AQ$2:$AQ$408,"Sí",Datos!$AR$2:$AR$408,3799) -> 2 | C27: =IFERROR(B27/COUNTIFS(Datos!$AQ$2:$AQ$408,"Sí"),"—") -> 0.2 | D27: =SUMIFS(Datos!$AR$2:$AR$408,Datos!$AQ$2:$AQ$408,"Sí",Datos!$AR$2:$AR$408,3799) -> 7598
A28: $3,400 | B28: =COUNTIFS(Datos!$AQ$2:$AQ$408,"Sí",Datos!$AR$2:$AR$408,3400) -> 0 | C28: =IFERROR(B28/COUNTIFS(Datos!$AQ$2:$AQ$408,"Sí"),"—") -> 0 | D28: =SUMIFS(Datos!$AR$2:$AR$408,Datos!$AQ$2:$AQ$408,"Sí",Datos!$AR$2:$AR$408,3400) -> 0
A29: $2,799 | B29: =COUNTIFS(Datos!$AQ$2:$AQ$408,"Sí",Datos!$AR$2:$AR$408,2799) -> 6 | C29: =IFERROR(B29/COUNTIFS(Datos!$AQ$2:$AQ$408,"Sí"),"—") -> 0.6 | D29: =SUMIFS(Datos!$AR$2:$AR$408,Datos!$AQ$2:$AQ$408,"Sí",Datos!$AR$2:$AR$408,2799) -> 16794
A30: $2,000 | B30: =COUNTIFS(Datos!$AQ$2:$AQ$408,"Sí",Datos!$AR$2:$AR$408,2000) -> 0 | C30: =IFERROR(B30/COUNTIFS(Datos!$AQ$2:$AQ$408,"Sí"),"—") -> 0 | D30: =SUMIFS(Datos!$AR$2:$AR$408,Datos!$AQ$2:$AQ$408,"Sí",Datos!$AR$2:$AR$408,2000) -> 0
A31: $1,950 | B31: =COUNTIFS(Datos!$AQ$2:$AQ$408,"Sí",Datos!$AR$2:$AR$408,1950) -> 0 | C31: =IFERROR(B31/COUNTIFS(Datos!$AQ$2:$AQ$408,"Sí"),"—") -> 0 | D31: =SUMIFS(Datos!$AR$2:$AR$408,Datos!$AQ$2:$AQ$408,"Sí",Datos!$AR$2:$AR$408,1950) -> 0
A32: Total | B32: =COUNTIFS(Datos!$AQ$2:$AQ$408,"Sí") -> 10 | D32: =SUMIFS(Datos!$AR$2:$AR$408,Datos!$AQ$2:$AQ$408,"Sí") -> 32390
A33: Ingreso si todas fueran a $3,999 | D33: =B32*3999 -> 39990
A34: Precio = presupuesto registrado al pasar a Ganado.
A36: Las ventas, una por una
A37: ID (#) | B37: Entrada | C37: Asesor asignado | D37: Ofertas recibidas | E37: Primera oferta enviada por | F37: Precio de venta | G37: Estado del cobro | H37: Horas hasta la venta
A38: =IF(Datos!B39="","—",Datos!B39) -> 370 | B38: =IF(Datos!C39="","—",Datos!C39) -> 46301.459 | C38: =IF(Datos!R39="","—",Datos!R39) -> Salma | D38: =IF(Datos!AA39="","—",Datos!AA39) -> $2,799 | E38: =IF(Datos!AB39="","—",Datos!AB39) -> Joceline | F38: =IF(Datos!AR39="","—",Datos!AR39) -> 2799 | G38: =IF(Datos!AS39="","—",Datos!AS39) -> Pagada completa | H38: =IF(Datos!AT39="","—",Datos!AT39) -> 22
A39: =IF(Datos!B67="","—",Datos!B67) -> 477 | B39: =IF(Datos!C67="","—",Datos!C67) -> 46301.86 | C39: =IF(Datos!R67="","—",Datos!R67) -> Victoria | D39: =IF(Datos!AA67="","—",Datos!AA67) -> $2,799 | E39: =IF(Datos!AB67="","—",Datos!AB67) -> Joceline | F39: =IF(Datos!AR67="","—",Datos!AR67) -> 2799 | G39: =IF(Datos!AS67="","—",Datos!AS67) -> Con saldo pendiente | H39: =IF(Datos!AT67="","—",Datos!AT67) -> 15.7
A40: =IF(Datos!B178="","—",Datos!B178) -> 1001 | B40: =IF(Datos!C178="","—",Datos!C178) -> 46304.399 | C40: =IF(Datos!R178="","—",Datos!R178) -> Salma | D40: =IF(Datos!AA178="","—",Datos!AA178) -> $2,799 | E40: =IF(Datos!AB178="","—",Datos!AB178) -> Salma | F40: =IF(Datos!AR178="","—",Datos!AR178) -> 2799 | G40: =IF(Datos!AS178="","—",Datos!AS178) -> Con saldo pendiente | H40: =IF(Datos!AT178="","—",Datos!AT178) -> 98.8
A41: =IF(Datos!B206="","—",Datos!B206) -> 1181 | B41: =IF(Datos!C206="","—",Datos!C206) -> 46305.485 | C41: =IF(Datos!R206="","—",Datos!R206) -> Alexander | D41: =IF(Datos!AA206="","—",Datos!AA206) -> — | E41: =IF(Datos!AB206="","—",Datos!AB206) -> — | F41: =IF(Datos!AR206="","—",Datos!AR206) -> 3999 | G41: =IF(Datos!AS206="","—",Datos!AS206) -> Con saldo pendiente | H41: =IF(Datos!AT206="","—",Datos!AT206) -> 101.6
A42: =IF(Datos!B211="","—",Datos!B211) -> 1194 | B42: =IF(Datos!C211="","—",Datos!C211) -> 46305.564 | C42: =IF(Datos!R211="","—",Datos!R211) -> Alexander | D42: =IF(Datos!AA211="","—",Datos!AA211) -> $3,799, $2,799 | E42: =IF(Datos!AB211="","—",Datos!AB211) -> Bot | F42: =IF(Datos!AR211="","—",Datos!AR211) -> 2799 | G42: =IF(Datos!AS211="","—",Datos!AS211) -> Pagada completa | H42: =IF(Datos!AT211="","—",Datos!AT211) -> 54.2
A43: =IF(Datos!B222="","—",Datos!B222) -> 1237 | B43: =IF(Datos!C222="","—",Datos!C222) -> 46305.833 | C43: =IF(Datos!R222="","—",Datos!R222) -> Victoria | D43: =IF(Datos!AA222="","—",Datos!AA222) -> $3,799, $2,799 | E43: =IF(Datos!AB222="","—",Datos!AB222) -> Victoria | F43: =IF(Datos!AR222="","—",Datos!AR222) -> 2799 | G43: =IF(Datos!AS222="","—",Datos!AS222) -> Pagada completa | H43: =IF(Datos!AT222="","—",Datos!AT222) -> 89.9
A44: =IF(Datos!B246="","—",Datos!B246) -> 1338 | B44: =IF(Datos!C246="","—",Datos!C246) -> 46306.743 | C44: =IF(Datos!R246="","—",Datos!R246) -> Salma | D44: =IF(Datos!AA246="","—",Datos!AA246) -> $3,799 | E44: =IF(Datos!AB246="","—",Datos!AB246) -> Bot | F44: =IF(Datos!AR246="","—",Datos!AR246) -> 3799 | G44: =IF(Datos!AS246="","—",Datos!AS246) -> Pagada completa | H44: =IF(Datos!AT246="","—",Datos!AT246) -> 44.4
...

Sheet Perfil y asesores
A1: DESARROLLO PROFESIONAL SyS
A2: Perfil del lead, señales y asesores
A3: ISO + Calidad · corte: 15 oct 2026, 23:59 h (Monterrey)
A5: Ocupación (de quienes la contestaron)
A6: Ocupación | B6: Leads | C6: % de los que contestaron | D6: Llegaron a facilidades | E6: Ventas | F6: Conversión
A7: Calidad | B7: =COUNTIFS(Datos!$N$2:$N$408,"Calidad") -> 55 | C7: =IFERROR(B7/COUNTIFS(Datos!$M$2:$M$408,"Sí"),"—") -> 0.34810127 | D7: =COUNTIFS(Datos!$N$2:$N$408,"Calidad",Datos!$P$2:$P$408,"Sí") -> 47 | E7: =COUNTIFS(Datos!$N$2:$N$408,"Calidad",Datos!$AQ$2:$AQ$408,"Sí") -> 3 | F7: =IFERROR(E7/B7,"—") -> 0.054545455
A8: Producción u operaciones | B8: =COUNTIFS(Datos!$N$2:$N$408,"Producción u operaciones") -> 24 | C8: =IFERROR(B8/COUNTIFS(Datos!$M$2:$M$408,"Sí"),"—") -> 0.15189873 | D8: =COUNTIFS(Datos!$N$2:$N$408,"Producción u operaciones",Datos!$P$2:$P$408,"Sí") -> 18 | E8: =COUNTIFS(Datos!$N$2:$N$408,"Producción u operaciones",Datos!$AQ$2:$AQ$408,"Sí") -> 0 | F8: =IFERROR(E8/B8,"—") -> 0
A9: Supervisión o jefatura | B9: =COUNTIFS(Datos!$N$2:$N$408,"Supervisión o jefatura") -> 15 | C9: =IFERROR(B9/COUNTIFS(Datos!$M$2:$M$408,"Sí"),"—") -> 0.094936709 | D9: =COUNTIFS(Datos!$N$2:$N$408,"Supervisión o jefatura",Datos!$P$2:$P$408,"Sí") -> 12 | E9: =COUNTIFS(Datos!$N$2:$N$408,"Supervisión o jefatura",Datos!$AQ$2:$AQ$408,"Sí") -> 0 | F9: =IFERROR(E9/B9,"—") -> 0
A10: Ingeniería | B10: =COUNTIFS(Datos!$N$2:$N$408,"Ingeniería") -> 18 | C10: =IFERROR(B10/COUNTIFS(Datos!$M$2:$M$408,"Sí"),"—") -> 0.11392405 | D10: =COUNTIFS(Datos!$N$2:$N$408,"Ingeniería",Datos!$P$2:$P$408,"Sí") -> 13 | E10: =COUNTIFS(Datos!$N$2:$N$408,"Ingeniería",Datos!$AQ$2:$AQ$408,"Sí") -> 0 | F10: =IFERROR(E10/B10,"—") -> 0
A11: Estudiante o recién egresado | B11: =COUNTIFS(Datos!$N$2:$N$408,"Estudiante o recién egresado") -> 30 | C11: =IFERROR(B11/COUNTIFS(Datos!$M$2:$M$408,"Sí"),"—") -> 0.18987342 | D11: =COUNTIFS(Datos!$N$2:$N$408,"Estudiante o recién egresado",Datos!$P$2:$P$408,"Sí") -> 23 | E11: =COUNTIFS(Datos!$N$2:$N$408,"Estudiante o recién egresado",Datos!$AQ$2:$AQ$408,"Sí") -> 0 | F11: =IFERROR(E11/B11,"—") -> 0
A12: Sin empleo o buscando | B12: =COUNTIFS(Datos!$N$2:$N$408,"Sin empleo o buscando") -> 6 | C12: =IFERROR(B12/COUNTIFS(Datos!$M$2:$M$408,"Sí"),"—") -> 0.037974684 | D12: =COUNTIFS(Datos!$N$2:$N$408,"Sin empleo o buscando",Datos!$P$2:$P$408,"Sí") -> 6 | E12: =COUNTIFS(Datos!$N$2:$N$408,"Sin empleo o buscando",Datos!$AQ$2:$AQ$408,"Sí") -> 0 | F12: =IFERROR(E12/B12,"—") -> 0
A13: Otra área | B13: =COUNTIFS(Datos!$N$2:$N$408,"Otra área") -> 10 | C13: =IFERROR(B13/COUNTIFS(Datos!$M$2:$M$408,"Sí"),"—") -> 0.063291139 | D13: =COUNTIFS(Datos!$N$2:$N$408,"Otra área",Datos!$P$2:$P$408,"Sí") -> 6 | E13: =COUNTIFS(Datos!$N$2:$N$408,"Otra área",Datos!$AQ$2:$AQ$408,"Sí") -> 0 | F13: =IFERROR(E13/B13,"—") -> 0
A14: Agrupado por palabras de lo que contestó en 24 h. Si trabaja y estudia, cuenta su área de trabajo.
A16: Señales y conversión
A17: Señal | B17: Sí: leads | C17: Sí: ventas | D17: Sí: conversión | E17: No: leads | F17: No: ventas | G17: No: conversión
A18: Contestó el saludo | B18: =COUNTIFS(Datos!$G$2:$G$408,"Sí") -> 256 | C18: =COUNTIFS(Datos!$G$2:$G$408,"Sí",Datos!$AQ$2:$AQ$408,"Sí") -> 7 | D18: =IFERROR(C18/B18,"—") -> 0.02734375 | E18: =COUNTIFS(Datos!$G$2:$G$408,"No") -> 151 | F18: =COUNTIFS(Datos!$G$2:$G$408,"No",Datos!$AQ$2:$AQ$408,"Sí") -> 3 | G18: =IFERROR(F18/E18,"—") -> 0.01986755
A19: Contestó la ocupación | B19: =COUNTIFS(Datos!$M$2:$M$408,"Sí") -> 158 | C19: =COUNTIFS(Datos!$M$2:$M$408,"Sí",Datos!$AQ$2:$AQ$408,"Sí") -> 3 | D19: =IFERROR(C19/B19,"—") -> 0.018987342 | E19: =COUNTIFS(Datos!$M$2:$M$408,"No") -> 249 | F19: =COUNTIFS(Datos!$M$2:$M$408,"No",Datos!$AQ$2:$AQ$408,"Sí") -> 7 | G19: =IFERROR(F19/E19,"—") -> 0.02811245
A20: Abrió algún link | B20: =COUNTIFS(Datos!$AG$2:$AG$408,"Sí") -> 105 | C20: =COUNTIFS(Datos!$AG$2:$AG$408,"Sí",Datos!$AQ$2:$AQ$408,"Sí") -> 7 | D20: =IFERROR(C20/B20,"—") -> 0.066666667 | E20: =COUNTIFS(Datos!$AG$2:$AG$408,"No") -> 302 | F20: =COUNTIFS(Datos!$AG$2:$AG$408,"No",Datos!$AQ$2:$AQ$408,"Sí") -> 3 | G20: =IFERROR(F20/E20,"—") -> 0.0099337748
A21: Recibió audio del equipo | B21: =COUNTIFS(Datos!$Y$2:$Y$408,"Sí") -> 156 | C21: =COUNTIFS(Datos!$Y$2:$Y$408,"Sí",Datos!$AQ$2:$AQ$408,"Sí") -> 4 | D21: =IFERROR(C21/B21,"—") -> 0.025641026 | E21: =COUNTIFS(Datos!$Y$2:$Y$408,"No") -> 251 | F21: =COUNTIFS(Datos!$Y$2:$Y$408,"No",Datos!$AQ$2:$AQ$408,"Sí") -> 6 | G21: =IFERROR(F21/E21,"—") -> 0.023904382
A22: Intervino auxiliar | B22: =COUNTIFS(Datos!$S$2:$S$408,"Sí") -> 209 | C22: =COUNTIFS(Datos!$S$2:$S$408,"Sí",Datos!$AQ$2:$AQ$408,"Sí") -> 8 | D22: =IFERROR(C22/B22,"—") -> 0.038277512 | E22: =COUNTIFS(Datos!$S$2:$S$408,"No") -> 198 | F22: =COUNTIFS(Datos!$S$2:$S$408,"No",Datos!$AQ$2:$AQ$408,"Sí") -> 2 | G22: =IFERROR(F22/E22,"—") -> 0.01010101
A23: Entró de 9 a 21 h | B23: =COUNTIFS(Datos!$F$2:$F$408,"Sí") -> 305 | C23: =COUNTIFS(Datos!$F$2:$F$408,"Sí",Datos!$AQ$2:$AQ$408,"Sí") -> 9 | D23: =IFERROR(C23/B23,"—") -> 0.029508197 | E23: =COUNTIFS(Datos!$F$2:$F$408,"No") -> 102 | F23: =COUNTIFS(Datos!$F$2:$F$408,"No",Datos!$AQ$2:$AQ$408,"Sí") -> 1 | G23: =IFERROR(F23/E23,"—") -> 0.0098039216
A24: Recibió oferta | B24: =COUNTIFS(Datos!$Z$2:$Z$408,"Sí") -> 352 | C24: =COUNTIFS(Datos!$Z$2:$Z$408,"Sí",Datos!$AQ$2:$AQ$408,"Sí") -> 8 | D24: =IFERROR(C24/B24,"—") -> 0.022727273 | E24: =COUNTIFS(Datos!$Z$2:$Z$408,"No") -> 55 | F24: =COUNTIFS(Datos!$Z$2:$Z$408,"No",Datos!$AQ$2:$AQ$408,"Sí") -> 2 | G24: =IFERROR(F24/E24,"—") -> 0.036363636
A25: Relación, no causa. Con pocas ventas, cada caso pesa mucho.
A27: Links que abrió el lead (aviso del CRM)
A28: Link | B28: Leads | C28: % de los leads | D28: Ventas | E28: Conversión
A29: Su ruta (temario) | B29: =COUNTIFS(Datos!$AH$2:$AH$408,"*Ruta*") -> 81 | C29: =IFERROR(B29/COUNT(Datos!$B$2:$B$408),"—") -> 0.1990172 | D29: =COUNTIFS(Datos!$AH$2:$AH$408,"*Ruta*",Datos!$AQ$2:$AQ$408,"Sí") -> 5 | E29: =IFERROR(D29/B29,"—") -> 0.061728395
A30: Clase demo | B30: =COUNTIFS(Datos!$AH$2:$AH$408,"*Clase demo*") -> 27 | C30: =IFERROR(B30/COUNT(Datos!$B$2:$B$408),"—") -> 0.066339066 | D30: =COUNTIFS(Datos!$AH$2:$AH$408,"*Clase demo*",Datos!$AQ$2:$AQ$408,"Sí") -> 4 | E30: =IFERROR(D30/B30,"—") -> 0.14814815
A31: Mapa de las 64 certificaciones | B31: =COUNTIFS(Datos!$AH$2:$AH$408,"*Mapa 64*") -> 13 | C31: =IFERROR(B31/COUNT(Datos!$B$2:$B$408),"—") -> 0.031941032 | D31: =COUNTIFS(Datos!$AH$2:$AH$408,"*Mapa 64*",Datos!$AQ$2:$AQ$408,"Sí") -> 2 | E31: =IFERROR(D31/B31,"—") -> 0.15384615
A32: Perfil profesional de ejemplo | B32: =COUNTIFS(Datos!$AH$2:$AH$408,"*Perfil ejemplo*") -> 3 | C32: =IFERROR(B32/COUNT(Datos!$B$2:$B$408),"—") -> 0.0073710074 | D32: =COUNTIFS(Datos!$AH$2:$AH$408,"*Perfil ejemplo*",Datos!$AQ$2:$AQ$408,"Sí") -> 0 | E32: =IFERROR(D32/B32,"—") -> 0
A34: Por asesor asignado
A35: Asesor | B35: Leads | C35: % de los leads | D35: % que contestó el saludo | E35: Min. a la 1a acción (mediana) | F35: Horas al 1er mensaje (mediana) | G35: Ventas | H35: Conversión | I35: % de los leads fuera de horario
A36: Salma | B36: =COUNTIFS(Datos!$R$2:$R$408,"Salma") -> 278 | C36: =IFERROR(B36/COUNT(Datos!$B$2:$B$408),"—") -> 0.68304668 | D36: =IFERROR(COUNTIFS(Datos!$R$2:$R$408,"Salma",Datos!$G$2:$G$408,"Sí")/B36,"—") -> 0.52517986 | E36: {=IFERROR(MEDIAN(IF((Datos!$R$2:$R$408="Salma")*(Datos!$V$2:$V$408<>""),Datos!$V$2:$V$408)),"—")} -> 45.35 | F36: {=IFERROR(MEDIAN(IF((Datos!$R$2:$R$408="Salma")*(Datos!$T$2:$T$408<>""),Datos!$T$2:$T$408))/60,"—")} -> 35.635 | G36: =COUNTIFS(Datos!$R$2:$R$408,"Salma",Datos!$AQ$2:$AQ$408,"Sí") -> 4 | H36: =IFERROR(G36/B36,"—") -> 0.014388489 | I36: =IFERROR(COUNTIFS(Datos!$R$2:$R$408,"Salma",Datos!$F$2:$F$408,"No")/COUNTIFS(Datos!$F$2:$F$408,"No"),"—") -> 0.84313725
A37: Alexander | B37: =COUNTIFS(Datos!$R$2:$R$408,"Alexander") -> 77 | C37: =IFERROR(B37/COUNT(Datos!$B$2:$B$408),"—") -> 0.18918919 | D37: =IFERROR(COUNTIFS(Datos!$R$2:$R$408,"Alexander",Datos!$G$2:$G$408,"Sí")/B37,"—") -> 0.83116883 | E37: {=IFERROR(MEDIAN(IF((Datos!$R$2:$R$408="Alexander")*(Datos!$V$2:$V$408<>""),Datos!$V$2:$V$408)),"—")} -> 1.8 | F37: {=IFERROR(MEDIAN(IF((Datos!$R$2:$R$408="Alexander")*(Datos!$T$2:$T$408<>""),Datos!$T$2:$T$408))/60,"—")} -> 0.33666667 | G37: =COUNTIFS(Datos!$R$2:$R$408,"Alexander",Datos!$AQ$2:$AQ$408,"Sí") -> 2 | H37: =IFERROR(G37/B37,"—") -> 0.025974026 | I37: =IFERROR(COUNTIFS(Datos!$R$2:$R$408,"Alexander",Datos!$F$2:$F$408,"No")/COUNTIFS(Datos!$F$2:$F$408,"No"),"—") -> 0.098039216
A38: Victoria | B38: =COUNTIFS(Datos!$R$2:$R$408,"Victoria") -> 48 | C38: =IFERROR(B38/COUNT(Datos!$B$2:$B$408),"—") -> 0.11793612 | D38: =IFERROR(COUNTIFS(Datos!$R$2:$R$408,"Victoria",Datos!$G$2:$G$408,"Sí")/B38,"—") -> 0.875 | E38: {=IFERROR(MEDIAN(IF((Datos!$R$2:$R$408="Victoria")*(Datos!$V$2:$V$408<>""),Datos!$V$2:$V$408)),"—")} -> 2 | F38: {=IFERROR(MEDIAN(IF((Datos!$R$2:$R$408="Victoria")*(Datos!$T$2:$T$408<>""),Datos!$T$2:$T$408))/60,"—")} -> 0.37833333 | G38: =COUNTIFS(Datos!$R$2:$R$408,"Victoria",Datos!$AQ$2:$AQ$408,"Sí") -> 4 | H38: =IFERROR(G38/B38,"—") -> 0.083333333 | I38: =IFERROR(COUNTIFS(Datos!$R$2:$R$408,"Victoria",Datos!$F$2:$F$408,"No")/COUNTIFS(Datos!$F$2:$F$408,"No"),"—") -> 0.049019608
A39: Sin asignar | B39: =COUNTIFS(Datos!$R$2:$R$408,"Sin asignar") -> 4 | C39: =IFERROR(B39/COUNT(Datos!$B$2:$B$408),"—") -> 0.0098280098 | D39: =IFERROR(COUNTIFS(Datos!$R$2:$R$408,"Sin asignar",Datos!$G$2:$G$408,"Sí")/B39,"—") -> 1 | E39: {=IFERROR(MEDIAN(IF((Datos!$R$2:$R$408="Sin asignar")*(Datos!$V$2:$V$408<>""),Datos!$V$2:$V$408)),"—")} -> 1.3 | F39: {=IFERROR(MEDIAN(IF((Datos!$R$2:$R$408="Sin asignar")*(Datos!$T$2:$T$408<>""),Datos!$T$2:$T$408))/60,"—")} -> 0.42166667 | G39: =COUNTIFS(Datos!$R$2:$R$408,"Sin asignar",Datos!$AQ$2:$AQ$408,"Sí") -> 0 | H39: =IFERROR(G39/B39,"—") -> 0 | I39: =IFERROR(COUNTIFS(Datos!$R$2:$R$408,"Sin asignar",Datos!$F$2:$F$408,"No")/COUNTIFS(Datos!$F$2:$F$408,"No"),"—") -> 0.0098039216
A40: La última columna dice qué parte de los leads que entran fuera de horario queda a nombre de cada asesor.
A41: Asesor = a nombre de quién quedó el lead. Joceline apoya como auxiliar: los leads no quedan a su nombre.
A43: Cómo se cierran los Perdidos
A44: Concepto | B44: Leads | C44: % de los Perdidos | D44: Horas hasta Perdido (mediana)
A45: Los marcó una persona | B45: =COUNTIFS(Datos!$AL$2:$AL$408,"Persona") -> 266 | C45: =IFERROR(B45/COUNTIFS(Datos!$AK$2:$AK$408,"Perdido"),"—") -> 0.97080292 | D45: {=IFERROR(MEDIAN(IF((Datos!$AL$2:$AL$408="Persona")*(Datos!$AN$2:$AN$408<>""),Datos!$AN$2:$AN$408)),"—")} -> 87.4
...

Sheet Datos
A1: Embudo | B1: ID (#) | C1: Entrada | D1: Semana | E1: Hora de entrada | F1: ¿Entró de 9 a 21 h? | G1: ¿Contestó el saludo? | H1: ¿Dio su nombre? | I1: ¿Llegó a 1.1? | J1: Minutos de su respuesta a 1.1 | K1: Lo pasó a 1.1 | L1: ¿Llegó a 1.2? | M1: ¿Contestó la ocupación? | N1: Ocupación | O1: ¿Entró a Negativo? | P1: ¿Llegó a facilidades de pago? | Q1: ¿Llegó a forma de pago? | R1: Asesor asignado | S1: ¿Intervino auxiliar? | T1: Minutos hasta el 1er mensaje de una persona | U1: 1er mensaje de una persona por | V1: Minutos hasta la 1a acción de una persona | W1: Mediana de minutos de respuesta de una persona | X1: Mensajes del lead sin respuesta de una persona | Y1: ¿Audio del equipo? | Z1: ¿Recibió oferta? | AA1: Ofertas recibidas | AB1: Primera oferta enviada por | AC1: Horas hasta la 1a oferta | AD1: Mensajes del lead | AE1: Mensajes del bot | AF1: Mensajes de personas | AG1: ¿Abrió algún link? | AH1: Links abiertos | AI1: Mensajes del bot bloqueados (24 h) | AJ1: Dejó de escribir en | AK1: Estado | AL1: Cómo llegó a Perdido | AM1: Razón de pérdida | AN1: Horas hasta Perdido | AO1: ¿Lo marcaron Perdido alguna vez? | AP1: ¿Escribió después de marcarlo Perdido? | AQ1: ¿Compró? | AR1: Precio de venta | AS1: Estado del cobro | AT1: Horas hasta la venta | AU1: Anuncio (utm_medium)
A2: ISO + Calidad | B2: 263 | C2: 46300.46 | D2: 2026-S41 | E2: 11 | F2: Sí | G2: No | H2: No | I2: No | L2: No | M2: No | O2: No | P2: No | Q2: No | R2: Alexander | S2: No | V2: 1619.3 | X2: 0 | Y2: No | Z2: No | AD2: 1 | AE2: 2 | AF2: 0 | AG2: No | AI2: 0 | AJ2: Solo su primer mensaje | AK2: Perdido | AL2: Persona | AM2: Lo está atendiendo Kommo: desde Kommo le escribieron a este cliente y se apagó | AN2: 27 | AO2: Sí | AP2: No | AQ2: No | AU2: plano
A3: ISO + Calidad | B3: 271 | C3: 46300.494 | D3: 2026-S41 | E3: 11 | F3: Sí | G3: No | H3: No | I3: Sí | K3: Bot | L3: Sí | M3: No | O3: Sí | P3: No | Q3: No | R3: Salma | S3: No | T3: 4649 | U3: Salma | V3: 4649 | X3: 0 | Y3: No | Z3: Sí | AA3: $3,799, $2,799 | AB3: Bot | AC3: 26.6 | AD3: 1 | AE3: 22 | AF3: 1 | AG3: No | AI3: 0 | AJ3: Solo su primer mensaje | AK3: Perdido | AL3: Persona | AM3: No contestaron | AN3: 77.5 | AO3: Sí | AP3: No | AQ3: No | AU3: Plano
A4: ISO + Calidad | B4: 276 | C4: 46300.516 | D4: 2026-S41 | E4: 12 | F4: Sí | G4: Sí | H4: Sí | I4: Sí | J4: 0.3 | K4: Salma | L4: Sí | M4: Sí | N4: Supervisión o jefatura | O4: Sí | P4: Sí | Q4: No | R4: Salma | S4: No | T4: 3.8 | U4: Salma | V4: 0.5 | W4: 0.2 | X4: 0 | Y4: Sí | Z4: Sí | AA4: $3,799, $2,799 | AB4: Bot | AC4: 28.4 | AD4: 5 | AE4: 23 | AF4: 7 | AG4: Sí | AH4: Ruta | AI4: 0 | AJ4: 1.2 Lista de cursos | AK4: Perdido | AL4: Persona | AM4: No contestaron | AN4: 76.6 | AO4: Sí | AP4: No | AQ4: No | AU4: GreenBelt
A5: ISO + Calidad | B5: 277 | C5: 46300.519 | D5: 2026-S41 | E5: 12 | F5: Sí | G5: No | H5: No | I5: Sí | K5: Bot | L5: Sí | M5: Sí | N5: Calidad | O5: Sí | P5: Sí | Q5: No | R5: Alexander | S5: Sí | T5: 106.2 | U5: Alexander | V5: 104.3 | W5: 1.6 | X5: 0 | Y5: Sí | Z5: Sí | AA5: $3,799, $2,799 | AB5: Bot | AC5: 30.2 | AD5: 3 | AE5: 30 | AF5: 4 | AG5: Sí | AH5: Ruta | AI5: 0 | AJ5: 1.2 Lista de cursos | AK5: Perdido | AL5: Persona | AM5: No contestaron | AN5: 72.8 | AO5: Sí | AP5: No | AQ5: No | AU5: 50% Descuento DC-3👉
A6: ISO + Calidad | B6: 278 | C6: 46300.521 | D6: 2026-S41 | E6: 12 | F6: Sí | G6: Sí | H6: Sí | I6: Sí | J6: 0.2 | K6: Joceline | L6: Sí | M6: Sí | N6: Calidad | O6: Sí | P6: Sí | Q6: No | R6: Salma | S6: Sí | T6: 3.9 | U6: Salma | V6: 0.5 | W6: 2 | X6: 0 | Y6: Sí | Z6: Sí | AA6: $3,799, $2,799 | AB6: Bot | AC6: 28.4 | AD6: 5 | AE6: 23 | AF6: 6 | AG6: Sí | AH6: Ruta | AI6: 0 | AJ6: Facilidades de pago | AK6: Perdido | AL6: Persona | AM6: No contestaron | AN6: 76.5 | AO6: Sí | AP6: No | AQ6: No | AU6: PLANO #2
