Workbook

Sheet Resumen
B1: Paso 1.3 · Llamadita y facilidades de pago
B2: ISO + Calidad, Core Tools Premium y Manufactura y Calidad · leads del 5/10/2026 al corte del 27/10/2026 15:00 (hora de Reynosa) · lectura del CRM sin cambios
B5: LO QUE SE ENCONTRÓ
B6: ¿Se hace el paso a 1.3? | C6: ="Sí, en la mayoría de los casos, pero no siempre. De "&TEXT(C23,"#,##0")&" leads que contestaron el área a tiempo, "&TEXT(C25,"#,##0")&" recibieron audio y "&TEXT(C26,"#,##0")&" ("&TEXT(C27,"0%")&") fueron movidos a mano a 1.3."
B7: El detalle | C7: ="Joceline (auxiliar) atendió "&TEXT('Quién lo usa'!C10,"#,##0")&" de esas respuestas y mandó el audio en el "&TEXT('Quién lo usa'!G10,"0%")&", pero solo el "&TEXT('Quién lo usa'!H10,"0%")&" llegó a 1.3, porque otra persona lo movió después. Salma, Ana Victoria y José los mueven entre el "&TEXT(MIN('Quién lo usa'!H7,'Quién lo usa'!H8,'Quién lo usa'!H9),"0%")&" y el "&TEXT(MAX('Quién lo usa'!H7,'Quién lo usa'!H8,'Quién lo usa'!H9),"0%")&"."
B8: Qué les pasa a los que no se mueven | C8: =TEXT(C30,"#,##0")&" leads contestaron a tiempo, no pasaron a 1.3 y a las 2 h el bot les mandó el Negativo. Con 7 días o más, compraron "&TEXT('Funciona 1.3'!F62,"#,##0")&" de "&TEXT('Funciona 1.3'!C62,"#,##0")&" ("&TEXT('Funciona 1.3'!G62,"0.0%")&"), contra "&TEXT('Funciona 1.3'!G60,"0.0%")&" de los movidos a 1.3. Son pocos casos: es una referencia, no un efecto demostrado."
B9: Velocidad | C9: ="Cuando se hace, se hace rápido: la mediana es de "&TEXT(C31,"0")&" minutos entre la respuesta del cliente y el paso a 1.3. Todos los movimientos a 1.3 son manuales."
B10: ¿Funciona 1.3? | C10: ="Sí, cuando el cliente contesta. Respondió en "&TEXT(IF(C32=0,0,C33/C32),"0%")&" de las "&TEXT(C32,"#,##0")&" entradas; de esos, el "&TEXT('Funciona 1.3'!E49,"0%")&" llegó a 1.4 o más, contra el "&TEXT('Funciona 1.3'!E50,"0%")&" de los que no contestaron. A la llamadita responde el "&TEXT(C34,"0%")&" en 30 min y a facilidades de pago el "&TEXT(C35,"0%")&"."
B11: La falla dentro de 1.3 | C11: ="En "&TEXT(C40,"#,##0")&" entradas el cliente respondió en 1.3 (con un sí, una pregunta de costo o pidiendo la llamada más tarde) y a las 4 h el bot lo mandó al Negativo porque nadie lo pasó a 1.4. El bot de 1.3 no se detiene cuando el cliente contesta."
B12: La llamadita | C12: ="Casi nunca se agenda: solo "&TEXT(C41,"#,##0")&" de "&TEXT(C32,"#,##0")&" entradas a 1.3 tuvieron una tarea de llamada."
B14: QUÉ CONVIENE HACER
B15: Esta semana | C15: Que el paso a 1.3 no dependa de la persona. Lo inmediato: que Joceline mueva a 1.3 al mandar el audio. Lo más seguro: que el CRM pase solo a 1.3 a quien contesta la pregunta del área y avise al asesor.
B16: Bot de 1.3 | C16: Que no mande al Negativo a quien respondió dentro de 1.3: que se detenga cuando el cliente contesta o que, en lugar del Negativo, le cree una tarea al asesor.
B17: Prueba "más directo" | C17: Corregir primero el paso manual y usar estas cifras de 1.3 como punto de partida (respuesta a la llamadita y a facilidades, avance a 1.4 y venta), para que la prueba mida el mensaje y no la falla del paso a 1.3.
B20: CIFRAS CLAVE
B21: Indicador | C21: Total | D21: ISO + Calidad | E21: Core Tools | F21: Manufactura
B22: Leads que recibieron la pregunta "¿en qué área trabajas?" | C22: =COUNTA('Base leads'!$A$5:$A$1238) | D22: =COUNTIFS('Base leads'!$B$5:$B$1238,"ISO + Calidad") | E22: =COUNTIFS('Base leads'!$B$5:$B$1238,"Core Tools Premium") | F22: =COUNTIFS('Base leads'!$B$5:$B$1238,"Manufactura y Calidad")
B23: Contestaron a tiempo (antes de que el bot los mandara al Negativo) | C23: =COUNTIFS('Base leads'!$E$5:$E$1238,"A tiempo (en 1.2)") | D23: =COUNTIFS('Base leads'!$B$5:$B$1238,"ISO + Calidad",'Base leads'!$E$5:$E$1238,"A tiempo (en 1.2)") | E23: =COUNTIFS('Base leads'!$B$5:$B$1238,"Core Tools Premium",'Base leads'!$E$5:$E$1238,"A tiempo (en 1.2)") | F23: =COUNTIFS('Base leads'!$B$5:$B$1238,"Manufactura y Calidad",'Base leads'!$E$5:$E$1238,"A tiempo (en 1.2)")
B24: % que contesta a tiempo | C24: =IF(C22=0,0,C23/C22) | D24: =IF(D22=0,0,D23/D22) | E24: =IF(E22=0,0,E23/E22) | F24: =IF(F22=0,0,F23/F22)
B25: De los que contestaron a tiempo: les mandaron audio | C25: =COUNTIFS('Base leads'!$E$5:$E$1238,"A tiempo (en 1.2)",'Base leads'!$K$5:$K$1238,"Sí") | D25: =COUNTIFS('Base leads'!$B$5:$B$1238,"ISO + Calidad",'Base leads'!$E$5:$E$1238,"A tiempo (en 1.2)",'Base leads'!$K$5:$K$1238,"Sí") | E25: =COUNTIFS('Base leads'!$B$5:$B$1238,"Core Tools Premium",'Base leads'!$E$5:$E$1238,"A tiempo (en 1.2)",'Base leads'!$K$5:$K$1238,"Sí") | F25: =COUNTIFS('Base leads'!$B$5:$B$1238,"Manufactura y Calidad",'Base leads'!$E$5:$E$1238,"A tiempo (en 1.2)",'Base leads'!$K$5:$K$1238,"Sí")
B26: De los que contestaron a tiempo: movidos a 1.3 | C26: =COUNTIFS('Base leads'!$E$5:$E$1238,"A tiempo (en 1.2)",'Base leads'!$N$5:$N$1238,"Sí") | D26: =COUNTIFS('Base leads'!$B$5:$B$1238,"ISO + Calidad",'Base leads'!$E$5:$E$1238,"A tiempo (en 1.2)",'Base leads'!$N$5:$N$1238,"Sí") | E26: =COUNTIFS('Base leads'!$B$5:$B$1238,"Core Tools Premium",'Base leads'!$E$5:$E$1238,"A tiempo (en 1.2)",'Base leads'!$N$5:$N$1238,"Sí") | F26: =COUNTIFS('Base leads'!$B$5:$B$1238,"Manufactura y Calidad",'Base leads'!$E$5:$E$1238,"A tiempo (en 1.2)",'Base leads'!$N$5:$N$1238,"Sí")
B27: % movido a 1.3 (de los que contestaron a tiempo) | C27: =IF(C23=0,0,C26/C23) | D27: =IF(D23=0,0,D26/D23) | E27: =IF(E23=0,0,E26/E23) | F27: =IF(F23=0,0,F26/F23)
B28: Contestaron a tiempo, recibieron audio y NO los movieron a 1.3 | C28: =COUNTIFS('Base leads'!$E$5:$E$1238,"A tiempo (en 1.2)",'Base leads'!$R$5:$R$1238,"Audio sin mover a 1.3") | D28: =COUNTIFS('Base leads'!$B$5:$B$1238,"ISO + Calidad",'Base leads'!$E$5:$E$1238,"A tiempo (en 1.2)",'Base leads'!$R$5:$R$1238,"Audio sin mover a 1.3") | E28: =COUNTIFS('Base leads'!$B$5:$B$1238,"Core Tools Premium",'Base leads'!$E$5:$E$1238,"A tiempo (en 1.2)",'Base leads'!$R$5:$R$1238,"Audio sin mover a 1.3") | F28: =COUNTIFS('Base leads'!$B$5:$B$1238,"Manufactura y Calidad",'Base leads'!$E$5:$E$1238,"A tiempo (en 1.2)",'Base leads'!$R$5:$R$1238,"Audio sin mover a 1.3")
B29: Contestaron a tiempo y no recibieron ni audio ni 1.3 | C29: =COUNTIFS('Base leads'!$E$5:$E$1238,"A tiempo (en 1.2)",'Base leads'!$R$5:$R$1238,"Ni audio ni 1.3") | D29: =COUNTIFS('Base leads'!$B$5:$B$1238,"ISO + Calidad",'Base leads'!$E$5:$E$1238,"A tiempo (en 1.2)",'Base leads'!$R$5:$R$1238,"Ni audio ni 1.3") | E29: =COUNTIFS('Base leads'!$B$5:$B$1238,"Core Tools Premium",'Base leads'!$E$5:$E$1238,"A tiempo (en 1.2)",'Base leads'!$R$5:$R$1238,"Ni audio ni 1.3") | F29: =COUNTIFS('Base leads'!$B$5:$B$1238,"Manufactura y Calidad",'Base leads'!$E$5:$E$1238,"A tiempo (en 1.2)",'Base leads'!$R$5:$R$1238,"Ni audio ni 1.3")
B30: Contestaron a tiempo, no los movieron y el bot los mandó al Negativo | C30: =COUNTIFS('Base leads'!$E$5:$E$1238,"A tiempo (en 1.2)",'Base leads'!$S$5:$S$1238,"Negativo (lo mandó el bot)") | D30: =COUNTIFS('Base leads'!$B$5:$B$1238,"ISO + Calidad",'Base leads'!$E$5:$E$1238,"A tiempo (en 1.2)",'Base leads'!$S$5:$S$1238,"Negativo (lo mandó el bot)") | E30: =COUNTIFS('Base leads'!$B$5:$B$1238,"Core Tools Premium",'Base leads'!$E$5:$E$1238,"A tiempo (en 1.2)",'Base leads'!$S$5:$S$1238,"Negativo (lo mandó el bot)") | F30: =COUNTIFS('Base leads'!$B$5:$B$1238,"Manufactura y Calidad",'Base leads'!$E$5:$E$1238,"A tiempo (en 1.2)",'Base leads'!$S$5:$S$1238,"Negativo (lo mandó el bot)")
B31: Minutos de su respuesta a 1.3 (mediana, movidos) | C31: {=MEDIAN(IF(('Base leads'!$E$5:$E$1238="A tiempo (en 1.2)")*('Base leads'!$N$5:$N$1238="Sí"),IF('Base leads'!$P$5:$P$1238<>"",'Base leads'!$P$5:$P$1238)))} | D31: {=MEDIAN(IF(('Base leads'!$E$5:$E$1238="A tiempo (en 1.2)")*('Base leads'!$N$5:$N$1238="Sí")*('Base leads'!$B$5:$B$1238="ISO + Calidad"),IF('Base leads'!$P$5:$P$1238<>"",'Base leads'!$P$5:$P$1238)))} | E31: {=MEDIAN(IF(('Base leads'!$E$5:$E$1238="A tiempo (en 1.2)")*('Base leads'!$N$5:$N$1238="Sí")*('Base leads'!$B$5:$B$1238="Core Tools Premium"),IF('Base leads'!$P$5:$P$1238<>"",'Base leads'!$P$5:$P$1238)))} | F31: {=MEDIAN(IF(('Base leads'!$E$5:$E$1238="A tiempo (en 1.2)")*('Base leads'!$N$5:$N$1238="Sí")*('Base leads'!$B$5:$B$1238="Manufactura y Calidad"),IF('Base leads'!$P$5:$P$1238<>"",'Base leads'!$P$5:$P$1238)))}
B32: Entradas a 1.3 en el periodo | C32: =COUNTA('Entradas a 1.3'!$A$5:$A$360) | D32: =COUNTIFS('Entradas a 1.3'!$B$5:$B$360,"ISO + Calidad") | E32: =COUNTIFS('Entradas a 1.3'!$B$5:$B$360,"Core Tools Premium") | F32: =COUNTIFS('Entradas a 1.3'!$B$5:$B$360,"Manufactura y Calidad")
B33: Entradas a 1.3 en las que el cliente respondió | C33: =COUNTIFS('Entradas a 1.3'!$I$5:$I$360,"Sí") | D33: =COUNTIFS('Entradas a 1.3'!$B$5:$B$360,"ISO + Calidad",'Entradas a 1.3'!$I$5:$I$360,"Sí") | E33: =COUNTIFS('Entradas a 1.3'!$B$5:$B$360,"Core Tools Premium",'Entradas a 1.3'!$I$5:$I$360,"Sí") | F33: =COUNTIFS('Entradas a 1.3'!$B$5:$B$360,"Manufactura y Calidad",'Entradas a 1.3'!$I$5:$I$360,"Sí")
B34: Respuesta en 30 min a la "llamadita" del bot | C34: =IF(COUNTIFS('Entradas a 1.3'!$G$5:$G$360,"Sí")=0,0,COUNTIFS('Entradas a 1.3'!$U$5:$U$360,"Sí")/COUNTIFS('Entradas a 1.3'!$G$5:$G$360,"Sí")) | D34: =IF(COUNTIFS('Entradas a 1.3'!$B$5:$B$360,"ISO + Calidad",'Entradas a 1.3'!$G$5:$G$360,"Sí")=0,0,COUNTIFS('Entradas a 1.3'!$B$5:$B$360,"ISO + Calidad",'Entradas a 1.3'!$U$5:$U$360,"Sí")/COUNTIFS('Entradas a 1.3'!$B$5:$B$360,"ISO + Calidad",'Entradas a 1.3'!$G$5:$G$360,"Sí")) | E34: =IF(COUNTIFS('Entradas a 1.3'!$B$5:$B$360,"Core Tools Premium",'Entradas a 1.3'!$G$5:$G$360,"Sí")=0,0,COUNTIFS('Entradas a 1.3'!$B$5:$B$360,"Core Tools Premium",'Entradas a 1.3'!$U$5:$U$360,"Sí")/COUNTIFS('Entradas a 1.3'!$B$5:$B$360,"Core Tools Premium",'Entradas a 1.3'!$G$5:$G$360,"Sí")) | F34: =IF(COUNTIFS('Entradas a 1.3'!$B$5:$B$360,"Manufactura y Calidad",'Entradas a 1.3'!$G$5:$G$360,"Sí")=0,0,COUNTIFS('Entradas a 1.3'!$B$5:$B$360,"Manufactura y Calidad",'Entradas a 1.3'!$U$5:$U$360,"Sí")/COUNTIFS('Entradas a 1.3'!$B$5:$B$360,"Manufactura y Calidad",'Entradas a 1.3'!$G$5:$G$360,"Sí"))
B35: Respuesta en 30 min a "facilidades de pago" del bot | C35: =IF(COUNTIFS('Entradas a 1.3'!$H$5:$H$360,"Sí")=0,0,COUNTIFS('Entradas a 1.3'!$V$5:$V$360,"Sí")/COUNTIFS('Entradas a 1.3'!$H$5:$H$360,"Sí")) | D35: =IF(COUNTIFS('Entradas a 1.3'!$B$5:$B$360,"ISO + Calidad",'Entradas a 1.3'!$H$5:$H$360,"Sí")=0,0,COUNTIFS('Entradas a 1.3'!$B$5:$B$360,"ISO + Calidad",'Entradas a 1.3'!$V$5:$V$360,"Sí")/COUNTIFS('Entradas a 1.3'!$B$5:$B$360,"ISO + Calidad",'Entradas a 1.3'!$H$5:$H$360,"Sí")) | E35: =IF(COUNTIFS('Entradas a 1.3'!$B$5:$B$360,"Core Tools Premium",'Entradas a 1.3'!$H$5:$H$360,"Sí")=0,0,COUNTIFS('Entradas a 1.3'!$B$5:$B$360,"Core Tools Premium",'Entradas a 1.3'!$V$5:$V$360,"Sí")/COUNTIFS('Entradas a 1.3'!$B$5:$B$360,"Core Tools Premium",'Entradas a 1.3'!$H$5:$H$360,"Sí")) | F35: =IF(COUNTIFS('Entradas a 1.3'!$B$5:$B$360,"Manufactura y Calidad",'Entradas a 1.3'!$H$5:$H$360,"Sí")=0,0,COUNTIFS('Entradas a 1.3'!$B$5:$B$360,"Manufactura y Calidad",'Entradas a 1.3'!$V$5:$V$360,"Sí")/COUNTIFS('Entradas a 1.3'!$B$5:$B$360,"Manufactura y Calidad",'Entradas a 1.3'!$H$5:$H$360,"Sí"))
B36: Entradas a 1.3 que después llegaron a 1.4 o más | C36: =COUNTIFS('Entradas a 1.3'!$P$5:$P$360,"Sí") | D36: =COUNTIFS('Entradas a 1.3'!$B$5:$B$360,"ISO + Calidad",'Entradas a 1.3'!$P$5:$P$360,"Sí") | E36: =COUNTIFS('Entradas a 1.3'!$B$5:$B$360,"Core Tools Premium",'Entradas a 1.3'!$P$5:$P$360,"Sí") | F36: =COUNTIFS('Entradas a 1.3'!$B$5:$B$360,"Manufactura y Calidad",'Entradas a 1.3'!$P$5:$P$360,"Sí")
B37: % de entradas a 1.3 que llega a 1.4 o más | C37: =IF(C32=0,0,C36/C32) | D37: =IF(D32=0,0,D36/D32) | E37: =IF(E32=0,0,E36/E32) | F37: =IF(F32=0,0,F36/F32)
B38: Entradas a 1.3 que terminaron en Ganado | C38: =COUNTIFS('Entradas a 1.3'!$R$5:$R$360,"Sí") | D38: =COUNTIFS('Entradas a 1.3'!$B$5:$B$360,"ISO + Calidad",'Entradas a 1.3'!$R$5:$R$360,"Sí") | E38: =COUNTIFS('Entradas a 1.3'!$B$5:$B$360,"Core Tools Premium",'Entradas a 1.3'!$R$5:$R$360,"Sí") | F38: =COUNTIFS('Entradas a 1.3'!$B$5:$B$360,"Manufactura y Calidad",'Entradas a 1.3'!$R$5:$R$360,"Sí")
B39: Salieron de 1.3 al Negativo por el bot | C39: =COUNTIFS('Entradas a 1.3'!$M$5:$M$360,"Negativo",'Entradas a 1.3'!$N$5:$N$360,"Bot de 1.3") | D39: =COUNTIFS('Entradas a 1.3'!$B$5:$B$360,"ISO + Calidad",'Entradas a 1.3'!$M$5:$M$360,"Negativo",'Entradas a 1.3'!$N$5:$N$360,"Bot de 1.3") | E39: =COUNTIFS('Entradas a 1.3'!$B$5:$B$360,"Core Tools Premium",'Entradas a 1.3'!$M$5:$M$360,"Negativo",'Entradas a 1.3'!$N$5:$N$360,"Bot de 1.3") | F39: =COUNTIFS('Entradas a 1.3'!$B$5:$B$360,"Manufactura y Calidad",'Entradas a 1.3'!$M$5:$M$360,"Negativo",'Entradas a 1.3'!$N$5:$N$360,"Bot de 1.3")
B40: El cliente respondió en 1.3 y aun así el bot lo mandó al Negativo | C40: =COUNTIFS('Entradas a 1.3'!$S$5:$S$360,"Sí") | D40: =COUNTIFS('Entradas a 1.3'!$B$5:$B$360,"ISO + Calidad",'Entradas a 1.3'!$S$5:$S$360,"Sí") | E40: =COUNTIFS('Entradas a 1.3'!$B$5:$B$360,"Core Tools Premium",'Entradas a 1.3'!$S$5:$S$360,"Sí") | F40: =COUNTIFS('Entradas a 1.3'!$B$5:$B$360,"Manufactura y Calidad",'Entradas a 1.3'!$S$5:$S$360,"Sí")
B41: Entradas a 1.3 con tarea de llamada creada | C41: =COUNTIFS('Entradas a 1.3'!$L$5:$L$360,"Sí") | D41: =COUNTIFS('Entradas a 1.3'!$B$5:$B$360,"ISO + Calidad",'Entradas a 1.3'!$L$5:$L$360,"Sí") | E41: =COUNTIFS('Entradas a 1.3'!$B$5:$B$360,"Core Tools Premium",'Entradas a 1.3'!$L$5:$L$360,"Sí") | F41: =COUNTIFS('Entradas a 1.3'!$B$5:$B$360,"Manufactura y Calidad",'Entradas a 1.3'!$L$5:$L$360,"Sí")
B43: Cada cifra es una fórmula sobre las hojas "Base leads" y "Entradas a 1.3". El método y las definiciones están en "Fuentes y método".

Sheet Tras la pregunta del área
B1: Qué pasa cuando el lead contesta el área
B2: Leads que contestaron "¿en qué área trabajas?" antes de que el bot los mandara al Negativo (2 h)
B5: LO QUE HIZO EL EQUIPO DESPUÉS DE SU RESPUESTA
B6: Qué hicieron | C6: Total | D6: ISO + Calidad | E6: Core Tools | F6: Manufactura | G6: % del total
B7: Audio y después 1.3 | C7: =COUNTIFS('Base leads'!$E$5:$E$1238,"A tiempo (en 1.2)",'Base leads'!$R$5:$R$1238,"Audio y después 1.3") | D7: =COUNTIFS('Base leads'!$B$5:$B$1238,"ISO + Calidad",'Base leads'!$E$5:$E$1238,"A tiempo (en 1.2)",'Base leads'!$R$5:$R$1238,"Audio y después 1.3") | E7: =COUNTIFS('Base leads'!$B$5:$B$1238,"Core Tools Premium",'Base leads'!$E$5:$E$1238,"A tiempo (en 1.2)",'Base leads'!$R$5:$R$1238,"Audio y después 1.3") | F7: =COUNTIFS('Base leads'!$B$5:$B$1238,"Manufactura y Calidad",'Base leads'!$E$5:$E$1238,"A tiempo (en 1.2)",'Base leads'!$R$5:$R$1238,"Audio y después 1.3") | G7: =IF(C$12=0,0,C7/C$12)
B8: 1.3 y después audio | C8: =COUNTIFS('Base leads'!$E$5:$E$1238,"A tiempo (en 1.2)",'Base leads'!$R$5:$R$1238,"1.3 y después audio") | D8: =COUNTIFS('Base leads'!$B$5:$B$1238,"ISO + Calidad",'Base leads'!$E$5:$E$1238,"A tiempo (en 1.2)",'Base leads'!$R$5:$R$1238,"1.3 y después audio") | E8: =COUNTIFS('Base leads'!$B$5:$B$1238,"Core Tools Premium",'Base leads'!$E$5:$E$1238,"A tiempo (en 1.2)",'Base leads'!$R$5:$R$1238,"1.3 y después audio") | F8: =COUNTIFS('Base leads'!$B$5:$B$1238,"Manufactura y Calidad",'Base leads'!$E$5:$E$1238,"A tiempo (en 1.2)",'Base leads'!$R$5:$R$1238,"1.3 y después audio") | G8: =IF(C$12=0,0,C8/C$12)
B9: Movido a 1.3 sin audio | C9: =COUNTIFS('Base leads'!$E$5:$E$1238,"A tiempo (en 1.2)",'Base leads'!$R$5:$R$1238,"Movido a 1.3 sin audio") | D9: =COUNTIFS('Base leads'!$B$5:$B$1238,"ISO + Calidad",'Base leads'!$E$5:$E$1238,"A tiempo (en 1.2)",'Base leads'!$R$5:$R$1238,"Movido a 1.3 sin audio") | E9: =COUNTIFS('Base leads'!$B$5:$B$1238,"Core Tools Premium",'Base leads'!$E$5:$E$1238,"A tiempo (en 1.2)",'Base leads'!$R$5:$R$1238,"Movido a 1.3 sin audio") | F9: =COUNTIFS('Base leads'!$B$5:$B$1238,"Manufactura y Calidad",'Base leads'!$E$5:$E$1238,"A tiempo (en 1.2)",'Base leads'!$R$5:$R$1238,"Movido a 1.3 sin audio") | G9: =IF(C$12=0,0,C9/C$12)
B10: Audio sin mover a 1.3 | C10: =COUNTIFS('Base leads'!$E$5:$E$1238,"A tiempo (en 1.2)",'Base leads'!$R$5:$R$1238,"Audio sin mover a 1.3") | D10: =COUNTIFS('Base leads'!$B$5:$B$1238,"ISO + Calidad",'Base leads'!$E$5:$E$1238,"A tiempo (en 1.2)",'Base leads'!$R$5:$R$1238,"Audio sin mover a 1.3") | E10: =COUNTIFS('Base leads'!$B$5:$B$1238,"Core Tools Premium",'Base leads'!$E$5:$E$1238,"A tiempo (en 1.2)",'Base leads'!$R$5:$R$1238,"Audio sin mover a 1.3") | F10: =COUNTIFS('Base leads'!$B$5:$B$1238,"Manufactura y Calidad",'Base leads'!$E$5:$E$1238,"A tiempo (en 1.2)",'Base leads'!$R$5:$R$1238,"Audio sin mover a 1.3") | G10: =IF(C$12=0,0,C10/C$12)
B11: Ni audio ni 1.3 | C11: =COUNTIFS('Base leads'!$E$5:$E$1238,"A tiempo (en 1.2)",'Base leads'!$R$5:$R$1238,"Ni audio ni 1.3") | D11: =COUNTIFS('Base leads'!$B$5:$B$1238,"ISO + Calidad",'Base leads'!$E$5:$E$1238,"A tiempo (en 1.2)",'Base leads'!$R$5:$R$1238,"Ni audio ni 1.3") | E11: =COUNTIFS('Base leads'!$B$5:$B$1238,"Core Tools Premium",'Base leads'!$E$5:$E$1238,"A tiempo (en 1.2)",'Base leads'!$R$5:$R$1238,"Ni audio ni 1.3") | F11: =COUNTIFS('Base leads'!$B$5:$B$1238,"Manufactura y Calidad",'Base leads'!$E$5:$E$1238,"A tiempo (en 1.2)",'Base leads'!$R$5:$R$1238,"Ni audio ni 1.3") | G11: =IF(C$12=0,0,C11/C$12)
B12: Total que contestó a tiempo | C12: =SUM(C7:C11) | D12: =SUM(D7:D11) | E12: =SUM(E7:E11) | F12: =SUM(F7:F11) | G12: =IF(C12=0,0,C12/C12)
B14: El protocolo esperado es: plantilla "Excelente… te mando un audio rapidito", nota de voz con la recomendación y mover a mano a 1.3.
B16: TIEMPOS (MEDIANA EN MINUTOS DESDE SU RESPUESTA)
B17: Paso | C17: Total | D17: ISO + Calidad | E17: Core Tools | F17: Manufactura
B18: Primera respuesta de una persona | C18: {=MEDIAN(IF(('Base leads'!$E$5:$E$1238="A tiempo (en 1.2)"),IF('Base leads'!$I$5:$I$1238<>"",'Base leads'!$I$5:$I$1238)))} | D18: {=MEDIAN(IF(('Base leads'!$E$5:$E$1238="A tiempo (en 1.2)")*('Base leads'!$B$5:$B$1238="ISO + Calidad"),IF('Base leads'!$I$5:$I$1238<>"",'Base leads'!$I$5:$I$1238)))} | E18: {=MEDIAN(IF(('Base leads'!$E$5:$E$1238="A tiempo (en 1.2)")*('Base leads'!$B$5:$B$1238="Core Tools Premium"),IF('Base leads'!$I$5:$I$1238<>"",'Base leads'!$I$5:$I$1238)))} | F18: {=MEDIAN(IF(('Base leads'!$E$5:$E$1238="A tiempo (en 1.2)")*('Base leads'!$B$5:$B$1238="Manufactura y Calidad"),IF('Base leads'!$I$5:$I$1238<>"",'Base leads'!$I$5:$I$1238)))}
B19: Audio | C19: {=MEDIAN(IF(('Base leads'!$E$5:$E$1238="A tiempo (en 1.2)")*('Base leads'!$K$5:$K$1238="Sí"),IF('Base leads'!$M$5:$M$1238<>"",'Base leads'!$M$5:$M$1238)))} | D19: {=MEDIAN(IF(('Base leads'!$E$5:$E$1238="A tiempo (en 1.2)")*('Base leads'!$K$5:$K$1238="Sí")*('Base leads'!$B$5:$B$1238="ISO + Calidad"),IF('Base leads'!$M$5:$M$1238<>"",'Base leads'!$M$5:$M$1238)))} | E19: {=MEDIAN(IF(('Base leads'!$E$5:$E$1238="A tiempo (en 1.2)")*('Base leads'!$K$5:$K$1238="Sí")*('Base leads'!$B$5:$B$1238="Core Tools Premium"),IF('Base leads'!$M$5:$M$1238<>"",'Base leads'!$M$5:$M$1238)))} | F19: {=MEDIAN(IF(('Base leads'!$E$5:$E$1238="A tiempo (en 1.2)")*('Base leads'!$K$5:$K$1238="Sí")*('Base leads'!$B$5:$B$1238="Manufactura y Calidad"),IF('Base leads'!$M$5:$M$1238<>"",'Base leads'!$M$5:$M$1238)))}
B20: Movido a 1.3 | C20: {=MEDIAN(IF(('Base leads'!$E$5:$E$1238="A tiempo (en 1.2)")*('Base leads'!$N$5:$N$1238="Sí"),IF('Base leads'!$P$5:$P$1238<>"",'Base leads'!$P$5:$P$1238)))} | D20: {=MEDIAN(IF(('Base leads'!$E$5:$E$1238="A tiempo (en 1.2)")*('Base leads'!$N$5:$N$1238="Sí")*('Base leads'!$B$5:$B$1238="ISO + Calidad"),IF('Base leads'!$P$5:$P$1238<>"",'Base leads'!$P$5:$P$1238)))} | E20: {=MEDIAN(IF(('Base leads'!$E$5:$E$1238="A tiempo (en 1.2)")*('Base leads'!$N$5:$N$1238="Sí")*('Base leads'!$B$5:$B$1238="Core Tools Premium"),IF('Base leads'!$P$5:$P$1238<>"",'Base leads'!$P$5:$P$1238)))} | F20: {=MEDIAN(IF(('Base leads'!$E$5:$E$1238="A tiempo (en 1.2)")*('Base leads'!$N$5:$N$1238="Sí")*('Base leads'!$B$5:$B$1238="Manufactura y Calidad"),IF('Base leads'!$P$5:$P$1238<>"",'Base leads'!$P$5:$P$1238)))}
B22: LOS QUE NO MOVIERON A 1.3: A DÓNDE FUERON
B23: Destino | C23: Total | D23: ISO + Calidad | E23: Core Tools | F23: Manufactura | G23: Preguntaron precio o pago
B24: Negativo (lo mandó el bot) | C24: =COUNTIFS('Base leads'!$E$5:$E$1238,"A tiempo (en 1.2)",'Base leads'!$S$5:$S$1238,"Negativo (lo mandó el bot)") | D24: =COUNTIFS('Base leads'!$B$5:$B$1238,"ISO + Calidad",'Base leads'!$E$5:$E$1238,"A tiempo (en 1.2)",'Base leads'!$S$5:$S$1238,"Negativo (lo mandó el bot)") | E24: =COUNTIFS('Base leads'!$B$5:$B$1238,"Core Tools Premium",'Base leads'!$E$5:$E$1238,"A tiempo (en 1.2)",'Base leads'!$S$5:$S$1238,"Negativo (lo mandó el bot)") | F24: =COUNTIFS('Base leads'!$B$5:$B$1238,"Manufactura y Calidad",'Base leads'!$E$5:$E$1238,"A tiempo (en 1.2)",'Base leads'!$S$5:$S$1238,"Negativo (lo mandó el bot)") | G24: =COUNTIFS('Base leads'!$E$5:$E$1238,"A tiempo (en 1.2)",'Base leads'!$S$5:$S$1238,"Negativo (lo mandó el bot)",'Base leads'!$G$5:$G$1238,"Sí")
B25: Perdido (persona) | C25: =COUNTIFS('Base leads'!$E$5:$E$1238,"A tiempo (en 1.2)",'Base leads'!$S$5:$S$1238,"Perdido (persona)") | D25: =COUNTIFS('Base leads'!$B$5:$B$1238,"ISO + Calidad",'Base leads'!$E$5:$E$1238,"A tiempo (en 1.2)",'Base leads'!$S$5:$S$1238,"Perdido (persona)") | E25: =COUNTIFS('Base leads'!$B$5:$B$1238,"Core Tools Premium",'Base leads'!$E$5:$E$1238,"A tiempo (en 1.2)",'Base leads'!$S$5:$S$1238,"Perdido (persona)") | F25: =COUNTIFS('Base leads'!$B$5:$B$1238,"Manufactura y Calidad",'Base leads'!$E$5:$E$1238,"A tiempo (en 1.2)",'Base leads'!$S$5:$S$1238,"Perdido (persona)") | G25: =COUNTIFS('Base leads'!$E$5:$E$1238,"A tiempo (en 1.2)",'Base leads'!$S$5:$S$1238,"Perdido (persona)",'Base leads'!$G$5:$G$1238,"Sí")
B26: 1.4, pago o Ganado (persona) | C26: =COUNTIFS('Base leads'!$E$5:$E$1238,"A tiempo (en 1.2)",'Base leads'!$S$5:$S$1238,"1.4, pago o Ganado (persona)") | D26: =COUNTIFS('Base leads'!$B$5:$B$1238,"ISO + Calidad",'Base leads'!$E$5:$E$1238,"A tiempo (en 1.2)",'Base leads'!$S$5:$S$1238,"1.4, pago o Ganado (persona)") | E26: =COUNTIFS('Base leads'!$B$5:$B$1238,"Core Tools Premium",'Base leads'!$E$5:$E$1238,"A tiempo (en 1.2)",'Base leads'!$S$5:$S$1238,"1.4, pago o Ganado (persona)") | F26: =COUNTIFS('Base leads'!$B$5:$B$1238,"Manufactura y Calidad",'Base leads'!$E$5:$E$1238,"A tiempo (en 1.2)",'Base leads'!$S$5:$S$1238,"1.4, pago o Ganado (persona)") | G26: =COUNTIFS('Base leads'!$E$5:$E$1238,"A tiempo (en 1.2)",'Base leads'!$S$5:$S$1238,"1.4, pago o Ganado (persona)",'Base leads'!$G$5:$G$1238,"Sí")
B27: Negativo (lo movió una persona) | C27: =COUNTIFS('Base leads'!$E$5:$E$1238,"A tiempo (en 1.2)",'Base leads'!$S$5:$S$1238,"Negativo (lo movió una persona)") | D27: =COUNTIFS('Base leads'!$B$5:$B$1238,"ISO + Calidad",'Base leads'!$E$5:$E$1238,"A tiempo (en 1.2)",'Base leads'!$S$5:$S$1238,"Negativo (lo movió una persona)") | E27: =COUNTIFS('Base leads'!$B$5:$B$1238,"Core Tools Premium",'Base leads'!$E$5:$E$1238,"A tiempo (en 1.2)",'Base leads'!$S$5:$S$1238,"Negativo (lo movió una persona)") | F27: =COUNTIFS('Base leads'!$B$5:$B$1238,"Manufactura y Calidad",'Base leads'!$E$5:$E$1238,"A tiempo (en 1.2)",'Base leads'!$S$5:$S$1238,"Negativo (lo movió una persona)") | G27: =COUNTIFS('Base leads'!$E$5:$E$1238,"A tiempo (en 1.2)",'Base leads'!$S$5:$S$1238,"Negativo (lo movió una persona)",'Base leads'!$G$5:$G$1238,"Sí")
B28: Sigue en 1.2 | C28: =COUNTIFS('Base leads'!$E$5:$E$1238,"A tiempo (en 1.2)",'Base leads'!$S$5:$S$1238,"Sigue en 1.2") | D28: =COUNTIFS('Base leads'!$B$5:$B$1238,"ISO + Calidad",'Base leads'!$E$5:$E$1238,"A tiempo (en 1.2)",'Base leads'!$S$5:$S$1238,"Sigue en 1.2") | E28: =COUNTIFS('Base leads'!$B$5:$B$1238,"Core Tools Premium",'Base leads'!$E$5:$E$1238,"A tiempo (en 1.2)",'Base leads'!$S$5:$S$1238,"Sigue en 1.2") | F28: =COUNTIFS('Base leads'!$B$5:$B$1238,"Manufactura y Calidad",'Base leads'!$E$5:$E$1238,"A tiempo (en 1.2)",'Base leads'!$S$5:$S$1238,"Sigue en 1.2") | G28: =COUNTIFS('Base leads'!$E$5:$E$1238,"A tiempo (en 1.2)",'Base leads'!$S$5:$S$1238,"Sigue en 1.2",'Base leads'!$G$5:$G$1238,"Sí")
B30: SEGÚN LA HORA EN QUE CONTESTÓ (HORA DE REYNOSA)
B31: Franja | C31: Contestaron a tiempo | D31: Con audio | E31: Movidos a 1.3 | F31: % movidos | G31: Min. a 1.3 (mediana)
B32: 9 a 18 h | C32: =COUNTIFS('Base leads'!$E$5:$E$1238,"A tiempo (en 1.2)",'Base leads'!$T$5:$T$1238,"9 a 18 h") | D32: =COUNTIFS('Base leads'!$E$5:$E$1238,"A tiempo (en 1.2)",'Base leads'!$T$5:$T$1238,"9 a 18 h",'Base leads'!$K$5:$K$1238,"Sí") | E32: =COUNTIFS('Base leads'!$E$5:$E$1238,"A tiempo (en 1.2)",'Base leads'!$T$5:$T$1238,"9 a 18 h",'Base leads'!$N$5:$N$1238,"Sí") | F32: =IF(C32=0,0,E32/C32) | G32: {=MEDIAN(IF(('Base leads'!$E$5:$E$1238="A tiempo (en 1.2)")*('Base leads'!$N$5:$N$1238="Sí")*('Base leads'!$T$5:$T$1238="9 a 18 h"),IF('Base leads'!$P$5:$P$1238<>"",'Base leads'!$P$5:$P$1238)))}
B33: 18 a 22 h | C33: =COUNTIFS('Base leads'!$E$5:$E$1238,"A tiempo (en 1.2)",'Base leads'!$T$5:$T$1238,"18 a 22 h") | D33: =COUNTIFS('Base leads'!$E$5:$E$1238,"A tiempo (en 1.2)",'Base leads'!$T$5:$T$1238,"18 a 22 h",'Base leads'!$K$5:$K$1238,"Sí") | E33: =COUNTIFS('Base leads'!$E$5:$E$1238,"A tiempo (en 1.2)",'Base leads'!$T$5:$T$1238,"18 a 22 h",'Base leads'!$N$5:$N$1238,"Sí") | F33: =IF(C33=0,0,E33/C33) | G33: {=MEDIAN(IF(('Base leads'!$E$5:$E$1238="A tiempo (en 1.2)")*('Base leads'!$N$5:$N$1238="Sí")*('Base leads'!$T$5:$T$1238="18 a 22 h"),IF('Base leads'!$P$5:$P$1238<>"",'Base leads'!$P$5:$P$1238)))}
B34: 22 a 9 h | C34: =COUNTIFS('Base leads'!$E$5:$E$1238,"A tiempo (en 1.2)",'Base leads'!$T$5:$T$1238,"22 a 9 h") | D34: =COUNTIFS('Base leads'!$E$5:$E$1238,"A tiempo (en 1.2)",'Base leads'!$T$5:$T$1238,"22 a 9 h",'Base leads'!$K$5:$K$1238,"Sí") | E34: =COUNTIFS('Base leads'!$E$5:$E$1238,"A tiempo (en 1.2)",'Base leads'!$T$5:$T$1238,"22 a 9 h",'Base leads'!$N$5:$N$1238,"Sí") | F34: =IF(C34=0,0,E34/C34) | G34: {=MEDIAN(IF(('Base leads'!$E$5:$E$1238="A tiempo (en 1.2)")*('Base leads'!$N$5:$N$1238="Sí")*('Base leads'!$T$5:$T$1238="22 a 9 h"),IF('Base leads'!$P$5:$P$1238<>"",'Base leads'!$P$5:$P$1238)))}
B36: LOS QUE CONTESTARON TARDE (YA ESTABAN EN EL NEGATIVO)
B37: Indicador | C37: Total | D37: ISO + Calidad | E37: Core Tools | F37: Manufactura
B38: Contestaron tarde | C38: =COUNTIFS('Base leads'!$E$5:$E$1238,"Tarde (ya fuera de 1.2)") | D38: =COUNTIFS('Base leads'!$B$5:$B$1238,"ISO + Calidad",'Base leads'!$E$5:$E$1238,"Tarde (ya fuera de 1.2)") | E38: =COUNTIFS('Base leads'!$B$5:$B$1238,"Core Tools Premium",'Base leads'!$E$5:$E$1238,"Tarde (ya fuera de 1.2)") | F38: =COUNTIFS('Base leads'!$B$5:$B$1238,"Manufactura y Calidad",'Base leads'!$E$5:$E$1238,"Tarde (ya fuera de 1.2)")
B39: Les mandaron audio | C39: =COUNTIFS('Base leads'!$E$5:$E$1238,"Tarde (ya fuera de 1.2)",'Base leads'!$K$5:$K$1238,"Sí") | D39: =COUNTIFS('Base leads'!$B$5:$B$1238,"ISO + Calidad",'Base leads'!$E$5:$E$1238,"Tarde (ya fuera de 1.2)",'Base leads'!$K$5:$K$1238,"Sí") | E39: =COUNTIFS('Base leads'!$B$5:$B$1238,"Core Tools Premium",'Base leads'!$E$5:$E$1238,"Tarde (ya fuera de 1.2)",'Base leads'!$K$5:$K$1238,"Sí") | F39: =COUNTIFS('Base leads'!$B$5:$B$1238,"Manufactura y Calidad",'Base leads'!$E$5:$E$1238,"Tarde (ya fuera de 1.2)",'Base leads'!$K$5:$K$1238,"Sí")
B40: Los movieron a 1.3 | C40: =COUNTIFS('Base leads'!$E$5:$E$1238,"Tarde (ya fuera de 1.2)",'Base leads'!$N$5:$N$1238,"Sí") | D40: =COUNTIFS('Base leads'!$B$5:$B$1238,"ISO + Calidad",'Base leads'!$E$5:$E$1238,"Tarde (ya fuera de 1.2)",'Base leads'!$N$5:$N$1238,"Sí") | E40: =COUNTIFS('Base leads'!$B$5:$B$1238,"Core Tools Premium",'Base leads'!$E$5:$E$1238,"Tarde (ya fuera de 1.2)",'Base leads'!$N$5:$N$1238,"Sí") | F40: =COUNTIFS('Base leads'!$B$5:$B$1238,"Manufactura y Calidad",'Base leads'!$E$5:$E$1238,"Tarde (ya fuera de 1.2)",'Base leads'!$N$5:$N$1238,"Sí")

Sheet Quién lo usa
B1: Quién hace el paso a 1.3
B2: Por la primera persona del equipo que le contestó al lead después de su respuesta al área (contestaron a tiempo)
B5: POR PERSONA QUE ATENDIÓ LA RESPUESTA
B6: Persona | C6: Respuestas que atendió | D6: Usó la plantilla del audio | E6: Mandó audio (cualquiera) | F6: Movidos a 1.3 | G6: % con audio | H6: % movidos a 1.3 | I6: Min. a la 1ª respuesta (mediana)
B7: Salma Santos Hernández | C7: =COUNTIFS('Base leads'!$E$5:$E$1238,"A tiempo (en 1.2)",'Base leads'!$H$5:$H$1238,"Salma Santos Hernández") | D7: =COUNTIFS('Base leads'!$E$5:$E$1238,"A tiempo (en 1.2)",'Base leads'!$H$5:$H$1238,"Salma Santos Hernández",'Base leads'!$J$5:$J$1238,"Sí") | E7: =COUNTIFS('Base leads'!$E$5:$E$1238,"A tiempo (en 1.2)",'Base leads'!$H$5:$H$1238,"Salma Santos Hernández",'Base leads'!$K$5:$K$1238,"Sí") | F7: =COUNTIFS('Base leads'!$E$5:$E$1238,"A tiempo (en 1.2)",'Base leads'!$H$5:$H$1238,"Salma Santos Hernández",'Base leads'!$N$5:$N$1238,"Sí") | G7: =IF(C7=0,0,E7/C7) | H7: =IF(C7=0,0,F7/C7) | I7: {=MEDIAN(IF(('Base leads'!$E$5:$E$1238="A tiempo (en 1.2)")*('Base leads'!$H$5:$H$1238="Salma Santos Hernández"),IF('Base leads'!$I$5:$I$1238<>"",'Base leads'!$I$5:$I$1238)))}
B8: José Alexander Morales | C8: =COUNTIFS('Base leads'!$E$5:$E$1238,"A tiempo (en 1.2)",'Base leads'!$H$5:$H$1238,"José Alexander Morales") | D8: =COUNTIFS('Base leads'!$E$5:$E$1238,"A tiempo (en 1.2)",'Base leads'!$H$5:$H$1238,"José Alexander Morales",'Base leads'!$J$5:$J$1238,"Sí") | E8: =COUNTIFS('Base leads'!$E$5:$E$1238,"A tiempo (en 1.2)",'Base leads'!$H$5:$H$1238,"José Alexander Morales",'Base leads'!$K$5:$K$1238,"Sí") | F8: =COUNTIFS('Base leads'!$E$5:$E$1238,"A tiempo (en 1.2)",'Base leads'!$H$5:$H$1238,"José Alexander Morales",'Base leads'!$N$5:$N$1238,"Sí") | G8: =IF(C8=0,0,E8/C8) | H8: =IF(C8=0,0,F8/C8) | I8: {=MEDIAN(IF(('Base leads'!$E$5:$E$1238="A tiempo (en 1.2)")*('Base leads'!$H$5:$H$1238="José Alexander Morales"),IF('Base leads'!$I$5:$I$1238<>"",'Base leads'!$I$5:$I$1238)))}
B9: Ana Victoria de Leon | C9: =COUNTIFS('Base leads'!$E$5:$E$1238,"A tiempo (en 1.2)",'Base leads'!$H$5:$H$1238,"Ana Victoria de Leon") | D9: =COUNTIFS('Base leads'!$E$5:$E$1238,"A tiempo (en 1.2)",'Base leads'!$H$5:$H$1238,"Ana Victoria de Leon",'Base leads'!$J$5:$J$1238,"Sí") | E9: =COUNTIFS('Base leads'!$E$5:$E$1238,"A tiempo (en 1.2)",'Base leads'!$H$5:$H$1238,"Ana Victoria de Leon",'Base leads'!$K$5:$K$1238,"Sí") | F9: =COUNTIFS('Base leads'!$E$5:$E$1238,"A tiempo (en 1.2)",'Base leads'!$H$5:$H$1238,"Ana Victoria de Leon",'Base leads'!$N$5:$N$1238,"Sí") | G9: =IF(C9=0,0,E9/C9) | H9: =IF(C9=0,0,F9/C9) | I9: {=MEDIAN(IF(('Base leads'!$E$5:$E$1238="A tiempo (en 1.2)")*('Base leads'!$H$5:$H$1238="Ana Victoria de Leon"),IF('Base leads'!$I$5:$I$1238<>"",'Base leads'!$I$5:$I$1238)))}
B10: Joceline Sarahi Benavides Serrano | C10: =COUNTIFS('Base leads'!$E$5:$E$1238,"A tiempo (en 1.2)",'Base leads'!$H$5:$H$1238,"Joceline Sarahi Benavides Serrano") | D10: =COUNTIFS('Base leads'!$E$5:$E$1238,"A tiempo (en 1.2)",'Base leads'!$H$5:$H$1238,"Joceline Sarahi Benavides Serrano",'Base leads'!$J$5:$J$1238,"Sí") | E10: =COUNTIFS('Base leads'!$E$5:$E$1238,"A tiempo (en 1.2)",'Base leads'!$H$5:$H$1238,"Joceline Sarahi Benavides Serrano",'Base leads'!$K$5:$K$1238,"Sí") | F10: =COUNTIFS('Base leads'!$E$5:$E$1238,"A tiempo (en 1.2)",'Base leads'!$H$5:$H$1238,"Joceline Sarahi Benavides Serrano",'Base leads'!$N$5:$N$1238,"Sí") | G10: =IF(C10=0,0,E10/C10) | H10: =IF(C10=0,0,F10/C10) | I10: {=MEDIAN(IF(('Base leads'!$E$5:$E$1238="A tiempo (en 1.2)")*('Base leads'!$H$5:$H$1238="Joceline Sarahi Benavides Serrano"),IF('Base leads'!$I$5:$I$1238<>"",'Base leads'!$I$5:$I$1238)))}
B12: El CRM le permite a la auxiliar mover etapas: en el mismo periodo movió leads a Perdido, a 1.1 Informes y a Ganado, pero ninguno a 1.3.
B14: QUIÉN MUEVE A 1.3 (TODAS LAS ENTRADAS A 1.3)
B15: Persona | C15: Entradas a 1.3 | D15: Desde 1.2 | E15: Desde el Negativo | F15: Llegaron a 1.4 o más | G15: % a 1.4 o más | H15: Ganado
B16: Salma Santos Hernández | C16: =COUNTIFS('Entradas a 1.3'!$F$5:$F$360,"Salma Santos Hernández") | D16: =COUNTIFS('Entradas a 1.3'!$F$5:$F$360,"Salma Santos Hernández",'Entradas a 1.3'!$E$5:$E$360,"1.2 Lista de cursos") | E16: =COUNTIFS('Entradas a 1.3'!$F$5:$F$360,"Salma Santos Hernández",'Entradas a 1.3'!$E$5:$E$360,"Negativo") | F16: =COUNTIFS('Entradas a 1.3'!$F$5:$F$360,"Salma Santos Hernández",'Entradas a 1.3'!$P$5:$P$360,"Sí") | G16: =IF(C16=0,0,F16/C16) | H16: =COUNTIFS('Entradas a 1.3'!$F$5:$F$360,"Salma Santos Hernández",'Entradas a 1.3'!$R$5:$R$360,"Sí")
B17: José Alexander Morales | C17: =COUNTIFS('Entradas a 1.3'!$F$5:$F$360,"José Alexander Morales") | D17: =COUNTIFS('Entradas a 1.3'!$F$5:$F$360,"José Alexander Morales",'Entradas a 1.3'!$E$5:$E$360,"1.2 Lista de cursos") | E17: =COUNTIFS('Entradas a 1.3'!$F$5:$F$360,"José Alexander Morales",'Entradas a 1.3'!$E$5:$E$360,"Negativo") | F17: =COUNTIFS('Entradas a 1.3'!$F$5:$F$360,"José Alexander Morales",'Entradas a 1.3'!$P$5:$P$360,"Sí") | G17: =IF(C17=0,0,F17/C17) | H17: =COUNTIFS('Entradas a 1.3'!$F$5:$F$360,"José Alexander Morales",'Entradas a 1.3'!$R$5:$R$360,"Sí")
B18: Ana Victoria de Leon | C18: =COUNTIFS('Entradas a 1.3'!$F$5:$F$360,"Ana Victoria de Leon") | D18: =COUNTIFS('Entradas a 1.3'!$F$5:$F$360,"Ana Victoria de Leon",'Entradas a 1.3'!$E$5:$E$360,"1.2 Lista de cursos") | E18: =COUNTIFS('Entradas a 1.3'!$F$5:$F$360,"Ana Victoria de Leon",'Entradas a 1.3'!$E$5:$E$360,"Negativo") | F18: =COUNTIFS('Entradas a 1.3'!$F$5:$F$360,"Ana Victoria de Leon",'Entradas a 1.3'!$P$5:$P$360,"Sí") | G18: =IF(C18=0,0,F18/C18) | H18: =COUNTIFS('Entradas a 1.3'!$F$5:$F$360,"Ana Victoria de Leon",'Entradas a 1.3'!$R$5:$R$360,"Sí")
B20: Todas las entradas a 1.3 del periodo fueron movimientos manuales: ningún bot ni regla mueve al lead a 1.3.

Sheet Frecuencia
B1: Con qué frecuencia se usa 1.3
B2: Entradas a 1.3 por semana (lunes a domingo) y embudo
B5: ENTRADAS A 1.3 POR SEMANA
B6: Semana (lunes) | C6: ISO + Calidad | D6: Core Tools | E6: Manufactura | F6: Total | G6: Recibieron la pregunta del área | H6: Entradas por cada 100 preguntas
B7: 05/10/2026 | C7: =COUNTIFS('Entradas a 1.3'!$B$5:$B$360,"ISO + Calidad",'Entradas a 1.3'!$C$5:$C$360,$B7) | D7: =COUNTIFS('Entradas a 1.3'!$B$5:$B$360,"Core Tools Premium",'Entradas a 1.3'!$C$5:$C$360,$B7) | E7: =COUNTIFS('Entradas a 1.3'!$B$5:$B$360,"Manufactura y Calidad",'Entradas a 1.3'!$C$5:$C$360,$B7) | F7: =SUM(C7:E7) | G7: =COUNTIFS('Base leads'!$C$5:$C$1238,$B7) | H7: =IF(G7=0,0,F7/G7*100)
B8: 12/10/2026 | C8: =COUNTIFS('Entradas a 1.3'!$B$5:$B$360,"ISO + Calidad",'Entradas a 1.3'!$C$5:$C$360,$B8) | D8: =COUNTIFS('Entradas a 1.3'!$B$5:$B$360,"Core Tools Premium",'Entradas a 1.3'!$C$5:$C$360,$B8) | E8: =COUNTIFS('Entradas a 1.3'!$B$5:$B$360,"Manufactura y Calidad",'Entradas a 1.3'!$C$5:$C$360,$B8) | F8: =SUM(C8:E8) | G8: =COUNTIFS('Base leads'!$C$5:$C$1238,$B8) | H8: =IF(G8=0,0,F8/G8*100)
B9: 19/10/2026 | C9: =COUNTIFS('Entradas a 1.3'!$B$5:$B$360,"ISO + Calidad",'Entradas a 1.3'!$C$5:$C$360,$B9) | D9: =COUNTIFS('Entradas a 1.3'!$B$5:$B$360,"Core Tools Premium",'Entradas a 1.3'!$C$5:$C$360,$B9) | E9: =COUNTIFS('Entradas a 1.3'!$B$5:$B$360,"Manufactura y Calidad",'Entradas a 1.3'!$C$5:$C$360,$B9) | F9: =SUM(C9:E9) | G9: =COUNTIFS('Base leads'!$C$5:$C$1238,$B9) | H9: =IF(G9=0,0,F9/G9*100)
B10: 26/10/2026 | C10: =COUNTIFS('Entradas a 1.3'!$B$5:$B$360,"ISO + Calidad",'Entradas a 1.3'!$C$5:$C$360,$B10) | D10: =COUNTIFS('Entradas a 1.3'!$B$5:$B$360,"Core Tools Premium",'Entradas a 1.3'!$C$5:$C$360,$B10) | E10: =COUNTIFS('Entradas a 1.3'!$B$5:$B$360,"Manufactura y Calidad",'Entradas a 1.3'!$C$5:$C$360,$B10) | F10: =SUM(C10:E10) | G10: =COUNTIFS('Base leads'!$C$5:$C$1238,$B10) | H10: =IF(G10=0,0,F10/G10*100)
B11: Total | C11: =SUM(C7:C10) | D11: =SUM(D7:D10) | E11: =SUM(E7:E10) | F11: =SUM(F7:F10) | G11: =SUM(G7:G10) | H11: =IF(G11=0,0,F11/G11*100)
B12: La última semana está incompleta (corte del martes 27/10).
B14: DE DÓNDE LLEGAN A 1.3
B15: Venía de | C15: ISO + Calidad | D15: Core Tools | E15: Manufactura | F15: Total
B16: 1.2 Lista de cursos | C16: =COUNTIFS('Entradas a 1.3'!$B$5:$B$360,"ISO + Calidad",'Entradas a 1.3'!$E$5:$E$360,$B16) | D16: =COUNTIFS('Entradas a 1.3'!$B$5:$B$360,"Core Tools Premium",'Entradas a 1.3'!$E$5:$E$360,$B16) | E16: =COUNTIFS('Entradas a 1.3'!$B$5:$B$360,"Manufactura y Calidad",'Entradas a 1.3'!$E$5:$E$360,$B16) | F16: =SUM(C16:E16)
B17: Leads entrantes | C17: =COUNTIFS('Entradas a 1.3'!$B$5:$B$360,"ISO + Calidad",'Entradas a 1.3'!$E$5:$E$360,$B17) | D17: =COUNTIFS('Entradas a 1.3'!$B$5:$B$360,"Core Tools Premium",'Entradas a 1.3'!$E$5:$E$360,$B17) | E17: =COUNTIFS('Entradas a 1.3'!$B$5:$B$360,"Manufactura y Calidad",'Entradas a 1.3'!$E$5:$E$360,$B17) | F17: =SUM(C17:E17)
B18: Negativo | C18: =COUNTIFS('Entradas a 1.3'!$B$5:$B$360,"ISO + Calidad",'Entradas a 1.3'!$E$5:$E$360,$B18) | D18: =COUNTIFS('Entradas a 1.3'!$B$5:$B$360,"Core Tools Premium",'Entradas a 1.3'!$E$5:$E$360,$B18) | E18: =COUNTIFS('Entradas a 1.3'!$B$5:$B$360,"Manufactura y Calidad",'Entradas a 1.3'!$E$5:$E$360,$B18) | F18: =SUM(C18:E18)

Sheet Funciona 1.3
B1: ¿Funciona 1.3 cuando se usa?
B2: Qué pasa con cada entrada a 1.3 y cómo les va a quienes contestaron el área según si los movieron o no
B5: QUÉ PASA DENTRO DE 1.3
B6: Indicador | C6: Total | D6: ISO + Calidad | E6: Core Tools | F6: Manufactura
B7: Entradas a 1.3 | C7: =COUNTA('Entradas a 1.3'!$A$5:$A$360) | D7: =COUNTIFS('Entradas a 1.3'!$B$5:$B$360,"ISO + Calidad") | E7: =COUNTIFS('Entradas a 1.3'!$B$5:$B$360,"Core Tools Premium") | F7: =COUNTIFS('Entradas a 1.3'!$B$5:$B$360,"Manufactura y Calidad")
B8: El bot mandó "¿te hago una llamadita?" | C8: =COUNTIFS('Entradas a 1.3'!$G$5:$G$360,"Sí") | D8: =COUNTIFS('Entradas a 1.3'!$B$5:$B$360,"ISO + Calidad",'Entradas a 1.3'!$G$5:$G$360,"Sí") | E8: =COUNTIFS('Entradas a 1.3'!$B$5:$B$360,"Core Tools Premium",'Entradas a 1.3'!$G$5:$G$360,"Sí") | F8: =COUNTIFS('Entradas a 1.3'!$B$5:$B$360,"Manufactura y Calidad",'Entradas a 1.3'!$G$5:$G$360,"Sí")
B9: El bot mandó "facilidades de pago" | C9: =COUNTIFS('Entradas a 1.3'!$H$5:$H$360,"Sí") | D9: =COUNTIFS('Entradas a 1.3'!$B$5:$B$360,"ISO + Calidad",'Entradas a 1.3'!$H$5:$H$360,"Sí") | E9: =COUNTIFS('Entradas a 1.3'!$B$5:$B$360,"Core Tools Premium",'Entradas a 1.3'!$H$5:$H$360,"Sí") | F9: =COUNTIFS('Entradas a 1.3'!$B$5:$B$360,"Manufactura y Calidad",'Entradas a 1.3'!$H$5:$H$360,"Sí")
B10: Una persona le escribió mientras estaba en 1.3 | C10: =COUNTIFS('Entradas a 1.3'!$K$5:$K$360,"Sí") | D10: =COUNTIFS('Entradas a 1.3'!$B$5:$B$360,"ISO + Calidad",'Entradas a 1.3'!$K$5:$K$360,"Sí") | E10: =COUNTIFS('Entradas a 1.3'!$B$5:$B$360,"Core Tools Premium",'Entradas a 1.3'!$K$5:$K$360,"Sí") | F10: =COUNTIFS('Entradas a 1.3'!$B$5:$B$360,"Manufactura y Calidad",'Entradas a 1.3'!$K$5:$K$360,"Sí")
B11: El cliente respondió en 1.3 | C11: =COUNTIFS('Entradas a 1.3'!$I$5:$I$360,"Sí") | D11: =COUNTIFS('Entradas a 1.3'!$B$5:$B$360,"ISO + Calidad",'Entradas a 1.3'!$I$5:$I$360,"Sí") | E11: =COUNTIFS('Entradas a 1.3'!$B$5:$B$360,"Core Tools Premium",'Entradas a 1.3'!$I$5:$I$360,"Sí") | F11: =COUNTIFS('Entradas a 1.3'!$B$5:$B$360,"Manufactura y Calidad",'Entradas a 1.3'!$I$5:$I$360,"Sí")
B12: Se creó una tarea de llamada | C12: =COUNTIFS('Entradas a 1.3'!$L$5:$L$360,"Sí") | D12: =COUNTIFS('Entradas a 1.3'!$B$5:$B$360,"ISO + Calidad",'Entradas a 1.3'!$L$5:$L$360,"Sí") | E12: =COUNTIFS('Entradas a 1.3'!$B$5:$B$360,"Core Tools Premium",'Entradas a 1.3'!$L$5:$L$360,"Sí") | F12: =COUNTIFS('Entradas a 1.3'!$B$5:$B$360,"Manufactura y Calidad",'Entradas a 1.3'!$L$5:$L$360,"Sí")
B13: Siguiente etapa: 1.4 Facilidades de pago | C13: =COUNTIFS('Entradas a 1.3'!$M$5:$M$360,"1.4 Facilidades de pago") | D13: =COUNTIFS('Entradas a 1.3'!$B$5:$B$360,"ISO + Calidad",'Entradas a 1.3'!$M$5:$M$360,"1.4 Facilidades de pago") | E13: =COUNTIFS('Entradas a 1.3'!$B$5:$B$360,"Core Tools Premium",'Entradas a 1.3'!$M$5:$M$360,"1.4 Facilidades de pago") | F13: =COUNTIFS('Entradas a 1.3'!$B$5:$B$360,"Manufactura y Calidad",'Entradas a 1.3'!$M$5:$M$360,"1.4 Facilidades de pago")
B14: Siguiente etapa: medio de pago | C14: =COUNTIFS('Entradas a 1.3'!$M$5:$M$360,"Medio de pago") | D14: =COUNTIFS('Entradas a 1.3'!$B$5:$B$360,"ISO + Calidad",'Entradas a 1.3'!$M$5:$M$360,"Medio de pago") | E14: =COUNTIFS('Entradas a 1.3'!$B$5:$B$360,"Core Tools Premium",'Entradas a 1.3'!$M$5:$M$360,"Medio de pago") | F14: =COUNTIFS('Entradas a 1.3'!$B$5:$B$360,"Manufactura y Calidad",'Entradas a 1.3'!$M$5:$M$360,"Medio de pago")
B15: Siguiente etapa: Ganado | C15: =COUNTIFS('Entradas a 1.3'!$M$5:$M$360,"Ganado") | D15: =COUNTIFS('Entradas a 1.3'!$B$5:$B$360,"ISO + Calidad",'Entradas a 1.3'!$M$5:$M$360,"Ganado") | E15: =COUNTIFS('Entradas a 1.3'!$B$5:$B$360,"Core Tools Premium",'Entradas a 1.3'!$M$5:$M$360,"Ganado") | F15: =COUNTIFS('Entradas a 1.3'!$B$5:$B$360,"Manufactura y Calidad",'Entradas a 1.3'!$M$5:$M$360,"Ganado")
B16: Siguiente etapa: Negativo (lo mandó el bot de 1.3) | C16: =COUNTIFS('Entradas a 1.3'!$M$5:$M$360,"Negativo",'Entradas a 1.3'!$N$5:$N$360,"Bot de 1.3") | D16: =COUNTIFS('Entradas a 1.3'!$B$5:$B$360,"ISO + Calidad",'Entradas a 1.3'!$M$5:$M$360,"Negativo",'Entradas a 1.3'!$N$5:$N$360,"Bot de 1.3") | E16: =COUNTIFS('Entradas a 1.3'!$B$5:$B$360,"Core Tools Premium",'Entradas a 1.3'!$M$5:$M$360,"Negativo",'Entradas a 1.3'!$N$5:$N$360,"Bot de 1.3") | F16: =COUNTIFS('Entradas a 1.3'!$B$5:$B$360,"Manufactura y Calidad",'Entradas a 1.3'!$M$5:$M$360,"Negativo",'Entradas a 1.3'!$N$5:$N$360,"Bot de 1.3")
B17: Siguiente etapa: Perdido | C17: =COUNTIFS('Entradas a 1.3'!$M$5:$M$360,"Perdido") | D17: =COUNTIFS('Entradas a 1.3'!$B$5:$B$360,"ISO + Calidad",'Entradas a 1.3'!$M$5:$M$360,"Perdido") | E17: =COUNTIFS('Entradas a 1.3'!$B$5:$B$360,"Core Tools Premium",'Entradas a 1.3'!$M$5:$M$360,"Perdido") | F17: =COUNTIFS('Entradas a 1.3'!$B$5:$B$360,"Manufactura y Calidad",'Entradas a 1.3'!$M$5:$M$360,"Perdido")
B18: Sigue en 1.3 | C18: =COUNTIFS('Entradas a 1.3'!$M$5:$M$360,"Sigue en 1.3") | D18: =COUNTIFS('Entradas a 1.3'!$B$5:$B$360,"ISO + Calidad",'Entradas a 1.3'!$M$5:$M$360,"Sigue en 1.3") | E18: =COUNTIFS('Entradas a 1.3'!$B$5:$B$360,"Core Tools Premium",'Entradas a 1.3'!$M$5:$M$360,"Sigue en 1.3") | F18: =COUNTIFS('Entradas a 1.3'!$B$5:$B$360,"Manufactura y Calidad",'Entradas a 1.3'!$M$5:$M$360,"Sigue en 1.3")
B19: Después llegó a 1.4 o más (en cualquier momento) | C19: =COUNTIFS('Entradas a 1.3'!$P$5:$P$360,"Sí") | D19: =COUNTIFS('Entradas a 1.3'!$B$5:$B$360,"ISO + Calidad",'Entradas a 1.3'!$P$5:$P$360,"Sí") | E19: =COUNTIFS('Entradas a 1.3'!$B$5:$B$360,"Core Tools Premium",'Entradas a 1.3'!$P$5:$P$360,"Sí") | F19: =COUNTIFS('Entradas a 1.3'!$B$5:$B$360,"Manufactura y Calidad",'Entradas a 1.3'!$P$5:$P$360,"Sí")
B20: Después llegó a un medio de pago | C20: =COUNTIFS('Entradas a 1.3'!$Q$5:$Q$360,"Sí") | D20: =COUNTIFS('Entradas a 1.3'!$B$5:$B$360,"ISO + Calidad",'Entradas a 1.3'!$Q$5:$Q$360,"Sí") | E20: =COUNTIFS('Entradas a 1.3'!$B$5:$B$360,"Core Tools Premium",'Entradas a 1.3'!$Q$5:$Q$360,"Sí") | F20: =COUNTIFS('Entradas a 1.3'!$B$5:$B$360,"Manufactura y Calidad",'Entradas a 1.3'!$Q$5:$Q$360,"Sí")
B21: Después Ganado | C21: =COUNTIFS('Entradas a 1.3'!$R$5:$R$360,"Sí") | D21: =COUNTIFS('Entradas a 1.3'!$B$5:$B$360,"ISO + Calidad",'Entradas a 1.3'!$R$5:$R$360,"Sí") | E21: =COUNTIFS('Entradas a 1.3'!$B$5:$B$360,"Core Tools Premium",'Entradas a 1.3'!$R$5:$R$360,"Sí") | F21: =COUNTIFS('Entradas a 1.3'!$B$5:$B$360,"Manufactura y Calidad",'Entradas a 1.3'!$R$5:$R$360,"Sí")
B22: Respondió en 1.3 y aun así el bot lo mandó al Negativo | C22: =COUNTIFS('Entradas a 1.3'!$S$5:$S$360,"Sí") | D22: =COUNTIFS('Entradas a 1.3'!$B$5:$B$360,"ISO + Calidad",'Entradas a 1.3'!$S$5:$S$360,"Sí") | E22: =COUNTIFS('Entradas a 1.3'!$B$5:$B$360,"Core Tools Premium",'Entradas a 1.3'!$S$5:$S$360,"Sí") | F22: =COUNTIFS('Entradas a 1.3'!$B$5:$B$360,"Manufactura y Calidad",'Entradas a 1.3'!$S$5:$S$360,"Sí")
B24: LAS MISMAS CIFRAS EN PORCENTAJE DE LAS ENTRADAS
B25: Indicador | C25: Total | D25: ISO + Calidad | E25: Core Tools | F25: Manufactura
B26: El bot mandó "¿te hago una llamadita?" | C26: =IF(C$7=0,0,C8/C$7) | D26: =IF(D$7=0,0,D8/D$7) | E26: =IF(E$7=0,0,E8/E$7) | F26: =IF(F$7=0,0,F8/F$7)
B27: El bot mandó "facilidades de pago" | C27: =IF(C$7=0,0,C9/C$7) | D27: =IF(D$7=0,0,D9/D$7) | E27: =IF(E$7=0,0,E9/E$7) | F27: =IF(F$7=0,0,F9/F$7)
B28: Una persona le escribió mientras estaba en 1.3 | C28: =IF(C$7=0,0,C10/C$7) | D28: =IF(D$7=0,0,D10/D$7) | E28: =IF(E$7=0,0,E10/E$7) | F28: =IF(F$7=0,0,F10/F$7)
B29: El cliente respondió en 1.3 | C29: =IF(C$7=0,0,C11/C$7) | D29: =IF(D$7=0,0,D11/D$7) | E29: =IF(E$7=0,0,E11/E$7) | F29: =IF(F$7=0,0,F11/F$7)
B30: Se creó una tarea de llamada | C30: =IF(C$7=0,0,C12/C$7) | D30: =IF(D$7=0,0,D12/D$7) | E30: =IF(E$7=0,0,E12/E$7) | F30: =IF(F$7=0,0,F12/F$7)
B31: Siguiente etapa: 1.4 Facilidades de pago | C31: =IF(C$7=0,0,C13/C$7) | D31: =IF(D$7=0,0,D13/D$7) | E31: =IF(E$7=0,0,E13/E$7) | F31: =IF(F$7=0,0,F13/F$7)
B32: Siguiente etapa: medio de pago | C32: =IF(C$7=0,0,C14/C$7) | D32: =IF(D$7=0,0,D14/D$7) | E32: =IF(E$7=0,0,E14/E$7) | F32: =IF(F$7=0,0,F14/F$7)
B33: Siguiente etapa: Ganado | C33: =IF(C$7=0,0,C15/C$7) | D33: =IF(D$7=0,0,D15/D$7) | E33: =IF(E$7=0,0,E15/E$7) | F33: =IF(F$7=0,0,F15/F$7)
B34: Siguiente etapa: Negativo (lo mandó el bot de 1.3) | C34: =IF(C$7=0,0,C16/C$7) | D34: =IF(D$7=0,0,D16/D$7) | E34: =IF(E$7=0,0,E16/E$7) | F34: =IF(F$7=0,0,F16/F$7)
B35: Siguiente etapa: Perdido | C35: =IF(C$7=0,0,C17/C$7) | D35: =IF(D$7=0,0,D17/D$7) | E35: =IF(E$7=0,0,E17/E$7) | F35: =IF(F$7=0,0,F17/F$7)
B36: Sigue en 1.3 | C36: =IF(C$7=0,0,C18/C$7) | D36: =IF(D$7=0,0,D18/D$7) | E36: =IF(E$7=0,0,E18/E$7) | F36: =IF(F$7=0,0,F18/F$7)
B37: Después llegó a 1.4 o más (en cualquier momento) | C37: =IF(C$7=0,0,C19/C$7) | D37: =IF(D$7=0,0,D19/D$7) | E37: =IF(E$7=0,0,E19/E$7) | F37: =IF(F$7=0,0,F19/F$7)
... B40: Respondió en 1.3 y aun así el bot lo mandó al Negativo | C40: =IF(C$7=0,0,C22/C$7) | D40: =IF(D$7=0,0,D22/D$7) | E40: =IF(E$7=0,0,E22/E$7) | F40: =IF(F$7=0,0,F22/F$7)
B42: RESPUESTA A LOS MENSAJES DEL BOT DE 1.3
B43: Mensaje | C43: Enviados | D43: Respondieron en 30 min | E43: % respuesta en 30 min
B44: "Igual si gustas te puedo hacer una llamadita…" | C44: =COUNTIFS('Entradas a 1.3'!$G$5:$G$360,"Sí") | D44: =COUNTIFS('Entradas a 1.3'!$U$5:$U$360,"Sí") | E44: =IF(C44=0,0,D44/C44)
B45: "…tenemos facilidades de pago 💳 ¿Quieres que te muestre cómo quedaría?" | C45: =COUNTIFS('Entradas a 1.3'!$H$5:$H$360,"Sí") | D45: =COUNTIFS('Entradas a 1.3'!$V$5:$V$360,"Sí") | E45: =IF(C45=0,0,D45/C45)
B47: SEGÚN SI EL CLIENTE RESPONDIÓ DENTRO DE 1.3
...

Sheet Base leads
A1: Base de leads
A2: Un renglón por lead que recibió la pregunta del área en los 3 embudos. Minutos en tiempo real (no solo horario laboral).
A4: Lead | B4: Embudo | C4: Semana (lunes) | D4: Contestó la pregunta del área | E4: Cuándo contestó | F4: Min. en contestar | G4: Preguntó precio o pago | H4: Primera persona que le contestó | I4: Min. a la primera respuesta de una persona | J4: Plantilla "audio rapidito" | K4: Le mandaron audio | L4: Quién mandó el audio | M4: Min. al audio | N4: Movido a 1.3 | O4: Quién lo movió a 1.3 | P4: Min. de su respuesta a 1.3 | Q4: Movido antes de que el bot lo mandara al Negativo | R4: Qué hicieron después de su respuesta | S4: Si no se movió a 1.3, a dónde fue | T4: Franja de su respuesta | U4: Llegó a 1.4 o más | V4: Llegó a un medio de pago | W4: Venta (Ganado o pago confirmado) | X4: Con 7 días o más | Y4: Etapa actual
A5: 267 | B5: Manufactura y Calidad | C5: 05/10/2026 | D5: Sí | E5: A tiempo (en 1.2) | F5: 2.8 | G5: No | H5: Salma Santos Hernández | I5: 0.5 | J5: Sí | K5: Sí | L5: Salma Santos Hernández | M5: 4 | N5: Sí | O5: Salma Santos Hernández | P5: 4.3 | Q5: Sí | R5: Audio y después 1.3 | T5: 9 a 18 h | U5: Sí | V5: No | W5: No | X5: Sí | Y5: Perdido
A6: 268 | B6: Core Tools Premium | C6: 05/10/2026 | D6: Sí | E6: Tarde (ya fuera de 1.2) | F6: 1367.6 | G6: Sí | H6: Joceline Sarahi Benavides Serrano | I6: 10.7 | J6: No | K6: Sí | L6: Joceline Sarahi Benavides Serrano | M6: 10.7 | N6: No | R6: Audio sin mover a 1.3 | S6: Negativo (lo mandó el bot) | T6: 9 a 18 h | U6: No | V6: No | W6: No | X6: Sí | Y6: Perdido
A7: 271 | B7: ISO + Calidad | C7: 05/10/2026 | D7: No | E7: No contestó | U7: No | V7: No | W7: No | X7: Sí | Y7: Perdido
A8: 276 | B8: ISO + Calidad | C8: 05/10/2026 | D8: Sí | E8: A tiempo (en 1.2) | F8: 0.6 | G8: No | H8: Salma Santos Hernández | I8: 0.3 | J8: Sí | K8: Sí | L8: Salma Santos Hernández | M8: 2.8 | N8: Sí | O8: Salma Santos Hernández | P8: 3.7 | Q8: Sí | R8: Audio y después 1.3 | T8: 9 a 18 h | U8: No | V8: No | W8: No | X8: Sí | Y8: Perdido
A9: 278 | B9: ISO + Calidad | C9: 05/10/2026 | D9: Sí | E9: A tiempo (en 1.2) | F9: 0.8 | G9: No | H9: Salma Santos Hernández | I9: 0.3 | J9: Sí | K9: Sí | L9: Salma Santos Hernández | M9: 2.6 | N9: Sí | O9: Salma Santos Hernández | P9: 2.9 | Q9: Sí | R9: Audio y después 1.3 | T9: 9 a 18 h | U9: No | V9: No | W9: No | X9: Sí | Y9: Perdido
A10: 282 | B10: ISO + Calidad | C10: 05/10/2026 | D10: No | E10: No contestó | U10: No | V10: No | W10: No | X10: Sí | Y10: Perdido
A11: 277 | B11: ISO + Calidad | C11: 05/10/2026 | D11: Sí | E11: A tiempo (en 1.2) | F11: 71.2 | G11: No | H11: José Alexander Morales | I11: 2.2 | J11: Sí | K11: Sí | L11: José Alexander Morales | M11: 8.5 | N11: Sí | O11: José Alexander Morales | P11: 8.9 | Q11: Sí | R11: Audio y después 1.3 | T11: 9 a 18 h | U11: No | V11: No | W11: No | X11: Sí | Y11: Perdido
A12: 280 | B12: ISO + Calidad | C12: 05/10/2026 | D12: No | E12: No contestó | U12: No | V12: No | W12: No | X12: Sí | Y12: Perdido
A13: 286 | B13: Core Tools Premium | C13: 05/10/2026 | D13: Sí | E13: A tiempo (en 1.2) | F13: 1.1 | G13: No | H13: Ana Victoria de Leon | I13: 0.2 | J13: Sí | K13: Sí | L13: Ana Victoria de Leon | M13: 5.1 | N13: Sí | O13: Ana Victoria de Leon | P13: 6.1 | Q13: Sí | R13: Audio y después 1.3 | T13: 9 a 18 h | U13: Sí | V13: Sí | W13: No | X13: Sí | Y13: Perdido
A14: 285 | B14: ISO + Calidad | C14: 05/10/2026 | D14: No | E14: No contestó | U14: No | V14: No | W14: No | X14: Sí | Y14: Perdido
A15: 291 | B15: ISO + Calidad | C15: 05/10/2026 | D15: No | E15: No contestó | U15: No | V15: No | W15: No | X15: Sí | Y15: Perdido
A16: 287 | B16: ISO + Calidad | C16: 05/10/2026 | D16: Sí | E16: A tiempo (en 1.2) | F16: 28.8 | G16: No | H16: Salma Santos Hernández | I16: 4 | J16: Sí | K16: Sí | L16: Salma Santos Hernández | M16: 10.8 | N16: Sí | O16: Salma Santos Hernández | P16: 11.6 | Q16: Sí | R16: Audio y después 1.3 | T16: 9 a 18 h | U16: No | V16: No | W16: No | X16: Sí | Y16: Perdido
A17: 289 | B17: Manufactura y Calidad | C17: 05/10/2026 | D17: Sí | E17: A tiempo (en 1.2) | F17: 72.7 | G17: No | H17: José Alexander Morales | I17: 1.3 | J17: No | K17: No | N17: No | R17: Ni audio ni 1.3 | S17: Negativo (lo mandó el bot) | T17: 9 a 18 h | U17: No | V17: No | W17: No | X17: Sí | Y17: Perdido
A18: 292 | B18: ISO + Calidad | C18: 05/10/2026 | D18: No | E18: No contestó | U18: No | V18: No | W18: No | X18: Sí | Y18: Perdido
A19: 296 | B19: ISO + Calidad | C19: 05/10/2026 | D19: Sí | E19: A tiempo (en 1.2) | F19: 29.8 | G19: No | H19: Salma Santos Hernández | I19: 0.2 | J19: Sí | K19: Sí | L19: Salma Santos Hernández | M19: 6.2 | N19: Sí | O19: Salma Santos Hernández | P19: 6.4 | Q19: Sí | R19: Audio y después 1.3 | T19: 9 a 18 h | U19: No | V19: No | W19: No | X19: Sí | Y19: Perdido
A20: 295 | B20: ISO + Calidad | C20: 05/10/2026 | D20: Sí | E20: A tiempo (en 1.2) | F20: 7.2 | G20: No | H20: Ana Victoria de Leon | I20: 0.6 | J20: No | K20: No | N20: No | R20: Ni audio ni 1.3 | S20: Negativo (lo mandó el bot) | T20: 9 a 18 h | U20: No | V20: No | W20: No | X20: Sí | Y20: Perdido
A21: 294 | B21: Core Tools Premium | C21: 05/10/2026 | D21: No | E21: No contestó | U21: No | V21: No | W21: No | X21: Sí | Y21: Perdido
A22: 298 | B22: ISO + Calidad | C22: 05/10/2026 | D22: Sí | E22: A tiempo (en 1.2) | F22: 0.8 | G22: Sí | H22: Salma Santos Hernández | I22: 0.1 | J22: Sí | K22: Sí | L22: Salma Santos Hernández | M22: 3.2 | N22: Sí | O22: Salma Santos Hernández | P22: 3.4 | Q22: Sí | R22: Audio y después 1.3 | T22: 9 a 18 h | U22: Sí | V22: No | W22: No | X22: Sí | Y22: Perdido
A23: 301 | B23: Core Tools Premium | C23: 05/10/2026 | D23: No | E23: No contestó | U23: No | V23: No | W23: No | X23: Sí | Y23: Perdido
A24: 300 | B24: Core Tools Premium | C24: 05/10/2026 | D24: No | E24: No contestó | U24: No | V24: No | W24: No | X24: Sí | Y24: Perdido
A25: 307 | B25: ISO + Calidad | C25: 05/10/2026 | D25: No | E25: No contestó | U25: No | V25: No | W25: No | X25: Sí | Y25: Perdido
A26: 309 | B26: Manufactura y Calidad | C26: 05/10/2026 | D26: Sí | E26: A tiempo (en 1.2) | F26: 1.4 | G26: No | H26: Ana Victoria de Leon | I26: 2.2 | J26: No | K26: No | N26: Sí | O26: Ana Victoria de Leon | P26: 2.4 | Q26: Sí | R26: Movido a 1.3 sin audio | T26: 9 a 18 h | U26: No | V26: No | W26: No | X26: Sí | Y26: Perdido
A27: 310 | B27: Core Tools Premium | C27: 05/10/2026 | D27: No | E27: No contestó | U27: No | V27: No | W27: No | X27: Sí | Y27: Perdido
A28: 308 | B28: ISO + Calidad | C28: 05/10/2026 | D28: Sí | E28: A tiempo (en 1.2) | F28: 53.3 | G28: No | H28: Salma Santos Hernández | I28: 10 | J28: Sí | K28: Sí | L28: Salma Santos Hernández | M28: 24 | N28: Sí | O28: Salma Santos Hernández | P28: 24.1 | Q28: Sí | R28: Audio y después 1.3 | T28: 18 a 22 h | U28: Sí | V28: No | W28: No | X28: Sí | Y28: Perdido
A29: 313 | B29: ISO + Calidad | C29: 05/10/2026 | D29: Sí | E29: A tiempo (en 1.2) | F29: 9.8 | G29: No | H29: Ana Victoria de Leon | I29: 1.6 | J29: No | K29: No | N29: Sí | O29: Ana Victoria de Leon | P29: 1.7 | Q29: Sí | R29: Movido a 1.3 sin audio | T29: 9 a 18 h | U29: No | V29: No | W29: No | X29: Sí | Y29: Perdido
A30: 311 | B30: ISO + Calidad | C30: 05/10/2026 | D30: No | E30: No contestó | U30: No | V30: No | W30: No | X30: Sí | Y30: Perdido
A31: 314 | B31: ISO + Calidad | C31: 05/10/2026 | D31: No | E31: No contestó | U31: No | V31: No | W31: No | X31: Sí | Y31: Perdido
A32: 317 | B32: ISO + Calidad | C32: 05/10/2026 | D32: Sí | E32: A tiempo (en 1.2) | F32: 1.4 | G32: Sí | H32: Ana Victoria de Leon | I32: 4.1 | J32: No | K32: No | N32: Sí | O32: Ana Victoria de Leon | P32: 4.3 | Q32: Sí | R32: Movido a 1.3 sin audio | T32: 18 a 22 h | U32: Sí | V32: Sí | W32: No | X32: Sí | Y32: Perdido
A33: 321 | B33: ISO + Calidad | C33: 05/10/2026 | D33: No | E33: No contestó | U33: No | V33: No | W33: No | X33: Sí | Y33: Perdido
A34: 319 | B34: ISO + Calidad | C34: 05/10/2026 | D34: No | E34: No contestó | U34: No | V34: No | W34: No | X34: Sí | Y34: Perdido
A35: 322 | B35: ISO + Calidad | C35: 05/10/2026 | D35: No | E35: No contestó | U35: No | V35: No | W35: No | X35: Sí | Y35: Perdido
A36: 323 | B36: ISO + Calidad | C36: 05/10/2026 | D36: No | E36: No contestó | U36: No | V36: No | W36: No | X36: Sí | Y36: Perdido
A37: 326 | B37: Manufactura y Calidad | C37: 05/10/2026 | D37: No | E37: No contestó | U37: No | V37: No | W37: No | X37: Sí | Y37: Perdido
A38: 327 | B38: Core Tools Premium | C38: 05/10/2026 | D38: Sí | E38: A tiempo (en 1.2) | F38: 4.2 | G38: No | H38: Ana Victoria de Leon | I38: 12.2 | J38: No | K38: No | N38: Sí | O38: Ana Victoria de Leon | P38: 12.3 | Q38: Sí | R38: Movido a 1.3 sin audio | T38: 18 a 22 h | U38: Sí | V38: Sí | W38: Sí | X38: Sí | Y38: Ganado
A39: 330 | B39: ISO + Calidad | C39: 05/10/2026 | D39: No | E39: No contestó | U39: No | V39: No | W39: No | X39: Sí | Y39: Perdido
A40: 329 | B40: Manufactura y Calidad | C40: 05/10/2026 | D40: No | E40: No contestó | U40: No | V40: No | W40: No | X40: Sí | Y40: Perdido
A41: 336 | B41: ISO + Calidad | C41: 05/10/2026 | D41: Sí | E41: Tarde (ya fuera de 1.2) | F41: 5661.5 | G41: No | J41: No | K41: No | N41: No | R41: Ni audio ni 1.3 | S41: Negativo (lo mandó el bot) | T41: 18 a 22 h | U41: No | V41: No | W41: No | X41: Sí | Y41: Perdido
...

Sheet Entradas a 1.3
A1: Entradas a 1.3
A2: Un renglón por cada vez que un lead entró a 1.3 Llamadita y facilidades de pago (5/10 al 27/10/2026).
A4: Lead | B4: Embudo | C4: Semana (lunes) | D4: Entró a 1.3 | E4: Venía de | F4: Quién lo movió | G4: Bot mandó "llamadita" | H4: Bot mandó "facilidades de pago" | I4: El cliente respondió en 1.3 | J4: Min. a su respuesta | K4: Una persona le escribió en 1.3 | L4: Tarea de llamada | M4: Siguiente etapa | N4: Quién lo sacó de 1.3 | O4: Horas en 1.3 | P4: Después llegó a 1.4 o más | Q4: Después llegó a un medio de pago | R4: Después Ganado | S4: Respondió y el bot lo mandó al Negativo | T4: Asesor asignado | U4: Respondió en 30 min a la llamadita | V4: Respondió en 30 min a facilidades
A5: 267 | B5: Manufactura y Calidad | C5: 05/10/2026 | D5: 05/10/2026 12:33 | E5: 1.2 Lista de cursos | F5: Salma Santos Hernández | G5: Sí | H5: Sí | I5: Sí | J5: 15.3 | K5: Sí | L5: No | M5: 1.4 Facilidades de pago | N5: Salma Santos Hernández | O5: 0.3 | P5: Sí | Q5: No | R5: No | S5: No | T5: Salma Santos Hernández | U5: Sí | V5: Sí
A6: 276 | B6: ISO + Calidad | C6: 05/10/2026 | D6: 05/10/2026 13:30 | E6: 1.2 Lista de cursos | F6: Salma Santos Hernández | G6: Sí | H6: Sí | I6: No | K6: No | L6: No | M6: Negativo | N6: Bot de 1.3 | O6: 4.3 | P6: No | Q6: No | R6: No | S6: No | T6: Salma Santos Hernández | U6: No | V6: No
A7: 278 | B7: ISO + Calidad | C7: 05/10/2026 | D7: 05/10/2026 13:36 | E7: 1.2 Lista de cursos | F7: Salma Santos Hernández | G7: Sí | H7: Sí | I7: Sí | J7: 0.1 | K7: Sí | L7: No | M7: Negativo | N7: Bot de 1.3 | O7: 4.3 | P7: No | Q7: No | R7: No | S7: Sí | T7: Salma Santos Hernández | U7: No | V7: No
A8: 286 | B8: Core Tools Premium | C8: 05/10/2026 | D8: 05/10/2026 14:51 | E8: 1.2 Lista de cursos | F8: Ana Victoria de Leon | G8: Sí | H8: Sí | I8: Sí | J8: 25.1 | K8: Sí | L8: No | M8: 1.4 Facilidades de pago | N8: Ana Victoria de Leon | O8: 0.4 | P8: Sí | Q8: Sí | R8: No | S8: No | T8: Ana Victoria de Leon | U8: Sí | V8: Sí
A9: 277 | B9: ISO + Calidad | C9: 05/10/2026 | D9: 05/10/2026 15:20 | E9: 1.2 Lista de cursos | F9: José Alexander Morales | G9: Sí | H9: Sí | I9: No | K9: No | L9: No | M9: Negativo | N9: Bot de 1.3 | O9: 4.3 | P9: No | Q9: No | R9: No | S9: No | T9: José Alexander Morales | U9: No | V9: No
A10: 287 | B10: ISO + Calidad | C10: 05/10/2026 | D10: 05/10/2026 15:38 | E10: 1.2 Lista de cursos | F10: Salma Santos Hernández | G10: Sí | H10: Sí | I10: Sí | J10: 28.4 | K10: Sí | L10: No | M10: Negativo | N10: Bot de 1.3 | O10: 4.3 | P10: No | Q10: No | R10: No | S10: Sí | T10: Ana Victoria de Leon | U10: Sí | V10: Sí
A11: 298 | B11: ISO + Calidad | C11: 05/10/2026 | D11: 05/10/2026 15:57 | E11: 1.2 Lista de cursos | F11: Salma Santos Hernández | G11: Sí | H11: No | I11: Sí | J11: 5 | K11: Sí | L11: No | M11: 1.4 Facilidades de pago | N11: Salma Santos Hernández | O11: 0.1 | P11: Sí | Q11: No | R11: No | S11: No | T11: Salma Santos Hernández | U11: Sí
A12: 296 | B12: ISO + Calidad | C12: 05/10/2026 | D12: 05/10/2026 16:21 | E12: 1.2 Lista de cursos | F12: Salma Santos Hernández | G12: Sí | H12: Sí | I12: No | K12: No | L12: No | M12: Negativo | N12: Bot de 1.3 | O12: 4.3 | P12: No | Q12: No | R12: No | S12: No | T12: Ana Victoria de Leon | U12: No | V12: No
A13: 309 | B13: Manufactura y Calidad | C13: 05/10/2026 | D13: 05/10/2026 17:19 | E13: 1.2 Lista de cursos | F13: Ana Victoria de Leon | G13: Sí | H13: Sí | I13: Sí | J13: 6.1 | K13: Sí | L13: No | M13: Negativo | N13: Bot de 1.3 | O13: 4.3 | P13: No | Q13: No | R13: No | S13: Sí | T13: Ana Victoria de Leon | U13: Sí | V13: No
A14: 313 | B14: ISO + Calidad | C14: 05/10/2026 | D14: 05/10/2026 17:52 | E14: 1.2 Lista de cursos | F14: Ana Victoria de Leon | G14: Sí | H14: Sí | I14: No | K14: No | L14: No | M14: Negativo | N14: Bot de 1.3 | O14: 4.3 | P14: No | Q14: No | R14: No | S14: No | T14: Ana Victoria de Leon | U14: No | V14: No
